Workbook

Sheet Istruzioni
B1: Budget familiare 2026
B2: Istruzioni d'uso · NettoChiaro · versione 2026.1
B5: Legenda
C6: Celle gialle: da compilare. Tutte le altre contengono formule e si aggiornano da sole.
C7: Celle arancioni: segnalano un dato da controllare (data mancante, categoria non trovata, nome doppio).
C8: Intestazioni verdi: titoli delle colonne. I fogli sono protetti senza password per evitare di cancellare le formule.
B10: Come iniziare
B11: 1. | C11: Impostazioni: anno, saldo di cassa al 1° gennaio (conto corrente più contanti), nomi dei membri della famiglia (facoltativi) e conti o metodi di pagamento.
B12: 2. | C12: Categorie: controlla l'elenco. Puoi rinominare le voci, aggiungerne nelle righe vuote e scegliere il tipo: Entrata, Spesa fissa, Spesa variabile, Risparmio e investimenti.
B13: 3. | C13: Budget: scrivi l'importo tipico mensile di ogni categoria; i 12 mesi si compilano da soli. Per le spese che non sono mensili (TARI, bollo auto, assicurazioni) scrivi l'importo nel mese in cui le paghi.
B14: 4. | C14: Movimenti: registra ogni entrata e uscita con data, descrizione, categoria scelta dal menu e importo. Conto e persona sono facoltativi.
B15: 5. | C15: Mensile e Dashboard: si aggiornano da soli. Mostrano il consuntivo per categoria e per mese, la differenza dal budget, il risparmio e i grafici.
B16: 6. | C16: Obiettivi e Debiti: elenca cosa vuoi mettere da parte e i debiti in corso. Il foglio calcola la quota mensile necessaria e l'ordine di estinzione consigliato.
B18: Regole utili
B19: • | C19: Gli importi si scrivono sempre positivi: è la categoria a dire se sono un'entrata o un'uscita. Un rimborso su una spesa si registra con importo negativo nella stessa categoria.
B20: • | C20: I versamenti su conti di risparmio, investimenti o fondo pensione vanno nelle categorie di tipo «Risparmio e investimenti». Non sono spese, ma escono dal saldo di cassa.
B21: • | C21: Risparmio = entrate − spese. Tasso di risparmio = risparmio / entrate. Avanzo = entrate − spese − versamenti a risparmio.
B22: • | C22: Saldo di cassa = saldo al 1° gennaio + entrate − spese − versamenti a risparmio. Se registri tutti i movimenti, si avvicina al totale di conto corrente e contanti (le spese con carta di credito escono dal conto più tardi).
B23: • | C23: Contano solo i movimenti con una data dell'anno impostato. La colonna «Controllo» dei Movimenti segnala date mancanti, categorie non trovate e movimenti di altri anni.
B24: • | C24: Il registro ha 2.000 righe. In Categorie non eliminare le righe: svuota le celle. Se rinomini una categoria già usata, correggi anche i movimenti con il vecchio nome.
B25: • | C25: Mese di riferimento (Impostazioni): «Automatico» usa il mese della data di riferimento (se la data è vuota, quello di oggi). Serve per i confronti «da inizio anno» di Mensile e Dashboard.
B26: • | C26: Per un mese di budget diverso dal solito scrivi il valore nella cella del mese. Per tornare all'importo tipico copia la cella di un mese non modificato.
B28: Protezione, stampa e nuovo anno
B29: • | C29: Per togliere la protezione (non c'è password): Excel, Revisione > Rimuovi protezione foglio; LibreOffice, Strumenti > Proteggi foglio; Google Sheets, Dati > Proteggi fogli e intervalli.
B30: • | C30: Per ordinare i movimenti togli prima la protezione del foglio Movimenti. Per stampare solo una parte del registro seleziona le righe e scegli «Stampa selezione».
B31: • | C31: Nuovo anno: salva una copia del file, cambia l'anno in Impostazioni, scrivi come saldo iniziale il saldo di cassa di fine anno, svuota i movimenti e aggiorna budget, obiettivi e debiti.
B33: Compatibilità
B34: • | C34: Excel 2016 o successivo (Windows e Mac), Google Sheets (carica il file su Google Drive e aprilo con Google Sheets), LibreOffice Calc. Nessuna macro, nessun collegamento esterno.
B35: • | C35: Excel apre i file scaricati da internet in «Visualizzazione protetta», dove i calcoli non si aggiornano: fai clic su «Abilita modifica».
B36: • | C36: In Google Sheets la protezione dei fogli può non restare attiva: scrivi solo nelle celle gialle. I grafici possono avere uno stile leggermente diverso.
B38: Avvertenze
B39: • | C39: Strumento di organizzazione personale: non è consulenza finanziaria né fiscale. Le stime su obiettivi e debiti ipotizzano tassi e rate costanti; controlla sempre i dati del tuo contratto.
B40: • | C40: Calcolo dello stipendio netto: nettochiaro.com/calcolo-stipendio-netto
B41: • | C41: Calcolo della rata del mutuo: nettochiaro.com/calcolo-rata-mutuo

Sheet Impostazioni
B1: Impostazioni
B2: Compila le celle gialle. Le altre si aggiornano da sole.
B4: Anno del budget | C4: 2026 | D4: Contano solo i movimenti con una data di quest'anno.
B5: Saldo di cassa al 1° gennaio | C5: 3200 | D5: Conto corrente più contanti a inizio anno. Esclude i conti di risparmio e gli investimenti.
B6: Nome della famiglia (facoltativo) | C6: Famiglia Rossi | D6: Compare nel titolo della Dashboard.
B7: Mese di riferimento | C7: Automatico | D7: «Automatico» (o vuoto) usa il mese della data di riferimento. Serve per i confronti «da inizio anno».
B8: Data di riferimento (facoltativa) | C8: 46387 | D8: Lascia vuoto per usare la data di oggi. Serve per obiettivi, debiti e mese automatico.
B10: Valori usati dal foglio (calcolati, non modificare)
B11: Data di riferimento usata | C11: =IF(C8="",TODAY(),C8)
B12: Mese di riferimento usato (numero) | C12: =IF(OR(C7="",C7="Automatico"),IF(YEAR(C11)=C4,MONTH(C11),IF(YEAR(C11)>C4,12,1)),IFERROR(MATCH(C7,Elenchi!$A$2:$A$13,0),12))
B13: Mese di riferimento usato (nome) | C13: =INDEX(Elenchi!$A$2:$A$13,C12)
B15: Membri della famiglia (facoltativo) | D15: Per la colonna «Chi» dei Movimenti e il riepilogo per persona in Dashboard.
B16: Membro 1 | C16: Marco
B17: Membro 2 | C17: Giulia
B18: Membro 3 | C18: Sofia
B19: Membro 4
B20: Membro 5
B21: Membro 6
B23: Conti e metodi di pagamento | D23: Per la colonna «Conto o metodo» dei Movimenti. Puoi rinominarli.
B24: Conto 1 | C24: Conto corrente
B25: Conto 2 | C25: Carta di debito
B26: Conto 3 | C26: Carta di credito
B27: Conto 4 | C27: Contanti
B28: Conto 5 | C28: Carta prepagata
B29: Conto 6
B30: Conto 7
B31: Conto 8

Sheet Categorie
A1: Categorie
A2: Rinomina, aggiungi o svuota le categorie. Non eliminare le righe: per togliere una categoria cancella nome e tipo.
A3: Se rinomini una categoria già usata, correggi anche i movimenti: il registro segnala «Categoria non trovata».
A4: Nei nomi non usare i simboli * ? ~ e non iniziare con < > =.
A5: Categoria | B5: Tipo | C5: Note | D5: Controllo
A6: Stipendio Marco | B6: Entrata | C6: Stipendio netto. | D6: =IF(AND(A6="",B6=""),"",IF(A6="","Manca il nome",IF(OR(ISNUMBER(FIND("*",A6)),ISNUMBER(FIND("?",A6)),ISNUMBER(FIND("~",A6)),ISNUMBER(FIND(LEFT(A6,1),"<>="))),"Simbolo non ammesso",IF(COUNTIF($A$6:$A$65,A6)>1,"Nome doppio",IF(B6="","Manca il tipo","")))))
A7: Stipendio Giulia | B7: Entrata | C7: Stipendio netto. | D7: =IF(AND(A7="",B7=""),"",IF(A7="","Manca il nome",IF(OR(ISNUMBER(FIND("*",A7)),ISNUMBER(FIND("?",A7)),ISNUMBER(FIND("~",A7)),ISNUMBER(FIND(LEFT(A7,1),"<>="))),"Simbolo non ammesso",IF(COUNTIF($A$6:$A$65,A7)>1,"Nome doppio",IF(B7="","Manca il tipo","")))))
A8: Tredicesima e quattordicesima | B8: Entrata | C8: Mensilità aggiuntive. | D8: =IF(AND(A8="",B8=""),"",IF(A8="","Manca il nome",IF(OR(ISNUMBER(FIND("*",A8)),ISNUMBER(FIND("?",A8)),ISNUMBER(FIND("~",A8)),ISNUMBER(FIND(LEFT(A8,1),"<>="))),"Simbolo non ammesso",IF(COUNTIF($A$6:$A$65,A8)>1,"Nome doppio",IF(B8="","Manca il tipo","")))))
A9: Assegno unico figli | B9: Entrata | C9: Assegno unico e universale INPS. | D9: =IF(AND(A9="",B9=""),"",IF(A9="","Manca il nome",IF(OR(ISNUMBER(FIND("*",A9)),ISNUMBER(FIND("?",A9)),ISNUMBER(FIND("~",A9)),ISNUMBER(FIND(LEFT(A9,1),"<>="))),"Simbolo non ammesso",IF(COUNTIF($A$6:$A$65,A9)>1,"Nome doppio",IF(B9="","Manca il tipo","")))))
A10: Entrate extra | B10: Entrata | C10: Lavori occasionali, vendita di oggetti usati. | D10: =IF(AND(A10="",B10=""),"",IF(A10="","Manca il nome",IF(OR(ISNUMBER(FIND("*",A10)),ISNUMBER(FIND("?",A10)),ISNUMBER(FIND("~",A10)),ISNUMBER(FIND(LEFT(A10,1),"<>="))),"Simbolo non ammesso",IF(COUNTIF($A$6:$A$65,A10)>1,"Nome doppio",IF(B10="","Manca il tipo","")))))
A11: Rimborsi e altre entrate | B11: Entrata | C11: Rimborso del 730, rimborsi spese, regali in denaro. | D11: =IF(AND(A11="",B11=""),"",IF(A11="","Manca il nome",IF(OR(ISNUMBER(FIND("*",A11)),ISNUMBER(FIND("?",A11)),ISNUMBER(FIND("~",A11)),ISNUMBER(FIND(LEFT(A11,1),"<>="))),"Simbolo non ammesso",IF(COUNTIF($A$6:$A$65,A11)>1,"Nome doppio",IF(B11="","Manca il tipo","")))))
A12: Affitto o rata mutuo | B12: Spesa fissa | C12: Per stimare la rata del mutuo: nettochiaro.com/calcolo-rata-mutuo | D12: =IF(AND(A12="",B12=""),"",IF(A12="","Manca il nome",IF(OR(ISNUMBER(FIND("*",A12)),ISNUMBER(FIND("?",A12)),ISNUMBER(FIND("~",A12)),ISNUMBER(FIND(LEFT(A12,1),"<>="))),"Simbolo non ammesso",IF(COUNTIF($A$6:$A$65,A12)>1,"Nome doppio",IF(B12="","Manca il tipo","")))))
A13: Condominio | B13: Spesa fissa | D13: =IF(AND(A13="",B13=""),"",IF(A13="","Manca il nome",IF(OR(ISNUMBER(FIND("*",A13)),ISNUMBER(FIND("?",A13)),ISNUMBER(FIND("~",A13)),ISNUMBER(FIND(LEFT(A13,1),"<>="))),"Simbolo non ammesso",IF(COUNTIF($A$6:$A$65,A13)>1,"Nome doppio",IF(B13="","Manca il tipo","")))))
A14: Luce | B14: Spesa fissa | D14: =IF(AND(A14="",B14=""),"",IF(A14="","Manca il nome",IF(OR(ISNUMBER(FIND("*",A14)),ISNUMBER(FIND("?",A14)),ISNUMBER(FIND("~",A14)),ISNUMBER(FIND(LEFT(A14,1),"<>="))),"Simbolo non ammesso",IF(COUNTIF($A$6:$A$65,A14)>1,"Nome doppio",IF(B14="","Manca il tipo","")))))
A15: Gas | B15: Spesa fissa | D15: =IF(AND(A15="",B15=""),"",IF(A15="","Manca il nome",IF(OR(ISNUMBER(FIND("*",A15)),ISNUMBER(FIND("?",A15)),ISNUMBER(FIND("~",A15)),ISNUMBER(FIND(LEFT(A15,1),"<>="))),"Simbolo non ammesso",IF(COUNTIF($A$6:$A$65,A15)>1,"Nome doppio",IF(B15="","Manca il tipo","")))))
A16: Acqua | B16: Spesa fissa | D16: =IF(AND(A16="",B16=""),"",IF(A16="","Manca il nome",IF(OR(ISNUMBER(FIND("*",A16)),ISNUMBER(FIND("?",A16)),ISNUMBER(FIND("~",A16)),ISNUMBER(FIND(LEFT(A16,1),"<>="))),"Simbolo non ammesso",IF(COUNTIF($A$6:$A$65,A16)>1,"Nome doppio",IF(B16="","Manca il tipo","")))))
A17: TARI | B17: Spesa fissa | C17: Tassa sui rifiuti del Comune. | D17: =IF(AND(A17="",B17=""),"",IF(A17="","Manca il nome",IF(OR(ISNUMBER(FIND("*",A17)),ISNUMBER(FIND("?",A17)),ISNUMBER(FIND("~",A17)),ISNUMBER(FIND(LEFT(A17,1),"<>="))),"Simbolo non ammesso",IF(COUNTIF($A$6:$A$65,A17)>1,"Nome doppio",IF(B17="","Manca il tipo","")))))
A18: Internet e telefono | B18: Spesa fissa | D18: =IF(AND(A18="",B18=""),"",IF(A18="","Manca il nome",IF(OR(ISNUMBER(FIND("*",A18)),ISNUMBER(FIND("?",A18)),ISNUMBER(FIND("~",A18)),ISNUMBER(FIND(LEFT(A18,1),"<>="))),"Simbolo non ammesso",IF(COUNTIF($A$6:$A$65,A18)>1,"Nome doppio",IF(B18="","Manca il tipo","")))))
A19: Assicurazioni | B19: Spesa fissa | C19: Auto, casa, salute, vita. | D19: =IF(AND(A19="",B19=""),"",IF(A19="","Manca il nome",IF(OR(ISNUMBER(FIND("*",A19)),ISNUMBER(FIND("?",A19)),ISNUMBER(FIND("~",A19)),ISNUMBER(FIND(LEFT(A19,1),"<>="))),"Simbolo non ammesso",IF(COUNTIF($A$6:$A$65,A19)>1,"Nome doppio",IF(B19="","Manca il tipo","")))))
A20: Bollo auto | B20: Spesa fissa | C20: Tassa automobilistica regionale. | D20: =IF(AND(A20="",B20=""),"",IF(A20="","Manca il nome",IF(OR(ISNUMBER(FIND("*",A20)),ISNUMBER(FIND("?",A20)),ISNUMBER(FIND("~",A20)),ISNUMBER(FIND(LEFT(A20,1),"<>="))),"Simbolo non ammesso",IF(COUNTIF($A$6:$A$65,A20)>1,"Nome doppio",IF(B20="","Manca il tipo","")))))
A21: Abbonamenti | B21: Spesa fissa | C21: Streaming, palestra, quotidiani, app. | D21: =IF(AND(A21="",B21=""),"",IF(A21="","Manca il nome",IF(OR(ISNUMBER(FIND("*",A21)),ISNUMBER(FIND("?",A21)),ISNUMBER(FIND("~",A21)),ISNUMBER(FIND(LEFT(A21,1),"<>="))),"Simbolo non ammesso",IF(COUNTIF($A$6:$A$65,A21)>1,"Nome doppio",IF(B21="","Manca il tipo","")))))
A22: Rate di prestiti | B22: Spesa fissa | C22: Prestiti personali, auto, acquisti a rate. Dettaglio nel foglio Debiti. | D22: =IF(AND(A22="",B22=""),"",IF(A22="","Manca il nome",IF(OR(ISNUMBER(FIND("*",A22)),ISNUMBER(FIND("?",A22)),ISNUMBER(FIND("~",A22)),ISNUMBER(FIND(LEFT(A22,1),"<>="))),"Simbolo non ammesso",IF(COUNTIF($A$6:$A$65,A22)>1,"Nome doppio",IF(B22="","Manca il tipo","")))))
A23: Spesa alimentare | B23: Spesa variabile | C23: Supermercato, mercato, prodotti per la casa. | D23: =IF(AND(A23="",B23=""),"",IF(A23="","Manca il nome",IF(OR(ISNUMBER(FIND("*",A23)),ISNUMBER(FIND("?",A23)),ISNUMBER(FIND("~",A23)),ISNUMBER(FIND(LEFT(A23,1),"<>="))),"Simbolo non ammesso",IF(COUNTIF($A$6:$A$65,A23)>1,"Nome doppio",IF(B23="","Manca il tipo","")))))
A24: Carburante | B24: Spesa variabile | D24: =IF(AND(A24="",B24=""),"",IF(A24="","Manca il nome",IF(OR(ISNUMBER(FIND("*",A24)),ISNUMBER(FIND("?",A24)),ISNUMBER(FIND("~",A24)),ISNUMBER(FIND(LEFT(A24,1),"<>="))),"Simbolo non ammesso",IF(COUNTIF($A$6:$A$65,A24)>1,"Nome doppio",IF(B24="","Manca il tipo","")))))
A25: Trasporti | B25: Spesa variabile | C25: Mezzi pubblici, treni, parcheggi, pedaggi. | D25: =IF(AND(A25="",B25=""),"",IF(A25="","Manca il nome",IF(OR(ISNUMBER(FIND("*",A25)),ISNUMBER(FIND("?",A25)),ISNUMBER(FIND("~",A25)),ISNUMBER(FIND(LEFT(A25,1),"<>="))),"Simbolo non ammesso",IF(COUNTIF($A$6:$A$65,A25)>1,"Nome doppio",IF(B25="","Manca il tipo","")))))
A26: Farmacia e salute | B26: Spesa variabile | C26: Farmaci, visite, ticket, dentista. | D26: =IF(AND(A26="",B26=""),"",IF(A26="","Manca il nome",IF(OR(ISNUMBER(FIND("*",A26)),ISNUMBER(FIND("?",A26)),ISNUMBER(FIND("~",A26)),ISNUMBER(FIND(LEFT(A26,1),"<>="))),"Simbolo non ammesso",IF(COUNTIF($A$6:$A$65,A26)>1,"Nome doppio",IF(B26="","Manca il tipo","")))))
A27: Scuola e figli | B27: Spesa variabile | C27: Mensa, libri, gite, sport, centri estivi. | D27: =IF(AND(A27="",B27=""),"",IF(A27="","Manca il nome",IF(OR(ISNUMBER(FIND("*",A27)),ISNUMBER(FIND("?",A27)),ISNUMBER(FIND("~",A27)),ISNUMBER(FIND(LEFT(A27,1),"<>="))),"Simbolo non ammesso",IF(COUNTIF($A$6:$A$65,A27)>1,"Nome doppio",IF(B27="","Manca il tipo","")))))
A28: Casa e manutenzione | B28: Spesa variabile | C28: Piccoli lavori, arredi, elettrodomestici. | D28: =IF(AND(A28="",B28=""),"",IF(A28="","Manca il nome",IF(OR(ISNUMBER(FIND("*",A28)),ISNUMBER(FIND("?",A28)),ISNUMBER(FIND("~",A28)),ISNUMBER(FIND(LEFT(A28,1),"<>="))),"Simbolo non ammesso",IF(COUNTIF($A$6:$A$65,A28)>1,"Nome doppio",IF(B28="","Manca il tipo","")))))
A29: Abbigliamento | B29: Spesa variabile | D29: =IF(AND(A29="",B29=""),"",IF(A29="","Manca il nome",IF(OR(ISNUMBER(FIND("*",A29)),ISNUMBER(FIND("?",A29)),ISNUMBER(FIND("~",A29)),ISNUMBER(FIND(LEFT(A29,1),"<>="))),"Simbolo non ammesso",IF(COUNTIF($A$6:$A$65,A29)>1,"Nome doppio",IF(B29="","Manca il tipo","")))))
A30: Svago | B30: Spesa variabile | C30: Ristoranti, bar, cinema, hobby. | D30: =IF(AND(A30="",B30=""),"",IF(A30="","Manca il nome",IF(OR(ISNUMBER(FIND("*",A30)),ISNUMBER(FIND("?",A30)),ISNUMBER(FIND("~",A30)),ISNUMBER(FIND(LEFT(A30,1),"<>="))),"Simbolo non ammesso",IF(COUNTIF($A$6:$A$65,A30)>1,"Nome doppio",IF(B30="","Manca il tipo","")))))
A31: Regali | B31: Spesa variabile | D31: =IF(AND(A31="",B31=""),"",IF(A31="","Manca il nome",IF(OR(ISNUMBER(FIND("*",A31)),ISNUMBER(FIND("?",A31)),ISNUMBER(FIND("~",A31)),ISNUMBER(FIND(LEFT(A31,1),"<>="))),"Simbolo non ammesso",IF(COUNTIF($A$6:$A$65,A31)>1,"Nome doppio",IF(B31="","Manca il tipo","")))))
A32: Vacanze | B32: Spesa variabile | D32: =IF(AND(A32="",B32=""),"",IF(A32="","Manca il nome",IF(OR(ISNUMBER(FIND("*",A32)),ISNUMBER(FIND("?",A32)),ISNUMBER(FIND("~",A32)),ISNUMBER(FIND(LEFT(A32,1),"<>="))),"Simbolo non ammesso",IF(COUNTIF($A$6:$A$65,A32)>1,"Nome doppio",IF(B32="","Manca il tipo","")))))
A33: Imprevisti | B33: Spesa variabile | C33: Riparazioni e spese non previste. | D33: =IF(AND(A33="",B33=""),"",IF(A33="","Manca il nome",IF(OR(ISNUMBER(FIND("*",A33)),ISNUMBER(FIND("?",A33)),ISNUMBER(FIND("~",A33)),ISNUMBER(FIND(LEFT(A33,1),"<>="))),"Simbolo non ammesso",IF(COUNTIF($A$6:$A$65,A33)>1,"Nome doppio",IF(B33="","Manca il tipo","")))))
A34: Fondo emergenze | B34: Risparmio e investimenti | C34: Versamenti sul conto di riserva. | D34: =IF(AND(A34="",B34=""),"",IF(A34="","Manca il nome",IF(OR(ISNUMBER(FIND("*",A34)),ISNUMBER(FIND("?",A34)),ISNUMBER(FIND("~",A34)),ISNUMBER(FIND(LEFT(A34,1),"<>="))),"Simbolo non ammesso",IF(COUNTIF($A$6:$A$65,A34)>1,"Nome doppio",IF(B34="","Manca il tipo","")))))
A35: Obiettivi di risparmio | B35: Risparmio e investimenti | C35: Versamenti per gli obiettivi del foglio Obiettivi. | D35: =IF(AND(A35="",B35=""),"",IF(A35="","Manca il nome",IF(OR(ISNUMBER(FIND("*",A35)),ISNUMBER(FIND("?",A35)),ISNUMBER(FIND("~",A35)),ISNUMBER(FIND(LEFT(A35,1),"<>="))),"Simbolo non ammesso",IF(COUNTIF($A$6:$A$65,A35)>1,"Nome doppio",IF(B35="","Manca il tipo","")))))
A36: Investimenti | B36: Risparmio e investimenti | C36: Piani di accumulo, titoli, buoni. | D36: =IF(AND(A36="",B36=""),"",IF(A36="","Manca il nome",IF(OR(ISNUMBER(FIND("*",A36)),ISNUMBER(FIND("?",A36)),ISNUMBER(FIND("~",A36)),ISNUMBER(FIND(LEFT(A36,1),"<>="))),"Simbolo non ammesso",IF(COUNTIF($A$6:$A$65,A36)>1,"Nome doppio",IF(B36="","Manca il tipo","")))))
A37: Previdenza complementare | B37: Risparmio e investimenti | C37: Versamenti volontari al fondo pensione. | D37: =IF(AND(A37="",B37=""),"",IF(A37="","Manca il nome",IF(OR(ISNUMBER(FIND("*",A37)),ISNUMBER(FIND("?",A37)),ISNUMBER(FIND("~",A37)),ISNUMBER(FIND(LEFT(A37,1),"<>="))),"Simbolo non ammesso",IF(COUNTIF($A$6:$A$65,A37)>1,"Nome doppio",IF(B37="","Manca il tipo","")))))
D38: =IF(AND(A38="",B38=""),"",IF(A38="","Manca il nome",IF(OR(ISNUMBER(FIND("*",A38)),ISNUMBER(FIND("?",A38)),ISNUMBER(FIND("~",A38)),ISNUMBER(FIND(LEFT(A38,1),"<>="))),"Simbolo non ammesso",IF(COUNTIF($A$6:$A$65,A38)>1,"Nome doppio",IF(B38="","Manca il tipo","")))))
D39: =IF(AND(A39="",B39=""),"",IF(A39="","Manca il nome",IF(OR(ISNUMBER(FIND("*",A39)),ISNUMBER(FIND("?",A39)),ISNUMBER(FIND("~",A39)),ISNUMBER(FIND(LEFT(A39,1),"<>="))),"Simbolo non ammesso",IF(COUNTIF($A$6:$A$65,A39)>1,"Nome doppio",IF(B39="","Manca il tipo","")))))
D40: =IF(AND(A40="",B40=""),"",IF(A40="","Manca il nome",IF(OR(ISNUMBER(FIND("*",A40)),ISNUMBER(FIND("?",A40)),ISNUMBER(FIND("~",A40)),ISNUMBER(FIND(LEFT(A40,1),"<>="))),"Simbolo non ammesso",IF(COUNTIF($A$6:$A$65,A40)>1,"Nome doppio",IF(B40="","Manca il tipo","")))))
...

Sheet Movimenti
A1: Movimenti
A2: Un movimento per riga. Importi sempre positivi: il tipo lo decide la categoria. Un rimborso su una spesa si scrive in negativo.
C3: Movimenti registrati | D3: =COUNT(D6:D2005) | G3: Righe da controllare | H3: =COUNTIF(H6:H2005,"?*")
A5: Data | B5: Descrizione | C5: Categoria | D5: Importo | E5: Conto o metodo | F5: Chi (facoltativo) | G5: Tipo | H5: Controllo
A6: 46023 | B6: Rata mutuo | C6: Affitto o rata mutuo | D6: 680 | E6: Conto corrente | G6: =IF(C6="","",IFERROR(INDEX(Categorie!$B$6:$B$65,MATCH(C6,Categorie!$A$6:$A$65,0))&"","")) | H6: =IF(AND(A6="",C6="",D6=""),"",IF(D6="","Manca l'importo",IF(NOT(ISNUMBER(D6)),"Importo non valido",IF(NOT(ISNUMBER(A6)),"Data mancante o non valida",IF(YEAR(A6)<>Impostazioni!$C$4,"Fuori dall'anno",IF(C6="","Manca la categoria",IF(ISNA(MATCH(C6,Categorie!$A$6:$A$65,0)),"Categoria non trovata",IF(G6="","Categoria senza tipo",""))))))))
A7: 46025 | B7: Spesa settimanale | C7: Spesa alimentare | D7: 97.53 | E7: Carta di debito | G7: =IF(C7="","",IFERROR(INDEX(Categorie!$B$6:$B$65,MATCH(C7,Categorie!$A$6:$A$65,0))&"","")) | H7: =IF(AND(A7="",C7="",D7=""),"",IF(D7="","Manca l'importo",IF(NOT(ISNUMBER(D7)),"Importo non valido",IF(NOT(ISNUMBER(A7)),"Data mancante o non valida",IF(YEAR(A7)<>Impostazioni!$C$4,"Fuori dall'anno",IF(C7="","Manca la categoria",IF(ISNA(MATCH(C7,Categorie!$A$6:$A$65,0)),"Categoria non trovata",IF(G7="","Categoria senza tipo",""))))))))
A8: 46025 | B8: Abbonamento bus Sofia | C8: Trasporti | D8: 25 | E8: Carta di debito | F8: Sofia | G8: =IF(C8="","",IFERROR(INDEX(Categorie!$B$6:$B$65,MATCH(C8,Categorie!$A$6:$A$65,0))&"","")) | H8: =IF(AND(A8="",C8="",D8=""),"",IF(D8="","Manca l'importo",IF(NOT(ISNUMBER(D8)),"Importo non valido",IF(NOT(ISNUMBER(A8)),"Data mancante o non valida",IF(YEAR(A8)<>Impostazioni!$C$4,"Fuori dall'anno",IF(C8="","Manca la categoria",IF(ISNA(MATCH(C8,Categorie!$A$6:$A$65,0)),"Categoria non trovata",IF(G8="","Categoria senza tipo",""))))))))
A9: 46026 | B9: Mensa scolastica | C9: Scuola e figli | D9: 78 | E9: Conto corrente | F9: Sofia | G9: =IF(C9="","",IFERROR(INDEX(Categorie!$B$6:$B$65,MATCH(C9,Categorie!$A$6:$A$65,0))&"","")) | H9: =IF(AND(A9="",C9="",D9=""),"",IF(D9="","Manca l'importo",IF(NOT(ISNUMBER(D9)),"Importo non valido",IF(NOT(ISNUMBER(A9)),"Data mancante o non valida",IF(YEAR(A9)<>Impostazioni!$C$4,"Fuori dall'anno",IF(C9="","Manca la categoria",IF(ISNA(MATCH(C9,Categorie!$A$6:$A$65,0)),"Categoria non trovata",IF(G9="","Categoria senza tipo",""))))))))
A10: 46026 | B10: Cena con amici | C10: Svago | D10: 48.88 | E10: Carta di debito | G10: =IF(C10="","",IFERROR(INDEX(Categorie!$B$6:$B$65,MATCH(C10,Categorie!$A$6:$A$65,0))&"","")) | H10: =IF(AND(A10="",C10="",D10=""),"",IF(D10="","Manca l'importo",IF(NOT(ISNUMBER(D10)),"Importo non valido",IF(NOT(ISNUMBER(A10)),"Data mancante o non valida",IF(YEAR(A10)<>Impostazioni!$C$4,"Fuori dall'anno",IF(C10="","Manca la categoria",IF(ISNA(MATCH(C10,Categorie!$A$6:$A$65,0)),"Categoria non trovata",IF(G10="","Categoria senza tipo",""))))))))
A11: 46027 | B11: Rifornimento | C11: Carburante | D11: 58.64 | E11: Carta di credito | F11: Marco | G11: =IF(C11="","",IFERROR(INDEX(Categorie!$B$6:$B$65,MATCH(C11,Categorie!$A$6:$A$65,0))&"","")) | H11: =IF(AND(A11="",C11="",D11=""),"",IF(D11="","Manca l'importo",IF(NOT(ISNUMBER(D11)),"Importo non valido",IF(NOT(ISNUMBER(A11)),"Data mancante o non valida",IF(YEAR(A11)<>Impostazioni!$C$4,"Fuori dall'anno",IF(C11="","Manca la categoria",IF(ISNA(MATCH(C11,Categorie!$A$6:$A$65,0)),"Categoria non trovata",IF(G11="","Categoria senza tipo",""))))))))
A12: 46027 | B12: Fibra casa | C12: Internet e telefono | D12: 27.9 | E12: Carta di credito | G12: =IF(C12="","",IFERROR(INDEX(Categorie!$B$6:$B$65,MATCH(C12,Categorie!$A$6:$A$65,0))&"","")) | H12: =IF(AND(A12="",C12="",D12=""),"",IF(D12="","Manca l'importo",IF(NOT(ISNUMBER(D12)),"Importo non valido",IF(NOT(ISNUMBER(A12)),"Data mancante o non valida",IF(YEAR(A12)<>Impostazioni!$C$4,"Fuori dall'anno",IF(C12="","Manca la categoria",IF(ISNA(MATCH(C12,Categorie!$A$6:$A$65,0)),"Categoria non trovata",IF(G12="","Categoria senza tipo",""))))))))
A13: 46027 | B13: Telefono Giulia | C13: Internet e telefono | D13: 7.99 | E13: Carta di credito | F13: Giulia | G13: =IF(C13="","",IFERROR(INDEX(Categorie!$B$6:$B$65,MATCH(C13,Categorie!$A$6:$A$65,0))&"","")) | H13: =IF(AND(A13="",C13="",D13=""),"",IF(D13="","Manca l'importo",IF(NOT(ISNUMBER(D13)),"Importo non valido",IF(NOT(ISNUMBER(A13)),"Data mancante o non valida",IF(YEAR(A13)<>Impostazioni!$C$4,"Fuori dall'anno",IF(C13="","Manca la categoria",IF(ISNA(MATCH(C13,Categorie!$A$6:$A$65,0)),"Categoria non trovata",IF(G13="","Categoria senza tipo",""))))))))
A14: 46027 | B14: Telefono Marco | C14: Internet e telefono | D14: 9.99 | E14: Carta di credito | F14: Marco | G14: =IF(C14="","",IFERROR(INDEX(Categorie!$B$6:$B$65,MATCH(C14,Categorie!$A$6:$A$65,0))&"","")) | H14: =IF(AND(A14="",C14="",D14=""),"",IF(D14="","Manca l'importo",IF(NOT(ISNUMBER(D14)),"Importo non valido",IF(NOT(ISNUMBER(A14)),"Data mancante o non valida",IF(YEAR(A14)<>Impostazioni!$C$4,"Fuori dall'anno",IF(C14="","Manca la categoria",IF(ISNA(MATCH(C14,Categorie!$A$6:$A$65,0)),"Categoria non trovata",IF(G14="","Categoria senza tipo",""))))))))
A15: 46029 | B15: Spesa al mercato | C15: Spesa alimentare | D15: 29.66 | E15: Contanti | G15: =IF(C15="","",IFERROR(INDEX(Categorie!$B$6:$B$65,MATCH(C15,Categorie!$A$6:$A$65,0))&"","")) | H15: =IF(AND(A15="",C15="",D15=""),"",IF(D15="","Manca l'importo",IF(NOT(ISNUMBER(D15)),"Importo non valido",IF(NOT(ISNUMBER(A15)),"Data mancante o non valida",IF(YEAR(A15)<>Impostazioni!$C$4,"Fuori dall'anno",IF(C15="","Manca la categoria",IF(ISNA(MATCH(C15,Categorie!$A$6:$A$65,0)),"Categoria non trovata",IF(G15="","Categoria senza tipo",""))))))))
A16: 46030 | B16: Musica in streaming | C16: Abbonamenti | D16: 10.99 | E16: Carta di credito | F16: Giulia | G16: =IF(C16="","",IFERROR(INDEX(Categorie!$B$6:$B$65,MATCH(C16,Categorie!$A$6:$A$65,0))&"","")) | H16: =IF(AND(A16="",C16="",D16=""),"",IF(D16="","Manca l'importo",IF(NOT(ISNUMBER(D16)),"Importo non valido",IF(NOT(ISNUMBER(A16)),"Data mancante o non valida",IF(YEAR(A16)<>Impostazioni!$C$4,"Fuori dall'anno",IF(C16="","Manca la categoria",IF(ISNA(MATCH(C16,Categorie!$A$6:$A$65,0)),"Categoria non trovata",IF(G16="","Categoria senza tipo",""))))))))
A17: 46030 | B17: Streaming video | C17: Abbonamenti | D17: 13.99 | E17: Carta di credito | G17: =IF(C17="","",IFERROR(INDEX(Categorie!$B$6:$B$65,MATCH(C17,Categorie!$A$6:$A$65,0))&"","")) | H17: =IF(AND(A17="",C17="",D17=""),"",IF(D17="","Manca l'importo",IF(NOT(ISNUMBER(D17)),"Importo non valido",IF(NOT(ISNUMBER(A17)),"Data mancante o non valida",IF(YEAR(A17)<>Impostazioni!$C$4,"Fuori dall'anno",IF(C17="","Manca la categoria",IF(ISNA(MATCH(C17,Categorie!$A$6:$A$65,0)),"Categoria non trovata",IF(G17="","Categoria senza tipo",""))))))))
A18: 46031 | B18: Parcheggio | C18: Trasporti | D18: 8.26 | E18: Contanti | G18: =IF(C18="","",IFERROR(INDEX(Categorie!$B$6:$B$65,MATCH(C18,Categorie!$A$6:$A$65,0))&"","")) | H18: =IF(AND(A18="",C18="",D18=""),"",IF(D18="","Manca l'importo",IF(NOT(ISNUMBER(D18)),"Importo non valido",IF(NOT(ISNUMBER(A18)),"Data mancante o non valida",IF(YEAR(A18)<>Impostazioni!$C$4,"Fuori dall'anno",IF(C18="","Manca la categoria",IF(ISNA(MATCH(C18,Categorie!$A$6:$A$65,0)),"Categoria non trovata",IF(G18="","Categoria senza tipo",""))))))))
A19: 46032 | B19: Saldi invernali | C19: Abbigliamento | D19: 142.8 | E19: Carta di credito | F19: Giulia | G19: =IF(C19="","",IFERROR(INDEX(Categorie!$B$6:$B$65,MATCH(C19,Categorie!$A$6:$A$65,0))&"","")) | H19: =IF(AND(A19="",C19="",D19=""),"",IF(D19="","Manca l'importo",IF(NOT(ISNUMBER(D19)),"Importo non valido",IF(NOT(ISNUMBER(A19)),"Data mancante o non valida",IF(YEAR(A19)<>Impostazioni!$C$4,"Fuori dall'anno",IF(C19="","Manca la categoria",IF(ISNA(MATCH(C19,Categorie!$A$6:$A$65,0)),"Categoria non trovata",IF(G19="","Categoria senza tipo",""))))))))
A20: 46032 | B20: Rata condominio trimestrale | C20: Condominio | D20: 270 | E20: Conto corrente | G20: =IF(C20="","",IFERROR(INDEX(Categorie!$B$6:$B$65,MATCH(C20,Categorie!$A$6:$A$65,0))&"","")) | H20: =IF(AND(A20="",C20="",D20=""),"",IF(D20="","Manca l'importo",IF(NOT(ISNUMBER(D20)),"Importo non valido",IF(NOT(ISNUMBER(A20)),"Data mancante o non valida",IF(YEAR(A20)<>Impostazioni!$C$4,"Fuori dall'anno",IF(C20="","Manca la categoria",IF(ISNA(MATCH(C20,Categorie!$A$6:$A$65,0)),"Categoria non trovata",IF(G20="","Categoria senza tipo",""))))))))
A21: 46032 | B21: Spesa settimanale | C21: Spesa alimentare | D21: 100.34 | E21: Carta di debito | G21: =IF(C21="","",IFERROR(INDEX(Categorie!$B$6:$B$65,MATCH(C21,Categorie!$A$6:$A$65,0))&"","")) | H21: =IF(AND(A21="",C21="",D21=""),"",IF(D21="","Manca l'importo",IF(NOT(ISNUMBER(D21)),"Importo non valido",IF(NOT(ISNUMBER(A21)),"Data mancante o non valida",IF(YEAR(A21)<>Impostazioni!$C$4,"Fuori dall'anno",IF(C21="","Manca la categoria",IF(ISNA(MATCH(C21,Categorie!$A$6:$A$65,0)),"Categoria non trovata",IF(G21="","Categoria senza tipo",""))))))))
A22: 46034 | B22: Corso di nuoto Sofia | C22: Scuola e figli | D22: 165 | E22: Carta di debito | F22: Sofia | G22: =IF(C22="","",IFERROR(INDEX(Categorie!$B$6:$B$65,MATCH(C22,Categorie!$A$6:$A$65,0))&"","")) | H22: =IF(AND(A22="",C22="",D22=""),"",IF(D22="","Manca l'importo",IF(NOT(ISNUMBER(D22)),"Importo non valido",IF(NOT(ISNUMBER(A22)),"Data mancante o non valida",IF(YEAR(A22)<>Impostazioni!$C$4,"Fuori dall'anno",IF(C22="","Manca la categoria",IF(ISNA(MATCH(C22,Categorie!$A$6:$A$65,0)),"Categoria non trovata",IF(G22="","Categoria senza tipo",""))))))))
A23: 46037 | B23: Rata carta revolving | C23: Rate di prestiti | D23: 60 | E23: Conto corrente | G23: =IF(C23="","",IFERROR(INDEX(Categorie!$B$6:$B$65,MATCH(C23,Categorie!$A$6:$A$65,0))&"","")) | H23: =IF(AND(A23="",C23="",D23=""),"",IF(D23="","Manca l'importo",IF(NOT(ISNUMBER(D23)),"Importo non valido",IF(NOT(ISNUMBER(A23)),"Data mancante o non valida",IF(YEAR(A23)<>Impostazioni!$C$4,"Fuori dall'anno",IF(C23="","Manca la categoria",IF(ISNA(MATCH(C23,Categorie!$A$6:$A$65,0)),"Categoria non trovata",IF(G23="","Categoria senza tipo",""))))))))
A24: 46037 | B24: Rata lavatrice a tasso zero | C24: Rate di prestiti | D24: 40 | E24: Conto corrente | G24: =IF(C24="","",IFERROR(INDEX(Categorie!$B$6:$B$65,MATCH(C24,Categorie!$A$6:$A$65,0))&"","")) | H24: =IF(AND(A24="",C24="",D24=""),"",IF(D24="","Manca l'importo",IF(NOT(ISNUMBER(D24)),"Importo non valido",IF(NOT(ISNUMBER(A24)),"Data mancante o non valida",IF(YEAR(A24)<>Impostazioni!$C$4,"Fuori dall'anno",IF(C24="","Manca la categoria",IF(ISNA(MATCH(C24,Categorie!$A$6:$A$65,0)),"Categoria non trovata",IF(G24="","Categoria senza tipo",""))))))))
A25: 46037 | B25: Rata prestito auto | C25: Rate di prestiti | D25: 210 | E25: Conto corrente | G25: =IF(C25="","",IFERROR(INDEX(Categorie!$B$6:$B$65,MATCH(C25,Categorie!$A$6:$A$65,0))&"","")) | H25: =IF(AND(A25="",C25="",D25=""),"",IF(D25="","Manca l'importo",IF(NOT(ISNUMBER(D25)),"Importo non valido",IF(NOT(ISNUMBER(A25)),"Data mancante o non valida",IF(YEAR(A25)<>Impostazioni!$C$4,"Fuori dall'anno",IF(C25="","Manca la categoria",IF(ISNA(MATCH(C25,Categorie!$A$6:$A$65,0)),"Categoria non trovata",IF(G25="","Categoria senza tipo",""))))))))
A26: 46038 | B26: Cena con amici | C26: Svago | D26: 53.4 | E26: Carta di debito | G26: =IF(C26="","",IFERROR(INDEX(Categorie!$B$6:$B$65,MATCH(C26,Categorie!$A$6:$A$65,0))&"","")) | H26: =IF(AND(A26="",C26="",D26=""),"",IF(D26="","Manca l'importo",IF(NOT(ISNUMBER(D26)),"Importo non valido",IF(NOT(ISNUMBER(A26)),"Data mancante o non valida",IF(YEAR(A26)<>Impostazioni!$C$4,"Fuori dall'anno",IF(C26="","Manca la categoria",IF(ISNA(MATCH(C26,Categorie!$A$6:$A$65,0)),"Categoria non trovata",IF(G26="","Categoria senza tipo",""))))))))
A27: 46038 | B27: Pizzeria | C27: Svago | D27: 38.28 | E27: Carta di debito | G27: =IF(C27="","",IFERROR(INDEX(Categorie!$B$6:$B$65,MATCH(C27,Categorie!$A$6:$A$65,0))&"","")) | H27: =IF(AND(A27="",C27="",D27=""),"",IF(D27="","Manca l'importo",IF(NOT(ISNUMBER(D27)),"Importo non valido",IF(NOT(ISNUMBER(A27)),"Data mancante o non valida",IF(YEAR(A27)<>Impostazioni!$C$4,"Fuori dall'anno",IF(C27="","Manca la categoria",IF(ISNA(MATCH(C27,Categorie!$A$6:$A$65,0)),"Categoria non trovata",IF(G27="","Categoria senza tipo",""))))))))
A28: 46039 | B28: Rifornimento | C28: Carburante | D28: 55.83 | E28: Carta di credito | F28: Giulia | G28: =IF(C28="","",IFERROR(INDEX(Categorie!$B$6:$B$65,MATCH(C28,Categorie!$A$6:$A$65,0))&"","")) | H28: =IF(AND(A28="",C28="",D28=""),"",IF(D28="","Manca l'importo",IF(NOT(ISNUMBER(D28)),"Importo non valido",IF(NOT(ISNUMBER(A28)),"Data mancante o non valida",IF(YEAR(A28)<>Impostazioni!$C$4,"Fuori dall'anno",IF(C28="","Manca la categoria",IF(ISNA(MATCH(C28,Categorie!$A$6:$A$65,0)),"Categoria non trovata",IF(G28="","Categoria senza tipo",""))))))))
A29: 46039 | B29: Spesa settimanale | C29: Spesa alimentare | D29: 121.05 | E29: Carta di debito | G29: =IF(C29="","",IFERROR(INDEX(Categorie!$B$6:$B$65,MATCH(C29,Categorie!$A$6:$A$65,0))&"","")) | H29: =IF(AND(A29="",C29="",D29=""),"",IF(D29="","Manca l'importo",IF(NOT(ISNUMBER(D29)),"Importo non valido",IF(NOT(ISNUMBER(A29)),"Data mancante o non valida",IF(YEAR(A29)<>Impostazioni!$C$4,"Fuori dall'anno",IF(C29="","Manca la categoria",IF(ISNA(MATCH(C29,Categorie!$A$6:$A$65,0)),"Categoria non trovata",IF(G29="","Categoria senza tipo",""))))))))
A30: 46039 | B30: Libri | C30: Svago | D30: 22.87 | E30: Carta di debito | G30: =IF(C30="","",IFERROR(INDEX(Categorie!$B$6:$B$65,MATCH(C30,Categorie!$A$6:$A$65,0))&"","")) | H30: =IF(AND(A30="",C30="",D30=""),"",IF(D30="","Manca l'importo",IF(NOT(ISNUMBER(D30)),"Importo non valido",IF(NOT(ISNUMBER(A30)),"Data mancante o non valida",IF(YEAR(A30)<>Impostazioni!$C$4,"Fuori dall'anno",IF(C30="","Manca la categoria",IF(ISNA(MATCH(C30,Categorie!$A$6:$A$65,0)),"Categoria non trovata",IF(G30="","Categoria senza tipo",""))))))))
A31: 46040 | B31: Bolletta gas | C31: Gas | D31: 168.03 | E31: Conto corrente | G31: =IF(C31="","",IFERROR(INDEX(Categorie!$B$6:$B$65,MATCH(C31,Categorie!$A$6:$A$65,0))&"","")) | H31: =IF(AND(A31="",C31="",D31=""),"",IF(D31="","Manca l'importo",IF(NOT(ISNUMBER(D31)),"Importo non valido",IF(NOT(ISNUMBER(A31)),"Data mancante o non valida",IF(YEAR(A31)<>Impostazioni!$C$4,"Fuori dall'anno",IF(C31="","Manca la categoria",IF(ISNA(MATCH(C31,Categorie!$A$6:$A$65,0)),"Categoria non trovata",IF(G31="","Categoria senza tipo",""))))))))
A32: 46040 | B32: Bolletta luce | C32: Luce | D32: 78.95 | E32: Conto corrente | G32: =IF(C32="","",IFERROR(INDEX(Categorie!$B$6:$B$65,MATCH(C32,Categorie!$A$6:$A$65,0))&"","")) | H32: =IF(AND(A32="",C32="",D32=""),"",IF(D32="","Manca l'importo",IF(NOT(ISNUMBER(D32)),"Importo non valido",IF(NOT(ISNUMBER(A32)),"Data mancante o non valida",IF(YEAR(A32)<>Impostazioni!$C$4,"Fuori dall'anno",IF(C32="","Manca la categoria",IF(ISNA(MATCH(C32,Categorie!$A$6:$A$65,0)),"Categoria non trovata",IF(G32="","Categoria senza tipo",""))))))))
A33: 46041 | B33: Farmacia | C33: Farmacia e salute | D33: 19.46 | E33: Carta di debito | G33: =IF(C33="","",IFERROR(INDEX(Categorie!$B$6:$B$65,MATCH(C33,Categorie!$A$6:$A$65,0))&"","")) | H33: =IF(AND(A33="",C33="",D33=""),"",IF(D33="","Manca l'importo",IF(NOT(ISNUMBER(D33)),"Importo non valido",IF(NOT(ISNUMBER(A33)),"Data mancante o non valida",IF(YEAR(A33)<>Impostazioni!$C$4,"Fuori dall'anno",IF(C33="","Manca la categoria",IF(ISNA(MATCH(C33,Categorie!$A$6:$A$65,0)),"Categoria non trovata",IF(G33="","Categoria senza tipo",""))))))))
A34: 46042 | B34: Assegno unico INPS | C34: Assegno unico figli | D34: 145.3 | E34: Conto corrente | G34: =IF(C34="","",IFERROR(INDEX(Categorie!$B$6:$B$65,MATCH(C34,Categorie!$A$6:$A$65,0))&"","")) | H34: =IF(AND(A34="",C34="",D34=""),"",IF(D34="","Manca l'importo",IF(NOT(ISNUMBER(D34)),"Importo non valido",IF(NOT(ISNUMBER(A34)),"Data mancante o non valida",IF(YEAR(A34)<>Impostazioni!$C$4,"Fuori dall'anno",IF(C34="","Manca la categoria",IF(ISNA(MATCH(C34,Categorie!$A$6:$A$65,0)),"Categoria non trovata",IF(G34="","Categoria senza tipo",""))))))))
A35: 46042 | B35: Farmacia | C35: Farmacia e salute | D35: 23.53 | E35: Carta di debito | G35: =IF(C35="","",IFERROR(INDEX(Categorie!$B$6:$B$65,MATCH(C35,Categorie!$A$6:$A$65,0))&"","")) | H35: =IF(AND(A35="",C35="",D35=""),"",IF(D35="","Manca l'importo",IF(NOT(ISNUMBER(D35)),"Importo non valido",IF(NOT(ISNUMBER(A35)),"Data mancante o non valida",IF(YEAR(A35)<>Impostazioni!$C$4,"Fuori dall'anno",IF(C35="","Manca la categoria",IF(ISNA(MATCH(C35,Categorie!$A$6:$A$65,0)),"Categoria non trovata",IF(G35="","Categoria senza tipo",""))))))))
A36: 46043 | B36: Spesa al mercato | C36: Spesa alimentare | D36: 32.08 | E36: Contanti | G36: =IF(C36="","",IFERROR(INDEX(Categorie!$B$6:$B$65,MATCH(C36,Categorie!$A$6:$A$65,0))&"","")) | H36: =IF(AND(A36="",C36="",D36=""),"",IF(D36="","Manca l'importo",IF(NOT(ISNUMBER(D36)),"Importo non valido",IF(NOT(ISNUMBER(A36)),"Data mancante o non valida",IF(YEAR(A36)<>Impostazioni!$C$4,"Fuori dall'anno",IF(C36="","Manca la categoria",IF(ISNA(MATCH(C36,Categorie!$A$6:$A$65,0)),"Categoria non trovata",IF(G36="","Categoria senza tipo",""))))))))
A37: 46046 | B37: Spesa settimanale | C37: Spesa alimentare | D37: 113.07 | E37: Carta di debito | G37: =IF(C37="","",IFERROR(INDEX(Categorie!$B$6:$B$65,MATCH(C37,Categorie!$A$6:$A$65,0))&"","")) | H37: =IF(AND(A37="",C37="",D37=""),"",IF(D37="","Manca l'importo",IF(NOT(ISNUMBER(D37)),"Importo non valido",IF(NOT(ISNUMBER(A37)),"Data mancante o non valida",IF(YEAR(A37)<>Impostazioni!$C$4,"Fuori dall'anno",IF(C37="","Manca la categoria",IF(ISNA(MATCH(C37,Categorie!$A$6:$A$65,0)),"Categoria non trovata",IF(G37="","Categoria senza tipo",""))))))))
A38: 46047 | B38: Farmacia | C38: Farmacia e salute | D38: 30.85 | E38: Carta di debito | G38: =IF(C38="","",IFERROR(INDEX(Categorie!$B$6:$B$65,MATCH(C38,Categorie!$A$6:$A$65,0))&"","")) | H38: =IF(AND(A38="",C38="",D38=""),"",IF(D38="","Manca l'importo",IF(NOT(ISNUMBER(D38)),"Importo non valido",IF(NOT(ISNUMBER(A38)),"Data mancante o non valida",IF(YEAR(A38)<>Impostazioni!$C$4,"Fuori dall'anno",IF(C38="","Manca la categoria",IF(ISNA(MATCH(C38,Categorie!$A$6:$A$65,0)),"Categoria non trovata",IF(G38="","Categoria senza tipo",""))))))))
A39: 46049 | B39: Stipendio | C39: Stipendio Giulia | D39: 1480 | E39: Conto corrente | F39: Giulia | G39: =IF(C39="","",IFERROR(INDEX(Categorie!$B$6:$B$65,MATCH(C39,Categorie!$A$6:$A$65,0))&"","")) | H39: =IF(AND(A39="",C39="",D39=""),"",IF(D39="","Manca l'importo",IF(NOT(ISNUMBER(D39)),"Importo non valido",IF(NOT(ISNUMBER(A39)),"Data mancante o non valida",IF(YEAR(A39)<>Impostazioni!$C$4,"Fuori dall'anno",IF(C39="","Manca la categoria",IF(ISNA(MATCH(C39,Categorie!$A$6:$A$65,0)),"Categoria non trovata",IF(G39="","Categoria senza tipo",""))))))))
A40: 46049 | B40: Stipendio | C40: Stipendio Marco | D40: 1850 | E40: Conto corrente | F40: Marco | G40: =IF(C40="","",IFERROR(INDEX(Categorie!$B$6:$B$65,MATCH(C40,Categorie!$A$6:$A$65,0))&"","")) | H40: =IF(AND(A40="",C40="",D40=""),"",IF(D40="","Manca l'importo",IF(NOT(ISNUMBER(D40)),"Importo non valido",IF(NOT(ISNUMBER(A40)),"Data mancante o non valida",IF(YEAR(A40)<>Impostazioni!$C$4,"Fuori dall'anno",IF(C40="","Manca la categoria",IF(ISNA(MATCH(C40,Categorie!$A$6:$A$65,0)),"Categoria non trovata",IF(G40="","Categoria senza tipo",""))))))))
A41: 46050 | B41: Versamento fondo emergenze | C41: Fondo emergenze | D41: 150 | E41: Conto corrente | G41: =IF(C41="","",IFERROR(INDEX(Categorie!$B$6:$B$65,MATCH(C41,Categorie!$A$6:$A$65,0))&"","")) | H41: =IF(AND(A41="",C41="",D41=""),"",IF(D41="","Manca l'importo",IF(NOT(ISNUMBER(D41)),"Importo non valido",IF(NOT(ISNUMBER(A41)),"Data mancante o non valida",IF(YEAR(A41)<>Impostazioni!$C$4,"Fuori dall'anno",IF(C41="","Manca la categoria",IF(ISNA(MATCH(C41,Categorie!$A$6:$A$65,0)),"Categoria non trovata",IF(G41="","Categoria senza tipo",""))))))))
...

Sheet Budget
A1: Budget
A2: Scrivi in colonna C l'importo tipico mensile: i mesi si compilano da soli. Per un mese diverso (TARI, bollo, assicurazioni) scrivi l'importo nella cella del mese.
A3: Per tornare all'importo tipico copia la cella di un mese non modificato. Le righe di riepilogo in alto si calcolano da sole.
D4: 1 | E4: 2 | F4: 3 | G4: 4 | H4: 5 | I4: 6 | J4: 7 | K4: 8 | L4: 9 | M4: 10 | N4: 11 | O4: 12
A5: Voce | B5: Tipo | C5: Importo tipico mensile | D5: Gen | E5: Feb | F5: Mar | G5: Apr | H5: Mag | I5: Giu | J5: Lug | K5: Ago | L5: Set | M5: Ott | N5: Nov | O5: Dic | P5: Totale anno
A6: Entrate | B6: Entrata | C6: =SUMIFS(C$14:C$73,$B$14:$B$73,"Entrata") | D6: =SUMIFS(D$14:D$73,$B$14:$B$73,"Entrata") | E6: =SUMIFS(E$14:E$73,$B$14:$B$73,"Entrata") | F6: =SUMIFS(F$14:F$73,$B$14:$B$73,"Entrata") | G6: =SUMIFS(G$14:G$73,$B$14:$B$73,"Entrata") | H6: =SUMIFS(H$14:H$73,$B$14:$B$73,"Entrata") | I6: =SUMIFS(I$14:I$73,$B$14:$B$73,"Entrata") | J6: =SUMIFS(J$14:J$73,$B$14:$B$73,"Entrata") | ... P6: =SUMIFS(P$14:P$73,$B$14:$B$73,"Entrata")
A7: Spese fisse | B7: Spesa fissa | C7: =SUMIFS(C$14:C$73,$B$14:$B$73,"Spesa fissa") | D7: =SUMIFS(D$14:D$73,$B$14:$B$73,"Spesa fissa") | E7: =SUMIFS(E$14:E$73,$B$14:$B$73,"Spesa fissa") | F7: =SUMIFS(F$14:F$73,$B$14:$B$73,"Spesa fissa") | G7: =SUMIFS(G$14:G$73,$B$14:$B$73,"Spesa fissa") | H7: =SUMIFS(H$14:H$73,$B$14:$B$73,"Spesa fissa") | I7: =SUMIFS(I$14:I$73,$B$14:$B$73,"Spesa fissa") | J7: =SUMIFS(J$14:J$73,$B$14:$B$73,"Spesa fissa") | ... P7: =SUMIFS(P$14:P$73,$B$14:$B$73,"Spesa fissa")
A8: Spese variabili | B8: Spesa variabile | C8: =SUMIFS(C$14:C$73,$B$14:$B$73,"Spesa variabile") | D8: =SUMIFS(D$14:D$73,$B$14:$B$73,"Spesa variabile") | E8: =SUMIFS(E$14:E$73,$B$14:$B$73,"Spesa variabile") | F8: =SUMIFS(F$14:F$73,$B$14:$B$73,"Spesa variabile") | G8: =SUMIFS(G$14:G$73,$B$14:$B$73,"Spesa variabile") | H8: =SUMIFS(H$14:H$73,$B$14:$B$73,"Spesa variabile") | I8: =SUMIFS(I$14:I$73,$B$14:$B$73,"Spesa variabile") | J8: =SUMIFS(J$14:J$73,$B$14:$B$73,"Spesa variabile") | ... P8: =SUMIFS(P$14:P$73,$B$14:$B$73,"Spesa variabile")
A9: Totale spese | B9: Spesa totale | C9: =C7+C8 | D9: =D7+D8 | E9: =E7+E8 | F9: =F7+F8 | G9: =G7+G8 | H9: =H7+H8 | I9: =I7+I8 | J9: =J7+J8 | ... P9: =P7+P8
A10: Risparmio e investimenti | B10: Risparmio e investimenti | C10: =SUMIFS(C$14:C$73,$B$14:$B$73,"Risparmio e investimenti") | D10: =SUMIFS(D$14:D$73,$B$14:$B$73,"Risparmio e investimenti") | E10: =SUMIFS(E$14:E$73,$B$14:$B$73,"Risparmio e investimenti") | F10: =SUMIFS(F$14:F$73,$B$14:$B$73,"Risparmio e investimenti") | G10: =SUMIFS(G$14:G$73,$B$14:$B$73,"Risparmio e investimenti") | H10: =SUMIFS(H$14:H$73,$B$14:$B$73,"Risparmio e investimenti") | I10: =SUMIFS(I$14:I$73,$B$14:$B$73,"Risparmio e investimenti") | J10: =SUMIFS(J$14:J$73,$B$14:$B$73,"Risparmio e investimenti") | ... P10: =SUMIFS(P$14:P$73,$B$14:$B$73,"Risparmio e investimenti")
A11: Avanzo (entrate − spese − risparmio) | B11: Risultato | C11: =C6-C9-C10 | D11: =D6-D9-D10 | E11: =E6-E9-E10 | F11: =F6-F9-F10 | G11: =G6-G9-G10 | H11: =H6-H9-H10 | I11: =I6-I9-I10 | J11: =J6-J9-J10 | ... P11: =P6-P9-P10
A12: Saldo di cassa previsto a fine mese | B12: Saldo | D12: =Impostazioni!$C$5+D11 | E12: =D12+E11 | F12: =E12+F11 | G12: =F12+G11 | H12: =G12+H11 | I12: =H12+I11 | J12: =I12+J11 | K12: =J12+K11 | L12: =K12+L11 | ... O12: =N12+O11 | P12: =O12
A13: Dettaglio per categoria
A14: =IF(Categorie!$A6="","",Categorie!$A6) | B14: =IF(A14="","",Categorie!$B6&"") | C14: 1850 | D14: =$C14 | E14: =$C14 | F14: =$C14 | G14: =$C14 | H14: =$C14 | I14: =$C14 | J14: =$C14 | K14: =$C14 | ... O14: =$C14 | P14: =SUM(D14:O14)
A15: =IF(Categorie!$A7="","",Categorie!$A7) | B15: =IF(A15="","",Categorie!$B7&"") | C15: 1480 | D15: =$C15 | E15: =$C15 | F15: =$C15 | G15: =$C15 | H15: =$C15 | I15: =$C15 | J15: =$C15 | K15: =$C15 | ... O15: =$C15 | P15: =SUM(D15:O15)
A16: =IF(Categorie!$A8="","",Categorie!$A8) | B16: =IF(A16="","",Categorie!$B8&"") | D16: =$C16 | E16: =$C16 | F16: =$C16 | G16: =$C16 | H16: =$C16 | I16: =$C16 | J16: =$C16 | K16: =$C16 | ... N16: =$C16 | O16: 3200 | P16: =SUM(D16:O16)
A17: =IF(Categorie!$A9="","",Categorie!$A9) | B17: =IF(A17="","",Categorie!$B9&"") | C17: 145 | D17: =$C17 | E17: =$C17 | F17: =$C17 | G17: =$C17 | H17: =$C17 | I17: =$C17 | J17: =$C17 | K17: =$C17 | ... O17: =$C17 | P17: =SUM(D17:O17)
A18: =IF(Categorie!$A10="","",Categorie!$A10) | B18: =IF(A18="","",Categorie!$B10&"") | D18: =$C18 | E18: =$C18 | F18: =$C18 | G18: =$C18 | H18: =$C18 | I18: =$C18 | J18: =$C18 | K18: =$C18 | ... O18: =$C18 | P18: =SUM(D18:O18)
A19: =IF(Categorie!$A11="","",Categorie!$A11) | B19: =IF(A19="","",Categorie!$B11&"") | D19: =$C19 | E19: =$C19 | F19: =$C19 | G19: =$C19 | H19: =$C19 | I19: =$C19 | J19: 350 | K19: =$C19 | L19: =$C19 | M19: =$C19 | N19: =$C19 | O19: =$C19 | P19: =SUM(D19:O19)
A20: =IF(Categorie!$A12="","",Categorie!$A12) | B20: =IF(A20="","",Categorie!$B12&"") | C20: 680 | D20: =$C20 | E20: =$C20 | F20: =$C20 | G20: =$C20 | H20: =$C20 | I20: =$C20 | J20: =$C20 | K20: =$C20 | ... O20: =$C20 | P20: =SUM(D20:O20)
A21: =IF(Categorie!$A13="","",Categorie!$A13) | B21: =IF(A21="","",Categorie!$B13&"") | D21: 270 | E21: =$C21 | F21: =$C21 | G21: 270 | H21: =$C21 | I21: =$C21 | J21: 270 | K21: =$C21 | L21: =$C21 | M21: 270 | N21: =$C21 | O21: =$C21 | P21: =SUM(D21:O21)
A22: =IF(Categorie!$A14="","",Categorie!$A14) | B22: =IF(A22="","",Categorie!$B14&"") | C22: 75 | D22: =$C22 | E22: =$C22 | F22: =$C22 | G22: =$C22 | H22: =$C22 | I22: =$C22 | J22: =$C22 | K22: =$C22 | ... O22: =$C22 | P22: =SUM(D22:O22)
A23: =IF(Categorie!$A15="","",Categorie!$A15) | B23: =IF(A23="","",Categorie!$B15&"") | D23: 160 | E23: 150 | F23: 120 | G23: 80 | H23: 45 | I23: 30 | J23: 25 | K23: 25 | L23: 30 | M23: 60 | N23: 110 | O23: 160 | P23: =SUM(D23:O23)
A24: =IF(Categorie!$A16="","",Categorie!$A16) | B24: =IF(A24="","",Categorie!$B16&"") | D24: =$C24 | E24: 95 | F24: =$C24 | G24: =$C24 | H24: 95 | I24: =$C24 | J24: =$C24 | K24: 95 | L24: =$C24 | M24: =$C24 | N24: 95 | O24: =$C24 | P24: =SUM(D24:O24)
A25: =IF(Categorie!$A17="","",Categorie!$A17) | B25: =IF(A25="","",Categorie!$B17&"") | D25: =$C25 | E25: =$C25 | F25: =$C25 | G25: 110 | H25: =$C25 | I25: =$C25 | J25: 110 | K25: =$C25 | L25: =$C25 | M25: =$C25 | N25: 110 | O25: =$C25 | P25: =SUM(D25:O25)
A26: =IF(Categorie!$A18="","",Categorie!$A18) | B26: =IF(A26="","",Categorie!$B18&"") | C26: 46 | D26: =$C26 | E26: =$C26 | F26: =$C26 | G26: =$C26 | H26: =$C26 | I26: =$C26 | J26: =$C26 | K26: =$C26 | ... O26: =$C26 | P26: =SUM(D26:O26)
A27: =IF(Categorie!$A19="","",Categorie!$A19) | B27: =IF(A27="","",Categorie!$B19&"") | D27: =$C27 | E27: =$C27 | F27: 480 | G27: =$C27 | H27: =$C27 | I27: 170 | J27: =$C27 | K27: =$C27 | L27: =$C27 | M27: =$C27 | N27: =$C27 | O27: =$C27 | P27: =SUM(D27:O27)
A28: =IF(Categorie!$A20="","",Categorie!$A20) | B28: =IF(A28="","",Categorie!$B20&"") | D28: =$C28 | E28: =$C28 | F28: =$C28 | G28: 235 | H28: =$C28 | I28: =$C28 | J28: =$C28 | K28: =$C28 | L28: =$C28 | M28: =$C28 | N28: =$C28 | O28: =$C28 | P28: =SUM(D28:O28)
A29: =IF(Categorie!$A21="","",Categorie!$A21) | B29: =IF(A29="","",Categorie!$B21&"") | C29: 25 | D29: =$C29 | E29: =$C29 | F29: =$C29 | G29: =$C29 | H29: =$C29 | I29: =$C29 | J29: =$C29 | K29: =$C29 | L29: 315 | M29: =$C29 | N29: =$C29 | O29: =$C29 | P29: =SUM(D29:O29)
A30: =IF(Categorie!$A22="","",Categorie!$A22) | B30: =IF(A30="","",Categorie!$B22&"") | C30: 310 | D30: =$C30 | E30: =$C30 | F30: =$C30 | G30: =$C30 | H30: =$C30 | I30: =$C30 | J30: =$C30 | K30: =$C30 | ... O30: =$C30 | P30: =SUM(D30:O30)
A31: =IF(Categorie!$A23="","",Categorie!$A23) | B31: =IF(A31="","",Categorie!$B23&"") | C31: 520 | D31: =$C31 | E31: =$C31 | F31: =$C31 | G31: =$C31 | H31: =$C31 | I31: =$C31 | J31: =$C31 | K31: =$C31 | ... N31: =$C31 | O31: 620 | P31: =SUM(D31:O31)
A32: =IF(Categorie!$A24="","",Categorie!$A24) | B32: =IF(A32="","",Categorie!$B24&"") | C32: 170 | D32: =$C32 | E32: =$C32 | F32: =$C32 | G32: =$C32 | H32: =$C32 | I32: =$C32 | J32: =$C32 | K32: 220 | L32: =$C32 | M32: =$C32 | N32: =$C32 | O32: =$C32 | P32: =SUM(D32:O32)
A33: =IF(Categorie!$A25="","",Categorie!$A25) | B33: =IF(A33="","",Categorie!$B25&"") | C33: 35 | D33: =$C33 | E33: =$C33 | F33: =$C33 | G33: =$C33 | H33: =$C33 | I33: =$C33 | J33: =$C33 | K33: =$C33 | ... O33: =$C33 | P33: =SUM(D33:O33)
A34: =IF(Categorie!$A26="","",Categorie!$A26) | B34: =IF(A34="","",Categorie!$B26&"") | C34: 50 | D34: =$C34 | E34: =$C34 | F34: =$C34 | G34: =$C34 | H34: =$C34 | I34: =$C34 | J34: =$C34 | K34: =$C34 | ... O34: =$C34 | P34: =SUM(D34:O34)
A35: =IF(Categorie!$A27="","",Categorie!$A27) | B35: =IF(A35="","",Categorie!$B27&"") | C35: 80 | D35: =$C35 | E35: =$C35 | F35: =$C35 | G35: =$C35 | H35: =$C35 | I35: =$C35 | J35: 320 | K35: 0 | L35: 420 | M35: =$C35 | N35: =$C35 | O35: =$C35 | P35: =SUM(D35:O35)
A36: =IF(Categorie!$A28="","",Categorie!$A28) | B36: =IF(A36="","",Categorie!$B28&"") | C36: 30 | D36: =$C36 | E36: =$C36 | F36: =$C36 | G36: =$C36 | H36: =$C36 | I36: =$C36 | J36: =$C36 | K36: =$C36 | ... O36: =$C36 | P36: =SUM(D36:O36)
A37: =IF(Categorie!$A29="","",Categorie!$A29) | B37: =IF(A37="","",Categorie!$B29&"") | C37: 60 | D37: =$C37 | E37: =$C37 | F37: =$C37 | G37: =$C37 | H37: =$C37 | I37: =$C37 | J37: =$C37 | K37: =$C37 | ... O37: =$C37 | P37: =SUM(D37:O37)
A38: =IF(Categorie!$A30="","",Categorie!$A30) | B38: =IF(A38="","",Categorie!$B30&"") | C38: 150 | D38: =$C38 | E38: =$C38 | F38: =$C38 | G38: =$C38 | H38: =$C38 | I38: =$C38 | J38: =$C38 | K38: =$C38 | ... N38: =$C38 | O38: 220 | P38: =SUM(D38:O38)
A39: =IF(Categorie!$A31="","",Categorie!$A31) | B39: =IF(A39="","",Categorie!$B31&"") | C39: 30 | D39: =$C39 | E39: =$C39 | F39: =$C39 | G39: =$C39 | H39: =$C39 | I39: =$C39 | J39: =$C39 | K39: =$C39 | ... N39: =$C39 | O39: 300 | P39: =SUM(D39:O39)
A40: =IF(Categorie!$A32="","",Categorie!$A32) | B40: =IF(A40="","",Categorie!$B32&"") | D40: =$C40 | E40: =$C40 | F40: =$C40 | G40: 300 | H40: =$C40 | I40: =$C40 | J40: 400 | K40: 1100 | L40: =$C40 | M40: =$C40 | N40: =$C40 | O40: =$C40 | P40: =SUM(D40:O40)
...

Sheet Mensile
A1: Mensile: consuntivo e differenze dal budget
A2: Somme dei movimenti per categoria e mese. Differenza = consuntivo − budget: verde se va bene, rosso se va male.
A3: ="Mese di riferimento: "&Impostazioni!$C$13&" (si cambia in Impostazioni)"
C4: 1 | D4: 2 | E4: 3 | F4: 4 | G4: 5 | H4: 6 | I4: 7 | J4: 8 | K4: 9 | L4: 10 | M4: 11 | N4: 12
A5: Voce | B5: Tipo | C5: Gen | D5: Feb | E5: Mar | F5: Apr | G5: Mag | H5: Giu | I5: Lug | J5: Ago | K5: Set | L5: Ott | M5: Nov | N5: Dic | O5: Totale anno | P5: Budget anno | Q5: Differenza anno | R5: % del budget | T5: ="Budget "&LOWER(Impostazioni!$C$13) | U5: ="Consuntivo "&LOWER(Impostazioni!$C$13) | V5: ="Differenza "&LOWER(Impostazioni!$C$13) | W5: Budget da inizio anno | X5: Consuntivo da inizio anno | Y5: Differenza da inizio anno | Z5: Ordine (tecnico)
A6: Entrate | B6: Entrata | C6: =SUMIFS(C$14:C$73,$B$14:$B$73,"Entrata") | D6: =SUMIFS(D$14:D$73,$B$14:$B$73,"Entrata") | E6: =SUMIFS(E$14:E$73,$B$14:$B$73,"Entrata") | F6: =SUMIFS(F$14:F$73,$B$14:$B$73,"Entrata") | G6: =SUMIFS(G$14:G$73,$B$14:$B$73,"Entrata") | H6: =SUMIFS(H$14:H$73,$B$14:$B$73,"Entrata") | I6: =SUMIFS(I$14:I$73,$B$14:$B$73,"Entrata") | J6: =SUMIFS(J$14:J$73,$B$14:$B$73,"Entrata") | ... P6: =SUMIFS(P$14:P$73,$B$14:$B$73,"Entrata") | Q6: =O6-P6 | R6: =IF(P6=0,"",O6/P6) | T6: =SUMIFS(T$14:T$73,$B$14:$B$73,"Entrata") | U6: =SUMIFS(U$14:U$73,$B$14:$B$73,"Entrata") | V6: =U6-T6 | W6: =SUMIFS(W$14:W$73,$B$14:$B$73,"Entrata") | X6: =SUMIFS(X$14:X$73,$B$14:$B$73,"Entrata") | Y6: =X6-W6
A7: Spese fisse | B7: Spesa fissa | C7: =SUMIFS(C$14:C$73,$B$14:$B$73,"Spesa fissa") | D7: =SUMIFS(D$14:D$73,$B$14:$B$73,"Spesa fissa") | E7: =SUMIFS(E$14:E$73,$B$14:$B$73,"Spesa fissa") | F7: =SUMIFS(F$14:F$73,$B$14:$B$73,"Spesa fissa") | G7: =SUMIFS(G$14:G$73,$B$14:$B$73,"Spesa fissa") | H7: =SUMIFS(H$14:H$73,$B$14:$B$73,"Spesa fissa") | I7: =SUMIFS(I$14:I$73,$B$14:$B$73,"Spesa fissa") | J7: =SUMIFS(J$14:J$73,$B$14:$B$73,"Spesa fissa") | ... P7: =SUMIFS(P$14:P$73,$B$14:$B$73,"Spesa fissa") | Q7: =O7-P7 | R7: =IF(P7=0,"",O7/P7) | T7: =SUMIFS(T$14:T$73,$B$14:$B$73,"Spesa fissa") | U7: =SUMIFS(U$14:U$73,$B$14:$B$73,"Spesa fissa") | V7: =U7-T7 | W7: =SUMIFS(W$14:W$73,$B$14:$B$73,"Spesa fissa") | X7: =SUMIFS(X$14:X$73,$B$14:$B$73,"Spesa fissa") | Y7: =X7-W7
A8: Spese variabili | B8: Spesa variabile | C8: =SUMIFS(C$14:C$73,$B$14:$B$73,"Spesa variabile") | D8: =SUMIFS(D$14:D$73,$B$14:$B$73,"Spesa variabile") | E8: =SUMIFS(E$14:E$73,$B$14:$B$73,"Spesa variabile") | F8: =SUMIFS(F$14:F$73,$B$14:$B$73,"Spesa variabile") | G8: =SUMIFS(G$14:G$73,$B$14:$B$73,"Spesa variabile") | H8: =SUMIFS(H$14:H$73,$B$14:$B$73,"Spesa variabile") | I8: =SUMIFS(I$14:I$73,$B$14:$B$73,"Spesa variabile") | J8: =SUMIFS(J$14:J$73,$B$14:$B$73,"Spesa variabile") | ... P8: =SUMIFS(P$14:P$73,$B$14:$B$73,"Spesa variabile") | Q8: =O8-P8 | R8: =IF(P8=0,"",O8/P8) | T8: =SUMIFS(T$14:T$73,$B$14:$B$73,"Spesa variabile") | U8: =SUMIFS(U$14:U$73,$B$14:$B$73,"Spesa variabile") | V8: =U8-T8 | W8: =SUMIFS(W$14:W$73,$B$14:$B$73,"Spesa variabile") | X8: =SUMIFS(X$14:X$73,$B$14:$B$73,"Spesa variabile") | Y8: =X8-W8
A9: Totale spese | B9: Spesa totale | C9: =C7+C8 | D9: =D7+D8 | E9: =E7+E8 | F9: =F7+F8 | G9: =G7+G8 | H9: =H7+H8 | I9: =I7+I8 | J9: =J7+J8 | ... P9: =P7+P8 | Q9: =O9-P9 | R9: =IF(P9=0,"",O9/P9) | T9: =T7+T8 | U9: =U7+U8 | V9: =U9-T9 | W9: =W7+W8 | X9: =X7+X8 | Y9: =X9-W9
A10: Risparmio e investimenti | B10: Risparmio e investimenti | C10: =SUMIFS(C$14:C$73,$B$14:$B$73,"Risparmio e investimenti") | D10: =SUMIFS(D$14:D$73,$B$14:$B$73,"Risparmio e investimenti") | E10: =SUMIFS(E$14:E$73,$B$14:$B$73,"Risparmio e investimenti") | F10: =SUMIFS(F$14:F$73,$B$14:$B$73,"Risparmio e investimenti") | G10: =SUMIFS(G$14:G$73,$B$14:$B$73,"Risparmio e investimenti") | H10: =SUMIFS(H$14:H$73,$B$14:$B$73,"Risparmio e investimenti") | I10: =SUMIFS(I$14:I$73,$B$14:$B$73,"Risparmio e investimenti") | J10: =SUMIFS(J$14:J$73,$B$14:$B$73,"Risparmio e investimenti") | ... P10: =SUMIFS(P$14:P$73,$B$14:$B$73,"Risparmio e investimenti") | Q10: =O10-P10 | R10: =IF(P10=0,"",O10/P10) | T10: =SUMIFS(T$14:T$73,$B$14:$B$73,"Risparmio e investimenti") | U10: =SUMIFS(U$14:U$73,$B$14:$B$73,"Risparmio e investimenti") | V10: =U10-T10 | W10: =SUMIFS(W$14:W$73,$B$14:$B$73,"Risparmio e investimenti") | X10: =SUMIFS(X$14:X$73,$B$14:$B$73,"Risparmio e investimenti") | Y10: =X10-W10
A11: Avanzo (entrate − spese − risparmio) | B11: Risultato | C11: =C6-C9-C10 | D11: =D6-D9-D10 | E11: =E6-E9-E10 | F11: =F6-F9-F10 | G11: =G6-G9-G10 | H11: =H6-H9-H10 | I11: =I6-I9-I10 | J11: =J6-J9-J10 | ... P11: =P6-P9-P10 | Q11: =O11-P11 | R11: =IF(P11=0,"",O11/P11) | T11: =T6-T9-T10 | U11: =U6-U9-U10 | V11: =U11-T11 | W11: =W6-W9-W10 | X11: =X6-X9-X10 | Y11: =X11-W11
A12: Saldo di cassa a fine mese | B12: Saldo | C12: =Impostazioni!$C$5+C11 | D12: =C12+D11 | E12: =D12+E11 | F12: =E12+F11 | G12: =F12+G11 | H12: =G12+H11 | I12: =H12+I11 | J12: =I12+J11 | K12: =J12+K11 | ... N12: =M12+N11 | O12: =N12 | P12: =Budget!P12 | Q12: =O12-P12 | T12: =INDEX(Budget!$D$12:$O$12,Impostazioni!$C$12) | U12: =INDEX($C$12:$N$12,Impostazioni!$C$12) | V12: =U12-T12
A13: Dettaglio per categoria | T13: ="Mese di riferimento: "&LOWER(Impostazioni!$C$13) | W13: Da gennaio al mese di riferimento
A14: =IF(Categorie!$A6="","",Categorie!$A6) | B14: =IF(A14="","",Categorie!$B6&"") | C14: =IF($A14="",0,SUMIFS(Movimenti!$D$6:$D$2005,Movimenti!$C$6:$C$2005,$A14,Movimenti!$A$6:$A$2005,">="&DATE(Impostazioni!$C$4,C$4,1),Movimenti!$A$6:$A$2005,"<"&DATE(Impostazioni!$C$4,C$4+1,1))) | D14: =IF($A14="",0,SUMIFS(Movimenti!$D$6:$D$2005,Movimenti!$C$6:$C$2005,$A14,Movimenti!$A$6:$A$2005,">="&DATE(Impostazioni!$C$4,D$4,1),Movimenti!$A$6:$A$2005,"<"&DATE(Impostazioni!$C$4,D$4+1,1))) | E14: =IF($A14="",0,SUMIFS(Movimenti!$D$6:$D$2005,Movimenti!$C$6:$C$2005,$A14,Movimenti!$A$6:$A$2005,">="&DATE(Impostazioni!$C$4,E$4,1),Movimenti!$A$6:$A$2005,"<"&DATE(Impostazioni!$C$4,E$4+1,1))) | F14: =IF($A14="",0,SUMIFS(Movimenti!$D$6:$D$2005,Movimenti!$C$6:$C$2005,$A14,Movimenti!$A$6:$A$2005,">="&DATE(Impostazioni!$C$4,F$4,1),Movimenti!$A$6:$A$2005,"<"&DATE(Impostazioni!$C$4,F$4+1,1))) | G14: =IF($A14="",0,SUMIFS(Movimenti!$D$6:$D$2005,Movimenti!$C$6:$C$2005,$A14,Movimenti!$A$6:$A$2005,">="&DATE(Impostazioni!$C$4,G$4,1),Movimenti!$A$6:$A$2005,"<"&DATE(Impostazioni!$C$4,G$4+1,1))) | H14: =IF($A14="",0,SUMIFS(Movimenti!$D$6:$D$2005,Movimenti!$C$6:$C$2005,$A14,Movimenti!$A$6:$A$2005,">="&DATE(Impostazioni!$C$4,H$4,1),Movimenti!$A$6:$A$2005,"<"&DATE(Impostazioni!$C$4,H$4+1,1))) | I14: =IF($A14="",0,SUMIFS(Movimenti!$D$6:$D$2005,Movimenti!$C$6:$C$2005,$A14,Movimenti!$A$6:$A$2005,">="&DATE(Impostazioni!$C$4,I$4,1),Movimenti!$A$6:$A$2005,"<"&DATE(Impostazioni!$C$4,I$4+1,1))) | J14: =IF($A14="",0,SUMIFS(Movimenti!$D$6:$D$2005,Movimenti!$C$6:$C$2005,$A14,Movimenti!$A$6:$A$2005,">="&DATE(Impostazioni!$C$4,J$4,1),Movimenti!$A$6:$A$2005,"<"&DATE(Impostazioni!$C$4,J$4+1,1))) | ... N14: =IF($A14="",0,SUMIFS(Movimenti!$D$6:$D$2005,Movimenti!$C$6:$C$2005,$A14,Movimenti!$A$6:$A$2005,">="&DATE(Impostazioni!$C$4,N$4,1),Movimenti!$A$6:$A$2005,"<"&DATE(Impostazioni!$C$4,N$4+1,1))) | O14: =SUM(C14:N14) | P14: =Budget!P14 | Q14: =O14-P14 | R14: =IF(P14=0,"",O14/P14) | T14: =INDEX(Budget!$D14:$O14,Impostazioni!$C$12) | U14: =INDEX($C14:$N14,Impostazioni!$C$12) | V14: =U14-T14 | W14: =SUMIFS(Budget!$D14:$O14,Budget!$D$4:$O$4,"<="&Impostazioni!$C$12) | X14: =SUMIFS($C14:$N14,$C$4:$N$4,"<="&Impostazioni!$C$12) | Y14: =X14-W14 | Z14: =IF(AND(O14>0,LEFT(B14,5)="Spesa"),O14-ROW()/10000000,0)
A15: =IF(Categorie!$A7="","",Categorie!$A7) | B15: =IF(A15="","",Categorie!$B7&"") | C15: =IF($A15="",0,SUMIFS(Movimenti!$D$6:$D$2005,Movimenti!$C$6:$C$2005,$A15,Movimenti!$A$6:$A$2005,">="&DATE(Impostazioni!$C$4,C$4,1),Movimenti!$A$6:$A$2005,"<"&DATE(Impostazioni!$C$4,C$4+1,1))) | D15: =IF($A15="",0,SUMIFS(Movimenti!$D$6:$D$2005,Movimenti!$C$6:$C$2005,$A15,Movimenti!$A$6:$A$2005,">="&DATE(Impostazioni!$C$4,D$4,1),Movimenti!$A$6:$A$2005,"<"&DATE(Impostazioni!$C$4,D$4+1,1))) | E15: =IF($A15="",0,SUMIFS(Movimenti!$D$6:$D$2005,Movimenti!$C$6:$C$2005,$A15,Movimenti!$A$6:$A$2005,">="&DATE(Impostazioni!$C$4,E$4,1),Movimenti!$A$6:$A$2005,"<"&DATE(Impostazioni!$C$4,E$4+1,1))) | F15: =IF($A15="",0,SUMIFS(Movimenti!$D$6:$D$2005,Movimenti!$C$6:$C$2005,$A15,Movimenti!$A$6:$A$2005,">="&DATE(Impostazioni!$C$4,F$4,1),Movimenti!$A$6:$A$2005,"<"&DATE(Impostazioni!$C$4,F$4+1,1))) | G15: =IF($A15="",0,SUMIFS(Movimenti!$D$6:$D$2005,Movimenti!$C$6:$C$2005,$A15,Movimenti!$A$6:$A$2005,">="&DATE(Impostazioni!$C$4,G$4,1),Movimenti!$A$6:$A$2005,"<"&DATE(Impostazioni!$C$4,G$4+1,1))) | H15: =IF($A15="",0,SUMIFS(Movimenti!$D$6:$D$2005,Movimenti!$C$6:$C$2005,$A15,Movimenti!$A$6:$A$2005,">="&DATE(Impostazioni!$C$4,H$4,1),Movimenti!$A$6:$A$2005,"<"&DATE(Impostazioni!$C$4,H$4+1,1))) | I15: =IF($A15="",0,SUMIFS(Movimenti!$D$6:$D$2005,Movimenti!$C$6:$C$2005,$A15,Movimenti!$A$6:$A$2005,">="&DATE(Impostazioni!$C$4,I$4,1),Movimenti!$A$6:$A$2005,"<"&DATE(Impostazioni!$C$4,I$4+1,1))) | J15: =IF($A15="",0,SUMIFS(Movimenti!$D$6:$D$2005,Movimenti!$C$6:$C$2005,$A15,Movimenti!$A$6:$A$2005,">="&DATE(Impostazioni!$C$4,J$4,1),Movimenti!$A$6:$A$2005,"<"&DATE(Impostazioni!$C$4,J$4+1,1))) | ... N15: =IF($A15="",0,SUMIFS(Movimenti!$D$6:$D$2005,Movimenti!$C$6:$C$2005,$A15,Movimenti!$A$6:$A$2005,">="&DATE(Impostazioni!$C$4,N$4,1),Movimenti!$A$6:$A$2005,"<"&DATE(Impostazioni!$C$4,N$4+1,1))) | O15: =SUM(C15:N15) | P15: =Budget!P15 | Q15: =O15-P15 | R15: =IF(P15=0,"",O15/P15) | T15: =INDEX(Budget!$D15:$O15,Impostazioni!$C$12) | U15: =INDEX($C15:$N15,Impostazioni!$C$12) | V15: =U15-T15 | W15: =SUMIFS(Budget!$D15:$O15,Budget!$D$4:$O$4,"<="&Impostazioni!$C$12) | X15: =SUMIFS($C15:$N15,$C$4:$N$4,"<="&Impostazioni!$C$12) | Y15: =X15-W15 | Z15: =IF(AND(O15>0,LEFT(B15,5)="Spesa"),O15-ROW()/10000000,0)
