Workbook

Sheet Istruzioni
B1: Gestionale Partita IVA forfettaria 2026
B2: NettoChiaro · parametri aggiornati al 06/10/2026 · Excel, Google Sheets e LibreOffice
B4: Come si usa
B5: 1. Impostazioni | C5: Scegli attività (coefficiente), previdenza e aliquota dell'imposta.
B6: 2. Fatture | C6: Registra ogni fattura: numero, date, cliente, compenso. Rivalsa e bollo si calcolano da soli. Rivalsa INPS 4%: scegli Sì solo se la applichi (vuoto = No). Bollo al cliente: vuoto = Sì, scegli No se il bollo resta a tuo carico. Quando il cliente paga, scrivi la data di incasso.
B7: 3. Spese | C7: Facoltativo: registra i costi dell'attività per vedere il netto vero.
B8: 4. Dashboard | C8: Incassato, imposta, contributi, netto e avanzamento verso le soglie, con i grafici.
B9: 5. Riepilogo mensile | C9: Mese per mese: incassato, quota da accantonare, netto e percentuale delle soglie.
B10: 6. Scadenze | C10: Date degli F24 dell'anno con gli importi che il file può stimare. Segna "Fatto" quando paghi.
B12: Legenda dei colori
B13: Giallo | C13: Celle da compilare (le uniche modificabili).
B14: Verde chiaro | C14: Risultati principali e valori calcolati da Impostazioni.
B15: Verde scuro | C15: Intestazioni e totali.
B16: Bianco | C16: Formule ed etichette: non modificarle.
B18: Principio di cassa
B19: Contano gli incassi | C19: Nel forfettario ricavi, tasse e soglie si calcolano su quello che incassi nell'anno, non su quello che fatturi. Una fattura di dicembre pagata a gennaio conta nell'anno nuovo. Il file usa sempre la data di incasso.
B20: Ricavo che conta | C20: Compenso + rivalsa INPS + bollo addebitato al cliente (puoi escludere il bollo in Impostazioni).
B22: Come calcola
B23: Reddito | C23: Incassato × coefficiente di redditività del tuo gruppo ATECO.
B24: Gestione Separata | C24: 26,07% del reddito (24% se sei pensionato o iscritto ad altra previdenza), fino al massimale di 122.295 €.
B25: Artigiani e commercianti | C25: Contributi fissi sul minimale, dovuti anche con reddito più basso, più l'aliquota sul reddito oltre il minimale (un punto in più oltre la soglia). La riduzione del 35% non tocca la quota maternità.
B26: Imposta sostitutiva | C26: (Reddito − contributi) × 15% o 5%. Stima "a regime": si deducono i contributi calcolati sull'anno. In realtà si deducono quelli versati nell'anno: se li conosci, inseriscili in Impostazioni.
B27: Bollo e rivalsa | C27: Bollo di 2,00 € sulle fatture oltre 77,47 €. Rivalsa 4% solo per la Gestione Separata, se scegli Sì.
B28: Da accantonare | C28: Ogni mese il file stima quanto mettere da parte di quello che hai incassato. Somma dei 12 mesi = tasse e contributi dell'anno.
B30: Soglie
B31: 85.000 € | C31: Oltre 85.000 € di ricavi resti forfettario quest'anno, ma dal prossimo passi al regime ordinario.
B32: 100.000 € | C32: Oltre 100.000 € esci dal forfettario già nell'anno: l'IVA si applica dall'operazione che fa superare la soglia e il reddito dell'intero anno si tassa con IRPEF e costi reali. La Dashboard mostra un avviso e i calcoli diventano solo indicativi.
B34: Avvertenze
B35: È una stima | C35: Il file aiuta a pianificare: non sostituisce il commercialista né la dichiarazione dei redditi. Controlla sempre gli importi prima di pagare.
B36: Cosa non gestisce | C36: Minimi e contributo integrativo delle casse professionali, altre riduzioni INPS (es. pensionati oltre 65 anni), IVA, crediti d'imposta, redditi diversi dal forfettario.
B37: Fatture pagate a rate | C37: Registra ogni pagamento su una riga con la sua data di incasso. Sulle righe dei pagamenti successivi al primo lascia vuota la data di emissione e scegli "No" in "Bollo al cliente": così il bollo e la fattura si contano una volta sola.
B38: Requisiti | C38: Il file non verifica i requisiti per entrare o restare nel regime (es. redditi da lavoro dipendente, partecipazioni).
B40: Uso pratico
B41: Protezione | C41: I fogli sono protetti senza password, per non cancellare le formule per sbaglio. Per sbloccarli: Excel, Revisione > Rimuovi protezione foglio; LibreOffice, Strumenti > Proteggi foglio.
B42: Excel | C42: Excel apre i file scaricati da internet in "Visualizzazione protetta", dove i calcoli non si aggiornano e le celle possono sembrare vuote: fai clic su "Abilita modifica".
B43: Google Sheets | C43: Carica il file su Google Drive e aprilo con Fogli Google (File > Salva come Fogli Google).
B44: Date e importi | C44: Scrivi le date come gg/mm/aaaa (es. 15/03/2026) e gli importi come numeri, senza testo. Se incolli dati da un altro file, il riquadro Controlli della Dashboard segnala le celle da correggere.
B45: Righe | C45: 300 righe di fatture e 200 di spese. Per l'anno nuovo usa una copia vuota del file.
B46: Aggiornamento | C46: Tutti i valori fiscali sono nel foglio Parametri 2026, con la fonte. Ogni anno esce la versione aggiornata.
B48: Progettato da NettoChiaro con l'aiuto di strumenti di intelligenza artificiale; formule verificate con test. nettochiaro.com

Sheet Impostazioni
A1: Impostazioni
A2: Compila le celle gialle. Tutto il resto del file si aggiorna da solo.
A4: Voce | B4: La tua scelta | C4: Spiegazione
A5: Nome o attività (facoltativo) | B5: Laura Conti, grafica freelance | C5: Compare in alto nella Dashboard.
A6: Attività (gruppo di codici ATECO) | B6: Attività professionali, scientifiche, tecniche, sanitarie, istruzione, servizi finanziari e assicurativi | C6: Scegli il gruppo del tuo codice ATECO: determina il coefficiente di redditività. Elenco completo nel foglio Parametri 2026.
A7: Previdenza | B7: Gestione Separata INPS (professionisti senza cassa) | C7: Gestione Separata se sei un professionista senza cassa. Artigiani o Commercianti se sei iscritto a una di queste gestioni INPS. Cassa professionale: inserisci l'aliquota nella riga sotto.
A8: Aliquota della cassa professionale (solo se hai una cassa) | C8: Aliquota del contributo soggettivo della tua cassa (es. 14,5%). Il foglio non calcola minimi e contributo integrativo della cassa.
A9: Imposta sostitutiva | B9: 15% (aliquota ordinaria) | C9: 5% per i primi 5 anni di una nuova attività, se hai i requisiti di legge. Altrimenti 15%.
A10: Riduzione contributiva del 35% | B10: No | C10: Solo artigiani e commercianti che l'hanno chiesta all'INPS. Non si applica alla quota maternità.
A11: Il bollo addebitato al cliente conta nei ricavi | B11: Sì | C11: Sì (prudente): secondo l'Agenzia delle Entrate (risposta 428/2022) il bollo riaddebitato fa parte del compenso. Dopo il D.Lgs. 192/2024 alcune interpretazioni lo escludono: chiedi al tuo commercialista. Vale per tasse e soglie.
A12: Contributi previdenziali versati nel 2026 (facoltativo) | C12: Lascia vuoto per la stima "a regime" (si deducono i contributi calcolati sull'anno). Se li conosci, inserisci i contributi che versi davvero nel 2026 (saldo 2025, acconti 2026, rate fisse pagate nel 2026): l'imposta si calcola su quelli. Primo anno di attività: scrivi 0.
A13: Acconti d'imposta sostitutiva versati per il 2026 (facoltativo) | B13: 3000 | C13: Somma dei due acconti 2026 (luglio e novembre). Serve al foglio Scadenze per stimare il saldo da versare nel 2027.
A15: Valori usati nei calcoli (si aggiornano da soli, non modificarli)
A16: Coefficiente di redditività | B16: =IFERROR(INDEX('Parametri 2026'!$B$46:$B$54,MATCH(Impostazioni!$B$6,'Parametri 2026'!$A$46:$A$54,0)),0) | C16: Dal gruppo di attività scelto.
A17: Codice della previdenza (1-5) | B17: =IFERROR(MATCH(Impostazioni!$B$7,'Parametri 2026'!$A$59:$A$63,0),0) | C17: 1-2 Gestione Separata, 3 Artigiani, 4 Commercianti, 5 Cassa; 0 = non scelta. Elenco in Parametri 2026.
A18: Aliquota dell'imposta sostitutiva | B18: =IF(Impostazioni!$B$9='Parametri 2026'!$A$67,'Parametri 2026'!$B$10,'Parametri 2026'!$B$9)
A19: Aliquota contributiva | B19: =CHOOSE(Impostazioni!$B$17+1,0,'Parametri 2026'!$B$18,'Parametri 2026'!$B$19,'Parametri 2026'!$B$25,'Parametri 2026'!$B$33,N(Impostazioni!$B$8)) | C19: Per artigiani e commercianti è l'aliquota fino alla soglia.
A20: Riduzione del 35% applicata | B20: =IF(AND(Impostazioni!$B$10="Sì",OR(Impostazioni!$B$17=3,Impostazioni!$B$17=4)),"Sì","No") | C20: Solo artigiani e commercianti.
A21: Quota dei contributi dovuta dopo la riduzione | B21: =IF(Impostazioni!$B$20="Sì",1-'Parametri 2026'!$B$38,1)
A22: Minimale di reddito (artigiani e commercianti) | B22: =IF(Impostazioni!$B$17=4,'Parametri 2026'!$B$30,'Parametri 2026'!$B$22)
A23: Contributo fisso annuo pieno | B23: =IF(Impostazioni!$B$17=3,'Parametri 2026'!$B$23,IF(Impostazioni!$B$17=4,'Parametri 2026'!$B$31,0))
A24: Quota maternità (non ridotta) | B24: =IF(Impostazioni!$B$17=3,'Parametri 2026'!$B$24,IF(Impostazioni!$B$17=4,'Parametri 2026'!$B$32,0))
A25: Contributi fissi annui dovuti | B25: =(Impostazioni!$B$23-Impostazioni!$B$24)*Impostazioni!$B$21+Impostazioni!$B$24 | C25: (fisso − maternità) × quota dovuta + maternità.
A26: Soglia per l'aliquota aggiuntiva | B26: =IF(Impostazioni!$B$17=4,'Parametri 2026'!$B$34,'Parametri 2026'!$B$26)
A27: Aliquota oltre la soglia | B27: =IF(Impostazioni!$B$17=4,'Parametri 2026'!$B$35,'Parametri 2026'!$B$27)
A28: Massimale di reddito | B28: =IF(Impostazioni!$B$17<=2,'Parametri 2026'!$B$20,IF(Impostazioni!$B$17=4,'Parametri 2026'!$B$36,'Parametri 2026'!$B$28)) | C28: Le casse professionali non hanno massimale qui.
A29: Bollo addebitato incluso nei ricavi | B29: =IF(Impostazioni!$B$11="No","No","Sì") | C29: Vuoto vale Sì.

Sheet Parametri 2026
A1: Parametri 2026
A2: Valori usati dalle formule, con la fonte. Aggiornati al 06/10/2026. Ogni anno basta aggiornare questa tabella (vedi Istruzioni).
A4: Parametro | B4: Valore | C4: Fonte
A5: Regime forfettario
A6: Anno di riferimento | B6: 2026 | C6: Anno a cui si riferiscono i valori e gli incassi
A7: Soglia di ricavi per restare nel regime l'anno dopo | B7: 85000 | C7: L. 190/2014, art. 1 c. 54
A8: Soglia di uscita immediata (già nell'anno) | B8: 100000 | C8: L. 190/2014, art. 1 c. 71; circolare Agenzia delle Entrate 32/E/2023
A9: Imposta sostitutiva ordinaria | B9: 0.15 | C9: L. 190/2014, art. 1 c. 64
A10: Imposta sostitutiva per le nuove attività (primi 5 anni) | B10: 0.05 | C10: L. 190/2014, art. 1 c. 65 (con i requisiti di legge)
A11: Limite di reddito da lavoro dipendente o pensione (solo informativo) | B11: 35000 | C11: L. 190/2014, art. 1 c. 57 lett. d-ter; 35.000 € per il 2026 (L. 199/2025, art. 1 c. 27). Il foglio non lo usa nei calcoli.
A12: Imposta di bollo e rivalsa
A13: Imposta di bollo su fatture senza IVA | B13: 2 | C13: DPR 642/1972, Tariffa parte I, art. 13
A14: Il bollo è dovuto se l'importo della fattura supera | B14: 77.47 | C14: DPR 642/1972, Tariffa parte I, art. 13 e note
A15: Bollo fatture elettroniche: si può rinviare al trimestre dopo fino a | B15: 5000 | C15: DM 17/06/2014, art. 6 c. 2 (soglia di 5.000 € dal 2023, DL 73/2022)
A16: Rivalsa INPS facoltativa in fattura (solo Gestione Separata) | B16: 0.04 | C16: L. 662/1996, art. 1 c. 212
A17: INPS Gestione Separata
A18: Aliquota professionisti senza altra previdenza obbligatoria | B18: 0.2607 | C18: Circolare INPS 8/2026 (25% IVS + 0,72% + 0,35% ISCRO)
A19: Aliquota pensionati o iscritti ad altra previdenza obbligatoria | B19: 0.24 | C19: Circolare INPS 8/2026
A20: Massimale di reddito | B20: 122295 | C20: Circolare INPS 8/2026
A21: INPS Artigiani
A22: Minimale di reddito | B22: 18808 | C22: Circolare INPS 14/2026
A23: Contributo fisso annuo sul minimale (quota maternità compresa) | B23: 4521.36 | C23: Circolare INPS 14/2026
A24: Quota maternità compresa nel contributo fisso (non si riduce) | B24: 7.44 | C24: Circolare INPS 14/2026 (0,62 € al mese)
A25: Aliquota fino alla soglia | B25: 0.24 | C25: Circolare INPS 14/2026
A26: Soglia oltre la quale l'aliquota sale di un punto | B26: 56224 | C26: Circolare INPS 14/2026 (prima fascia di retribuzione pensionabile)
A27: Aliquota oltre la soglia | B27: 0.25 | C27: Circolare INPS 14/2026
A28: Massimale di reddito | B28: 122295 | C28: Circolare INPS 14/2026
A29: INPS Commercianti
A30: Minimale di reddito | B30: 18808 | C30: Circolare INPS 14/2026
A31: Contributo fisso annuo sul minimale (quota maternità compresa) | B31: 4611.64 | C31: Circolare INPS 14/2026
A32: Quota maternità compresa nel contributo fisso (non si riduce) | B32: 7.44 | C32: Circolare INPS 14/2026 (0,62 € al mese)
A33: Aliquota fino alla soglia | B33: 0.2448 | C33: Circolare INPS 14/2026
A34: Soglia oltre la quale l'aliquota sale di un punto | B34: 56224 | C34: Circolare INPS 14/2026 (prima fascia di retribuzione pensionabile)
A35: Aliquota oltre la soglia | B35: 0.2548 | C35: Circolare INPS 14/2026
A36: Massimale di reddito | B36: 122295 | C36: Circolare INPS 14/2026
A37: Riduzione contributiva
A38: Riduzione per forfettari iscritti ad artigiani o commercianti (su domanda) | B38: 0.35 | C38: L. 190/2014, art. 1 c. 77
A39: Acconti dell'imposta sostitutiva (foglio Scadenze)
A40: Ogni rata di acconto (due rate uguali) | B40: 0.5 | C40: DL 124/2019, art. 58
A41: Nessun acconto se l'imposta dell'anno non supera | B41: 51.65 | C41: Istruzioni del modello Redditi PF
...

Sheet Fatture
A1: Fatture
A2: Una riga per fattura. Celle gialle da compilare; quando il cliente paga, scrivi la data di incasso: conta quella (principio di cassa).
L3: Incassato nel 2026 | M3: ='Riepilogo mensile'!$B$17 | N3: =COUNTIF($N$5:$N$304,"Da incassare")&" da incassare"
A4: N. | B4: Data emissione | C4: Data incasso | D4: Cliente | E4: Descrizione | F4: Compenso (€) | G4: Rivalsa INPS 4% | H4: Rivalsa (€) | I4: Imponibile (€) | J4: Bollo (€) | K4: Bollo al cliente | L4: Totale fattura (€) | M4: Ricavo che conta (€) | N4: Stato | O4: Note
A5: 18/2025 | B5: 46006 | C5: 46034 | D5: Agenzia Delta Comunicazione srl | E5: Restyling logo e linee guida | F5: 1800 | G5: Sì | H5: =IF(ISNUMBER(F5),IF(OR(G5="Sì",G5="Si"),ROUND(F5*'Parametri 2026'!$B$16,2),0),"") | I5: =IF(ISNUMBER(F5),F5+H5,"") | J5: =IF(ISNUMBER(F5),IF(I5>'Parametri 2026'!$B$14,'Parametri 2026'!$B$13,0),"") | K5: Sì | L5: =IF(ISNUMBER(F5),I5+IF(K5="No",0,J5),"") | M5: =IF(ISNUMBER(F5),I5+IF(AND(K5<>"No",Impostazioni!$B$29="Sì"),J5,0),"") | N5: =IF(F5="","",IF(NOT(ISNUMBER(F5)),"Compenso non valido",IF(C5="","Da incassare",IF(NOT(ISNUMBER(C5)),"Data non valida",IF(YEAR(C5)='Parametri 2026'!$B$6,"Incassata","Incassata nel "&YEAR(C5))))))
A6: 1/2026 | B6: 46031 | C6: 46052 | D6: Panificio Moretti | E6: Menu e volantini | F6: 450 | G6: Sì | H6: =IF(ISNUMBER(F6),IF(OR(G6="Sì",G6="Si"),ROUND(F6*'Parametri 2026'!$B$16,2),0),"") | I6: =IF(ISNUMBER(F6),F6+H6,"") | J6: =IF(ISNUMBER(F6),IF(I6>'Parametri 2026'!$B$14,'Parametri 2026'!$B$13,0),"") | K6: Sì | L6: =IF(ISNUMBER(F6),I6+IF(K6="No",0,J6),"") | M6: =IF(ISNUMBER(F6),I6+IF(AND(K6<>"No",Impostazioni!$B$29="Sì"),J6,0),"") | N6: =IF(F6="","",IF(NOT(ISNUMBER(F6)),"Compenso non valido",IF(C6="","Da incassare",IF(NOT(ISNUMBER(C6)),"Data non valida",IF(YEAR(C6)='Parametri 2026'!$B$6,"Incassata","Incassata nel "&YEAR(C6))))))
A7: 2/2026 | B7: 46042 | C7: 46072 | D7: Studio Associato Bianchi | E7: Grafica pagine sito web | F7: 2200 | G7: Sì | H7: =IF(ISNUMBER(F7),IF(OR(G7="Sì",G7="Si"),ROUND(F7*'Parametri 2026'!$B$16,2),0),"") | I7: =IF(ISNUMBER(F7),F7+H7,"") | J7: =IF(ISNUMBER(F7),IF(I7>'Parametri 2026'!$B$14,'Parametri 2026'!$B$13,0),"") | K7: Sì | L7: =IF(ISNUMBER(F7),I7+IF(K7="No",0,J7),"") | M7: =IF(ISNUMBER(F7),I7+IF(AND(K7<>"No",Impostazioni!$B$29="Sì"),J7,0),"") | N7: =IF(F7="","",IF(NOT(ISNUMBER(F7)),"Compenso non valido",IF(C7="","Da incassare",IF(NOT(ISNUMBER(C7)),"Data non valida",IF(YEAR(C7)='Parametri 2026'!$B$6,"Incassata","Incassata nel "&YEAR(C7))))))
A8: 3/2026 | B8: 46055 | C8: 46084 | D8: Hotel Belvedere | E8: Brochure e cartella stampa | F8: 1350 | G8: Sì | H8: =IF(ISNUMBER(F8),IF(OR(G8="Sì",G8="Si"),ROUND(F8*'Parametri 2026'!$B$16,2),0),"") | I8: =IF(ISNUMBER(F8),F8+H8,"") | J8: =IF(ISNUMBER(F8),IF(I8>'Parametri 2026'!$B$14,'Parametri 2026'!$B$13,0),"") | K8: Sì | L8: =IF(ISNUMBER(F8),I8+IF(K8="No",0,J8),"") | M8: =IF(ISNUMBER(F8),I8+IF(AND(K8<>"No",Impostazioni!$B$29="Sì"),J8,0),"") | N8: =IF(F8="","",IF(NOT(ISNUMBER(F8)),"Compenso non valido",IF(C8="","Da incassare",IF(NOT(ISNUMBER(C8)),"Data non valida",IF(YEAR(C8)='Parametri 2026'!$B$6,"Incassata","Incassata nel "&YEAR(C8))))))
A9: 4/2026 | B9: 46069 | C9: 46069 | D9: Giulia Ferri | E9: Biglietti da visita | F9: 70 | G9: No | H9: =IF(ISNUMBER(F9),IF(OR(G9="Sì",G9="Si"),ROUND(F9*'Parametri 2026'!$B$16,2),0),"") | I9: =IF(ISNUMBER(F9),F9+H9,"") | J9: =IF(ISNUMBER(F9),IF(I9>'Parametri 2026'!$B$14,'Parametri 2026'!$B$13,0),"") | K9: Sì | L9: =IF(ISNUMBER(F9),I9+IF(K9="No",0,J9),"") | M9: =IF(ISNUMBER(F9),I9+IF(AND(K9<>"No",Impostazioni!$B$29="Sì"),J9,0),"") | N9: =IF(F9="","",IF(NOT(ISNUMBER(F9)),"Compenso non valido",IF(C9="","Da incassare",IF(NOT(ISNUMBER(C9)),"Data non valida",IF(YEAR(C9)='Parametri 2026'!$B$6,"Incassata","Incassata nel "&YEAR(C9))))))
A10: 5/2026 | B10: 46080 | C10: 46112 | D10: Agenzia Delta Comunicazione srl | E10: Campagna social marzo | F10: 1600 | G10: Sì | H10: =IF(ISNUMBER(F10),IF(OR(G10="Sì",G10="Si"),ROUND(F10*'Parametri 2026'!$B$16,2),0),"") | I10: =IF(ISNUMBER(F10),F10+H10,"") | J10: =IF(ISNUMBER(F10),IF(I10>'Parametri 2026'!$B$14,'Parametri 2026'!$B$13,0),"") | K10: Sì | L10: =IF(ISNUMBER(F10),I10+IF(K10="No",0,J10),"") | M10: =IF(ISNUMBER(F10),I10+IF(AND(K10<>"No",Impostazioni!$B$29="Sì"),J10,0),"") | N10: =IF(F10="","",IF(NOT(ISNUMBER(F10)),"Compenso non valido",IF(C10="","Da incassare",IF(NOT(ISNUMBER(C10)),"Data non valida",IF(YEAR(C10)='Parametri 2026'!$B$6,"Incassata","Incassata nel "&YEAR(C10))))))
A11: 6/2026 | B11: 46091 | C11: 46121 | D11: Cantina Colli Alti | E11: Etichette vino, 3 referenze | F11: 2400 | G11: Sì | H11: =IF(ISNUMBER(F11),IF(OR(G11="Sì",G11="Si"),ROUND(F11*'Parametri 2026'!$B$16,2),0),"") | I11: =IF(ISNUMBER(F11),F11+H11,"") | J11: =IF(ISNUMBER(F11),IF(I11>'Parametri 2026'!$B$14,'Parametri 2026'!$B$13,0),"") | K11: Sì | L11: =IF(ISNUMBER(F11),I11+IF(K11="No",0,J11),"") | M11: =IF(ISNUMBER(F11),I11+IF(AND(K11<>"No",Impostazioni!$B$29="Sì"),J11,0),"") | N11: =IF(F11="","",IF(NOT(ISNUMBER(F11)),"Compenso non valido",IF(C11="","Da incassare",IF(NOT(ISNUMBER(C11)),"Data non valida",IF(YEAR(C11)='Parametri 2026'!$B$6,"Incassata","Incassata nel "&YEAR(C11))))))
A12: 7/2026 | B12: 46106 | C12: 46136 | D12: Associazione culturale Il Ponte | E12: Locandine rassegna | F12: 380 | G12: Sì | H12: =IF(ISNUMBER(F12),IF(OR(G12="Sì",G12="Si"),ROUND(F12*'Parametri 2026'!$B$16,2),0),"") | I12: =IF(ISNUMBER(F12),F12+H12,"") | J12: =IF(ISNUMBER(F12),IF(I12>'Parametri 2026'!$B$14,'Parametri 2026'!$B$13,0),"") | K12: Sì | L12: =IF(ISNUMBER(F12),I12+IF(K12="No",0,J12),"") | M12: =IF(ISNUMBER(F12),I12+IF(AND(K12<>"No",Impostazioni!$B$29="Sì"),J12,0),"") | N12: =IF(F12="","",IF(NOT(ISNUMBER(F12)),"Compenso non valido",IF(C12="","Da incassare",IF(NOT(ISNUMBER(C12)),"Data non valida",IF(YEAR(C12)='Parametri 2026'!$B$6,"Incassata","Incassata nel "&YEAR(C12))))))
A13: 8/2026 | B13: 46120 | C13: 46150 | D13: Studio Associato Bianchi | E13: Manutenzione grafica sito | F13: 600 | G13: Sì | H13: =IF(ISNUMBER(F13),IF(OR(G13="Sì",G13="Si"),ROUND(F13*'Parametri 2026'!$B$16,2),0),"") | I13: =IF(ISNUMBER(F13),F13+H13,"") | J13: =IF(ISNUMBER(F13),IF(I13>'Parametri 2026'!$B$14,'Parametri 2026'!$B$13,0),"") | K13: Sì | L13: =IF(ISNUMBER(F13),I13+IF(K13="No",0,J13),"") | M13: =IF(ISNUMBER(F13),I13+IF(AND(K13<>"No",Impostazioni!$B$29="Sì"),J13,0),"") | N13: =IF(F13="","",IF(NOT(ISNUMBER(F13)),"Compenso non valido",IF(C13="","Da incassare",IF(NOT(ISNUMBER(C13)),"Data non valida",IF(YEAR(C13)='Parametri 2026'!$B$6,"Incassata","Incassata nel "&YEAR(C13))))))
A14: 9/2026 | B14: 46134 | C14: 46171 | D14: Ferramenta Galli | E14: Catalogo prodotti | F14: 2900 | G14: Sì | H14: =IF(ISNUMBER(F14),IF(OR(G14="Sì",G14="Si"),ROUND(F14*'Parametri 2026'!$B$16,2),0),"") | I14: =IF(ISNUMBER(F14),F14+H14,"") | J14: =IF(ISNUMBER(F14),IF(I14>'Parametri 2026'!$B$14,'Parametri 2026'!$B$13,0),"") | K14: Sì | L14: =IF(ISNUMBER(F14),I14+IF(K14="No",0,J14),"") | M14: =IF(ISNUMBER(F14),I14+IF(AND(K14<>"No",Impostazioni!$B$29="Sì"),J14,0),"") | N14: =IF(F14="","",IF(NOT(ISNUMBER(F14)),"Compenso non valido",IF(C14="","Da incassare",IF(NOT(ISNUMBER(C14)),"Data non valida",IF(YEAR(C14)='Parametri 2026'!$B$6,"Incassata","Incassata nel "&YEAR(C14))))))
A15: 10/2026 | B15: 46148 | C15: 46178 | D15: Agenzia Delta Comunicazione srl | E15: Campagna social maggio | F15: 1600 | G15: Sì | H15: =IF(ISNUMBER(F15),IF(OR(G15="Sì",G15="Si"),ROUND(F15*'Parametri 2026'!$B$16,2),0),"") | I15: =IF(ISNUMBER(F15),F15+H15,"") | J15: =IF(ISNUMBER(F15),IF(I15>'Parametri 2026'!$B$14,'Parametri 2026'!$B$13,0),"") | K15: Sì | L15: =IF(ISNUMBER(F15),I15+IF(K15="No",0,J15),"") | M15: =IF(ISNUMBER(F15),I15+IF(AND(K15<>"No",Impostazioni!$B$29="Sì"),J15,0),"") | N15: =IF(F15="","",IF(NOT(ISNUMBER(F15)),"Compenso non valido",IF(C15="","Da incassare",IF(NOT(ISNUMBER(C15)),"Data non valida",IF(YEAR(C15)='Parametri 2026'!$B$6,"Incassata","Incassata nel "&YEAR(C15))))))
A16: 11/2026 | B16: 46162 | C16: 46192 | D16: Hotel Belvedere | E16: Grafica sito e servizio foto | F16: 3100 | G16: Sì | H16: =IF(ISNUMBER(F16),IF(OR(G16="Sì",G16="Si"),ROUND(F16*'Parametri 2026'!$B$16,2),0),"") | I16: =IF(ISNUMBER(F16),F16+H16,"") | J16: =IF(ISNUMBER(F16),IF(I16>'Parametri 2026'!$B$14,'Parametri 2026'!$B$13,0),"") | K16: Sì | L16: =IF(ISNUMBER(F16),I16+IF(K16="No",0,J16),"") | M16: =IF(ISNUMBER(F16),I16+IF(AND(K16<>"No",Impostazioni!$B$29="Sì"),J16,0),"") | N16: =IF(F16="","",IF(NOT(ISNUMBER(F16)),"Compenso non valido",IF(C16="","Da incassare",IF(NOT(ISNUMBER(C16)),"Data non valida",IF(YEAR(C16)='Parametri 2026'!$B$6,"Incassata","Incassata nel "&YEAR(C16))))))
... A29: 24/2026 | B29: 46358 | C29: 46378 | D29: Ferramenta Galli | E29: Calendario 2027 | F29: 1450 | G29: Sì | H29: =IF(ISNUMBER(F29),IF(OR(G29="Sì",G29="Si"),ROUND(F29*'Parametri 2026'!$B$16,2),0),"") | I29: =IF(ISNUMBER(F29),F29+H29,"") | J29: =IF(ISNUMBER(F29),IF(I29>'Parametri 2026'!$B$14,'Parametri 2026'!$B$13,0),"") | K29: Sì | L29: =IF(ISNUMBER(F29),I29+IF(K29="No",0,J29),"") | M29: =IF(ISNUMBER(F29),I29+IF(AND(K29<>"No",Impostazioni!$B$29="Sì"),J29,0),"") | N29: =IF(F29="","",IF(NOT(ISNUMBER(F29)),"Compenso non valido",IF(C29="","Da incassare",IF(NOT(ISNUMBER(C29)),"Data non valida",IF(YEAR(C29)='Parametri 2026'!$B$6,"Incassata","Incassata nel "&YEAR(C29))))))
A30: 25/2026 | B30: 46371 | D30: Hotel Belvedere | E30: Auguri e campagna gennaio | F30: 1200 | G30: Sì | H30: =IF(ISNUMBER(F30),IF(OR(G30="Sì",G30="Si"),ROUND(F30*'Parametri 2026'!$B$16,2),0),"") | I30: =IF(ISNUMBER(F30),F30+H30,"") | J30: =IF(ISNUMBER(F30),IF(I30>'Parametri 2026'!$B$14,'Parametri 2026'!$B$13,0),"") | K30: Sì | L30: =IF(ISNUMBER(F30),I30+IF(K30="No",0,J30),"") | M30: =IF(ISNUMBER(F30),I30+IF(AND(K30<>"No",Impostazioni!$B$29="Sì"),J30,0),"") | N30: =IF(F30="","",IF(NOT(ISNUMBER(F30)),"Compenso non valido",IF(C30="","Da incassare",IF(NOT(ISNUMBER(C30)),"Data non valida",IF(YEAR(C30)='Parametri 2026'!$B$6,"Incassata","Incassata nel "&YEAR(C30))))))
A31: 26/2026 | B31: 46377 | D31: Cantina Colli Alti | E31: Etichette nuova linea | F31: 1900 | G31: Sì | H31: =IF(ISNUMBER(F31),IF(OR(G31="Sì",G31="Si"),ROUND(F31*'Parametri 2026'!$B$16,2),0),"") | I31: =IF(ISNUMBER(F31),F31+H31,"") | J31: =IF(ISNUMBER(F31),IF(I31>'Parametri 2026'!$B$14,'Parametri 2026'!$B$13,0),"") | K31: Sì | L31: =IF(ISNUMBER(F31),I31+IF(K31="No",0,J31),"") | M31: =IF(ISNUMBER(F31),I31+IF(AND(K31<>"No",Impostazioni!$B$29="Sì"),J31,0),"") | N31: =IF(F31="","",IF(NOT(ISNUMBER(F31)),"Compenso non valido",IF(C31="","Da incassare",IF(NOT(ISNUMBER(C31)),"Data non valida",IF(YEAR(C31)='Parametri 2026'!$B$6,"Incassata","Incassata nel "&YEAR(C31))))))
H32: =IF(ISNUMBER(F32),IF(OR(G32="Sì",G32="Si"),ROUND(F32*'Parametri 2026'!$B$16,2),0),"") | I32: =IF(ISNUMBER(F32),F32+H32,"") | J32: =IF(ISNUMBER(F32),IF(I32>'Parametri 2026'!$B$14,'Parametri 2026'!$B$13,0),"") | L32: =IF(ISNUMBER(F32),I32+IF(K32="No",0,J32),"") | M32: =IF(ISNUMBER(F32),I32+IF(AND(K32<>"No",Impostazioni!$B$29="Sì"),J32,0),"") | N32: =IF(F32="","",IF(NOT(ISNUMBER(F32)),"Compenso non valido",IF(C32="","Da incassare",IF(NOT(ISNUMBER(C32)),"Data non valida",IF(YEAR(C32)='Parametri 2026'!$B$6,"Incassata","Incassata nel "&YEAR(C32))))))
H33: =IF(ISNUMBER(F33),IF(OR(G33="Sì",G33="Si"),ROUND(F33*'Parametri 2026'!$B$16,2),0),"") | I33: =IF(ISNUMBER(F33),F33+H33,"") | J33: =IF(ISNUMBER(F33),IF(I33>'Parametri 2026'!$B$14,'Parametri 2026'!$B$13,0),"") | L33: =IF(ISNUMBER(F33),I33+IF(K33="No",0,J33),"") | M33: =IF(ISNUMBER(F33),I33+IF(AND(K33<>"No",Impostazioni!$B$29="Sì"),J33,0),"") | N33: =IF(F33="","",IF(NOT(ISNUMBER(F33)),"Compenso non valido",IF(C33="","Da incassare",IF(NOT(ISNUMBER(C33)),"Data non valida",IF(YEAR(C33)='Parametri 2026'!$B$6,"Incassata","Incassata nel "&YEAR(C33))))))
H34: =IF(ISNUMBER(F34),IF(OR(G34="Sì",G34="Si"),ROUND(F34*'Parametri 2026'!$B$16,2),0),"") | I34: =IF(ISNUMBER(F34),F34+H34,"") | J34: =IF(ISNUMBER(F34),IF(I34>'Parametri 2026'!$B$14,'Parametri 2026'!$B$13,0),"") | L34: =IF(ISNUMBER(F34),I34+IF(K34="No",0,J34),"") | M34: =IF(ISNUMBER(F34),I34+IF(AND(K34<>"No",Impostazioni!$B$29="Sì"),J34,0),"") | N34: =IF(F34="","",IF(NOT(ISNUMBER(F34)),"Compenso non valido",IF(C34="","Da incassare",IF(NOT(ISNUMBER(C34)),"Data non valida",IF(YEAR(C34)='Parametri 2026'!$B$6,"Incassata","Incassata nel "&YEAR(C34))))))
H35: =IF(ISNUMBER(F35),IF(OR(G35="Sì",G35="Si"),ROUND(F35*'Parametri 2026'!$B$16,2),0),"") | I35: =IF(ISNUMBER(F35),F35+H35,"") | J35: =IF(ISNUMBER(F35),IF(I35>'Parametri 2026'!$B$14,'Parametri 2026'!$B$13,0),"") | L35: =IF(ISNUMBER(F35),I35+IF(K35="No",0,J35),"") | M35: =IF(ISNUMBER(F35),I35+IF(AND(K35<>"No",Impostazioni!$B$29="Sì"),J35,0),"") | N35: =IF(F35="","",IF(NOT(ISNUMBER(F35)),"Compenso non valido",IF(C35="","Da incassare",IF(NOT(ISNUMBER(C35)),"Data non valida",IF(YEAR(C35)='Parametri 2026'!$B$6,"Incassata","Incassata nel "&YEAR(C35))))))
H36: =IF(ISNUMBER(F36),IF(OR(G36="Sì",G36="Si"),ROUND(F36*'Parametri 2026'!$B$16,2),0),"") | I36: =IF(ISNUMBER(F36),F36+H36,"") | J36: =IF(ISNUMBER(F36),IF(I36>'Parametri 2026'!$B$14,'Parametri 2026'!$B$13,0),"") | L36: =IF(ISNUMBER(F36),I36+IF(K36="No",0,J36),"") | M36: =IF(ISNUMBER(F36),I36+IF(AND(K36<>"No",Impostazioni!$B$29="Sì"),J36,0),"") | N36: =IF(F36="","",IF(NOT(ISNUMBER(F36)),"Compenso non valido",IF(C36="","Da incassare",IF(NOT(ISNUMBER(C36)),"Data non valida",IF(YEAR(C36)='Parametri 2026'!$B$6,"Incassata","Incassata nel "&YEAR(C36))))))
H37: =IF(ISNUMBER(F37),IF(OR(G37="Sì",G37="Si"),ROUND(F37*'Parametri 2026'!$B$16,2),0),"") | I37: =IF(ISNUMBER(F37),F37+H37,"") | J37: =IF(ISNUMBER(F37),IF(I37>'Parametri 2026'!$B$14,'Parametri 2026'!$B$13,0),"") | L37: =IF(ISNUMBER(F37),I37+IF(K37="No",0,J37),"") | M37: =IF(ISNUMBER(F37),I37+IF(AND(K37<>"No",Impostazioni!$B$29="Sì"),J37,0),"") | N37: =IF(F37="","",IF(NOT(ISNUMBER(F37)),"Compenso non valido",IF(C37="","Da incassare",IF(NOT(ISNUMBER(C37)),"Data non valida",IF(YEAR(C37)='Parametri 2026'!$B$6,"Incassata","Incassata nel "&YEAR(C37))))))
H38: =IF(ISNUMBER(F38),IF(OR(G38="Sì",G38="Si"),ROUND(F38*'Parametri 2026'!$B$16,2),0),"") | I38: =IF(ISNUMBER(F38),F38+H38,"") | J38: =IF(ISNUMBER(F38),IF(I38>'Parametri 2026'!$B$14,'Parametri 2026'!$B$13,0),"") | L38: =IF(ISNUMBER(F38),I38+IF(K38="No",0,J38),"") | M38: =IF(ISNUMBER(F38),I38+IF(AND(K38<>"No",Impostazioni!$B$29="Sì"),J38,0),"") | N38: =IF(F38="","",IF(NOT(ISNUMBER(F38)),"Compenso non valido",IF(C38="","Da incassare",IF(NOT(ISNUMBER(C38)),"Data non valida",IF(YEAR(C38)='Parametri 2026'!$B$6,"Incassata","Incassata nel "&YEAR(C38))))))
H39: =IF(ISNUMBER(F39),IF(OR(G39="Sì",G39="Si"),ROUND(F39*'Parametri 2026'!$B$16,2),0),"") | I39: =IF(ISNUMBER(F39),F39+H39,"") | J39: =IF(ISNUMBER(F39),IF(I39>'Parametri 2026'!$B$14,'Parametri 2026'!$B$13,0),"") | L39: =IF(ISNUMBER(F39),I39+IF(K39="No",0,J39),"") | M39: =IF(ISNUMBER(F39),I39+IF(AND(K39<>"No",Impostazioni!$B$29="Sì"),J39,0),"") | N39: =IF(F39="","",IF(NOT(ISNUMBER(F39)),"Compenso non valido",IF(C39="","Da incassare",IF(NOT(ISNUMBER(C39)),"Data non valida",IF(YEAR(C39)='Parametri 2026'!$B$6,"Incassata","Incassata nel "&YEAR(C39))))))
H40: =IF(ISNUMBER(F40),IF(OR(G40="Sì",G40="Si"),ROUND(F40*'Parametri 2026'!$B$16,2),0),"") | I40: =IF(ISNUMBER(F40),F40+H40,"") | J40: =IF(ISNUMBER(F40),IF(I40>'Parametri 2026'!$B$14,'Parametri 2026'!$B$13,0),"") | L40: =IF(ISNUMBER(F40),I40+IF(K40="No",0,J40),"") | M40: =IF(ISNUMBER(F40),I40+IF(AND(K40<>"No",Impostazioni!$B$29="Sì"),J40,0),"") | N40: =IF(F40="","",IF(NOT(ISNUMBER(F40)),"Compenso non valido",IF(C40="","Da incassare",IF(NOT(ISNUMBER(C40)),"Data non valida",IF(YEAR(C40)='Parametri 2026'!$B$6,"Incassata","Incassata nel "&YEAR(C40))))))
H41: =IF(ISNUMBER(F41),IF(OR(G41="Sì",G41="Si"),ROUND(F41*'Parametri 2026'!$B$16,2),0),"") | I41: =IF(ISNUMBER(F41),F41+H41,"") | J41: =IF(ISNUMBER(F41),IF(I41>'Parametri 2026'!$B$14,'Parametri 2026'!$B$13,0),"") | L41: =IF(ISNUMBER(F41),I41+IF(K41="No",0,J41),"") | M41: =IF(ISNUMBER(F41),I41+IF(AND(K41<>"No",Impostazioni!$B$29="Sì"),J41,0),"") | N41: =IF(F41="","",IF(NOT(ISNUMBER(F41)),"Compenso non valido",IF(C41="","Da incassare",IF(NOT(ISNUMBER(C41)),"Data non valida",IF(YEAR(C41)='Parametri 2026'!$B$6,"Incassata","Incassata nel "&YEAR(C41))))))
H42: =IF(ISNUMBER(F42),IF(OR(G42="Sì",G42="Si"),ROUND(F42*'Parametri 2026'!$B$16,2),0),"") | I42: =IF(ISNUMBER(F42),F42+H42,"") | J42: =IF(ISNUMBER(F42),IF(I42>'Parametri 2026'!$B$14,'Parametri 2026'!$B$13,0),"") | L42: =IF(ISNUMBER(F42),I42+IF(K42="No",0,J42),"") | M42: =IF(ISNUMBER(F42),I42+IF(AND(K42<>"No",Impostazioni!$B$29="Sì"),J42,0),"") | N42: =IF(F42="","",IF(NOT(ISNUMBER(F42)),"Compenso non valido",IF(C42="","Da incassare",IF(NOT(ISNUMBER(C42)),"Data non valida",IF(YEAR(C42)='Parametri 2026'!$B$6,"Incassata","Incassata nel "&YEAR(C42))))))
H43: =IF(ISNUMBER(F43),IF(OR(G43="Sì",G43="Si"),ROUND(F43*'Parametri 2026'!$B$16,2),0),"") | I43: =IF(ISNUMBER(F43),F43+H43,"") | J43: =IF(ISNUMBER(F43),IF(I43>'Parametri 2026'!$B$14,'Parametri 2026'!$B$13,0),"") | L43: =IF(ISNUMBER(F43),I43+IF(K43="No",0,J43),"") | M43: =IF(ISNUMBER(F43),I43+IF(AND(K43<>"No",Impostazioni!$B$29="Sì"),J43,0),"") | N43: =IF(F43="","",IF(NOT(ISNUMBER(F43)),"Compenso non valido",IF(C43="","Da incassare",IF(NOT(ISNUMBER(C43)),"Data non valida",IF(YEAR(C43)='Parametri 2026'!$B$6,"Incassata","Incassata nel "&YEAR(C43))))))
... H304: =IF(ISNUMBER(F304),IF(OR(G304="Sì",G304="Si"),ROUND(F304*'Parametri 2026'!$B$16,2),0),"") | I304: =IF(ISNUMBER(F304),F304+H304,"") | J304: =IF(ISNUMBER(F304),IF(I304>'Parametri 2026'!$B$14,'Parametri 2026'!$B$13,0),"") | L304: =IF(ISNUMBER(F304),I304+IF(K304="No",0,J304),"") | M304: =IF(ISNUMBER(F304),I304+IF(AND(K304<>"No",Impostazioni!$B$29="Sì"),J304,0),"") | N304: =IF(F304="","",IF(NOT(ISNUMBER(F304)),"Compenso non valido",IF(C304="","Da incassare",IF(NOT(ISNUMBER(C304)),"Data non valida",IF(YEAR(C304)='Parametri 2026'!$B$6,"Incassata","Incassata nel "&YEAR(C304))))))

Sheet Spese
A1: Spese (facoltativo)
A2: Nel forfettario i costi non si deducono: questo foglio serve solo a vedere il netto vero. Non inserire qui tasse e contributi, li calcola il file.
C3: Spese nel 2026 | D3: ='Riepilogo mensile'!$L$17
A4: Data pagamento | B4: Descrizione | C4: Categoria | D4: Importo (€) | E4: Note
A5: 46027 | B5: Coworking, 1° trimestre | C5: Affitto e coworking | D5: 420
A6: 46037 | B6: Software di grafica, abbonamento annuale | C6: Software e abbonamenti | D6: 720
A7: 46053 | B7: Hosting e dominio del portfolio | C7: Software e abbonamenti | D7: 95
A8: 46063 | B8: Commercialista, prima rata | C8: Commercialista | D8: 400
A9: 46086 | B9: Monitor | C9: Attrezzatura | D9: 389
A10: 46119 | B10: Coworking, 2° trimestre | C10: Affitto e coworking | D10: 420
A11: 46132 | B11: Corso online di tipografia | C11: Formazione | D11: 180
A12: 46185 | B12: Stampa campioni etichette | C12: Materiali | D12: 85
A13: 46209 | B13: Coworking, 3° trimestre | C13: Affitto e coworking | D13: 420
A14: 46275 | B14: Commercialista, seconda rata | C14: Commercialista | D14: 400
A15: 46300 | B15: Coworking, 4° trimestre | C15: Affitto e coworking | D15: 420
A16: 46344 | B16: Trasferta fiera Cantina Colli Alti | C16: Trasporti e trasferte | D16: 210
A17: 46357 | B17: Telefono e internet, anno | C17: Telefono e internet | D17: 300

Sheet Riepilogo mensile
A1: Riepilogo mensile 2026
A2: Incassi per data di incasso. Le colonne "da inizio anno" stimano tasse e contributi come se l'anno finisse quel mese; "Da accantonare nel mese" è la differenza con il mese prima.
A4: Mese | B4: Incassato nel mese | C4: Fatture incassate | D4: Incassato da inizio anno | E4: % soglia 85.000 € | F4: % soglia 100.000 € | G4: Reddito da inizio anno | H4: Contributi stimati da inizio anno | I4: Imposta stimata da inizio anno | J4: Tasse e contributi da inizio anno | K4: Da accantonare nel mese | L4: Spese del mese | M4: Netto stimato del mese | N4: Netto da inizio anno
A5: Gennaio | B5: =SUMIFS(Fatture!$M$5:$M$304,Fatture!$C$5:$C$304,">="&DATE('Parametri 2026'!$B$6,1,1),Fatture!$C$5:$C$304,"<"&DATE('Parametri 2026'!$B$6,2,1)) | C5: =COUNTIFS(Fatture!$C$5:$C$304,">="&DATE('Parametri 2026'!$B$6,1,1),Fatture!$C$5:$C$304,"<"&DATE('Parametri 2026'!$B$6,2,1),Fatture!$N$5:$N$304,"Incassata") | D5: =B5 | E5: =D5/'Parametri 2026'!$B$7 | F5: =D5/'Parametri 2026'!$B$8 | G5: =D5*Impostazioni!$B$16 | H5: =Impostazioni!$B$25+IF(OR(Impostazioni!$B$17=1,Impostazioni!$B$17=2),MIN(MAX(G5,0),Impostazioni!$B$28)*Impostazioni!$B$19,IF(Impostazioni!$B$17=5,MAX(G5,0)*Impostazioni!$B$19,IF(OR(Impostazioni!$B$17=3,Impostazioni!$B$17=4),(MAX(0,MIN(MIN(MAX(G5,0),Impostazioni!$B$28),Impostazioni!$B$26)-Impostazioni!$B$22)*Impostazioni!$B$19+MAX(0,MIN(MAX(G5,0),Impostazioni!$B$28)-Impostazioni!$B$26)*Impostazioni!$B$27)*Impostazioni!$B$21,0))) | I5: =MAX(0,G5-IF(ISNUMBER(Impostazioni!$B$12),Impostazioni!$B$12,H5))*Impostazioni!$B$18 | J5: =H5+I5 | K5: =J5-Impostazioni!$B$25+Impostazioni!$B$25/12 | L5: =SUMIFS(Spese!$D$5:$D$204,Spese!$A$5:$A$204,">="&DATE('Parametri 2026'!$B$6,1,1),Spese!$A$5:$A$204,"<"&DATE('Parametri 2026'!$B$6,2,1)) | M5: =B5-K5-L5 | N5: =M5
A6: Febbraio | B6: =SUMIFS(Fatture!$M$5:$M$304,Fatture!$C$5:$C$304,">="&DATE('Parametri 2026'!$B$6,2,1),Fatture!$C$5:$C$304,"<"&DATE('Parametri 2026'!$B$6,3,1)) | C6: =COUNTIFS(Fatture!$C$5:$C$304,">="&DATE('Parametri 2026'!$B$6,2,1),Fatture!$C$5:$C$304,"<"&DATE('Parametri 2026'!$B$6,3,1),Fatture!$N$5:$N$304,"Incassata") | D6: =D5+B6 | E6: =D6/'Parametri 2026'!$B$7 | F6: =D6/'Parametri 2026'!$B$8 | G6: =D6*Impostazioni!$B$16 | H6: =Impostazioni!$B$25+IF(OR(Impostazioni!$B$17=1,Impostazioni!$B$17=2),MIN(MAX(G6,0),Impostazioni!$B$28)*Impostazioni!$B$19,IF(Impostazioni!$B$17=5,MAX(G6,0)*Impostazioni!$B$19,IF(OR(Impostazioni!$B$17=3,Impostazioni!$B$17=4),(MAX(0,MIN(MIN(MAX(G6,0),Impostazioni!$B$28),Impostazioni!$B$26)-Impostazioni!$B$22)*Impostazioni!$B$19+MAX(0,MIN(MAX(G6,0),Impostazioni!$B$28)-Impostazioni!$B$26)*Impostazioni!$B$27)*Impostazioni!$B$21,0))) | I6: =MAX(0,G6-IF(ISNUMBER(Impostazioni!$B$12),Impostazioni!$B$12,H6))*Impostazioni!$B$18 | J6: =H6+I6 | K6: =J6-J5+Impostazioni!$B$25/12 | L6: =SUMIFS(Spese!$D$5:$D$204,Spese!$A$5:$A$204,">="&DATE('Parametri 2026'!$B$6,2,1),Spese!$A$5:$A$204,"<"&DATE('Parametri 2026'!$B$6,3,1)) | M6: =B6-K6-L6 | N6: =N5+M6
A7: Marzo | B7: =SUMIFS(Fatture!$M$5:$M$304,Fatture!$C$5:$C$304,">="&DATE('Parametri 2026'!$B$6,3,1),Fatture!$C$5:$C$304,"<"&DATE('Parametri 2026'!$B$6,4,1)) | C7: =COUNTIFS(Fatture!$C$5:$C$304,">="&DATE('Parametri 2026'!$B$6,3,1),Fatture!$C$5:$C$304,"<"&DATE('Parametri 2026'!$B$6,4,1),Fatture!$N$5:$N$304,"Incassata") | D7: =D6+B7 | E7: =D7/'Parametri 2026'!$B$7 | F7: =D7/'Parametri 2026'!$B$8 | G7: =D7*Impostazioni!$B$16 | H7: =Impostazioni!$B$25+IF(OR(Impostazioni!$B$17=1,Impostazioni!$B$17=2),MIN(MAX(G7,0),Impostazioni!$B$28)*Impostazioni!$B$19,IF(Impostazioni!$B$17=5,MAX(G7,0)*Impostazioni!$B$19,IF(OR(Impostazioni!$B$17=3,Impostazioni!$B$17=4),(MAX(0,MIN(MIN(MAX(G7,0),Impostazioni!$B$28),Impostazioni!$B$26)-Impostazioni!$B$22)*Impostazioni!$B$19+MAX(0,MIN(MAX(G7,0),Impostazioni!$B$28)-Impostazioni!$B$26)*Impostazioni!$B$27)*Impostazioni!$B$21,0))) | I7: =MAX(0,G7-IF(ISNUMBER(Impostazioni!$B$12),Impostazioni!$B$12,H7))*Impostazioni!$B$18 | J7: =H7+I7 | K7: =J7-J6+Impostazioni!$B$25/12 | L7: =SUMIFS(Spese!$D$5:$D$204,Spese!$A$5:$A$204,">="&DATE('Parametri 2026'!$B$6,3,1),Spese!$A$5:$A$204,"<"&DATE('Parametri 2026'!$B$6,4,1)) | M7: =B7-K7-L7 | N7: =N6+M7
A8: Aprile | B8: =SUMIFS(Fatture!$M$5:$M$304,Fatture!$C$5:$C$304,">="&DATE('Parametri 2026'!$B$6,4,1),Fatture!$C$5:$C$304,"<"&DATE('Parametri 2026'!$B$6,5,1)) | C8: =COUNTIFS(Fatture!$C$5:$C$304,">="&DATE('Parametri 2026'!$B$6,4,1),Fatture!$C$5:$C$304,"<"&DATE('Parametri 2026'!$B$6,5,1),Fatture!$N$5:$N$304,"Incassata") | D8: =D7+B8 | E8: =D8/'Parametri 2026'!$B$7 | F8: =D8/'Parametri 2026'!$B$8 | G8: =D8*Impostazioni!$B$16 | H8: =Impostazioni!$B$25+IF(OR(Impostazioni!$B$17=1,Impostazioni!$B$17=2),MIN(MAX(G8,0),Impostazioni!$B$28)*Impostazioni!$B$19,IF(Impostazioni!$B$17=5,MAX(G8,0)*Impostazioni!$B$19,IF(OR(Impostazioni!$B$17=3,Impostazioni!$B$17=4),(MAX(0,MIN(MIN(MAX(G8,0),Impostazioni!$B$28),Impostazioni!$B$26)-Impostazioni!$B$22)*Impostazioni!$B$19+MAX(0,MIN(MAX(G8,0),Impostazioni!$B$28)-Impostazioni!$B$26)*Impostazioni!$B$27)*Impostazioni!$B$21,0))) | I8: =MAX(0,G8-IF(ISNUMBER(Impostazioni!$B$12),Impostazioni!$B$12,H8))*Impostazioni!$B$18 | J8: =H8+I8 | K8: =J8-J7+Impostazioni!$B$25/12 | L8: =SUMIFS(Spese!$D$5:$D$204,Spese!$A$5:$A$204,">="&DATE('Parametri 2026'!$B$6,4,1),Spese!$A$5:$A$204,"<"&DATE('Parametri 2026'!$B$6,5,1)) | M8: =B8-K8-L8 | N8: =N7+M8
A9: Maggio | B9: =SUMIFS(Fatture!$M$5:$M$304,Fatture!$C$5:$C$304,">="&DATE('Parametri 2026'!$B$6,5,1),Fatture!$C$5:$C$304,"<"&DATE('Parametri 2026'!$B$6,6,1)) | C9: =COUNTIFS(Fatture!$C$5:$C$304,">="&DATE('Parametri 2026'!$B$6,5,1),Fatture!$C$5:$C$304,"<"&DATE('Parametri 2026'!$B$6,6,1),Fatture!$N$5:$N$304,"Incassata") | D9: =D8+B9 | E9: =D9/'Parametri 2026'!$B$7 | F9: =D9/'Parametri 2026'!$B$8 | G9: =D9*Impostazioni!$B$16 | H9: =Impostazioni!$B$25+IF(OR(Impostazioni!$B$17=1,Impostazioni!$B$17=2),MIN(MAX(G9,0),Impostazioni!$B$28)*Impostazioni!$B$19,IF(Impostazioni!$B$17=5,MAX(G9,0)*Impostazioni!$B$19,IF(OR(Impostazioni!$B$17=3,Impostazioni!$B$17=4),(MAX(0,MIN(MIN(MAX(G9,0),Impostazioni!$B$28),Impostazioni!$B$26)-Impostazioni!$B$22)*Impostazioni!$B$19+MAX(0,MIN(MAX(G9,0),Impostazioni!$B$28)-Impostazioni!$B$26)*Impostazioni!$B$27)*Impostazioni!$B$21,0))) | I9: =MAX(0,G9-IF(ISNUMBER(Impostazioni!$B$12),Impostazioni!$B$12,H9))*Impostazioni!$B$18 | J9: =H9+I9 | K9: =J9-J8+Impostazioni!$B$25/12 | L9: =SUMIFS(Spese!$D$5:$D$204,Spese!$A$5:$A$204,">="&DATE('Parametri 2026'!$B$6,5,1),Spese!$A$5:$A$204,"<"&DATE('Parametri 2026'!$B$6,6,1)) | M9: =B9-K9-L9 | N9: =N8+M9
A10: Giugno | B10: =SUMIFS(Fatture!$M$5:$M$304,Fatture!$C$5:$C$304,">="&DATE('Parametri 2026'!$B$6,6,1),Fatture!$C$5:$C$304,"<"&DATE('Parametri 2026'!$B$6,7,1)) | C10: =COUNTIFS(Fatture!$C$5:$C$304,">="&DATE('Parametri 2026'!$B$6,6,1),Fatture!$C$5:$C$304,"<"&DATE('Parametri 2026'!$B$6,7,1),Fatture!$N$5:$N$304,"Incassata") | D10: =D9+B10 | E10: =D10/'Parametri 2026'!$B$7 | F10: =D10/'Parametri 2026'!$B$8 | G10: =D10*Impostazioni!$B$16 | H10: =Impostazioni!$B$25+IF(OR(Impostazioni!$B$17=1,Impostazioni!$B$17=2),MIN(MAX(G10,0),Impostazioni!$B$28)*Impostazioni!$B$19,IF(Impostazioni!$B$17=5,MAX(G10,0)*Impostazioni!$B$19,IF(OR(Impostazioni!$B$17=3,Impostazioni!$B$17=4),(MAX(0,MIN(MIN(MAX(G10,0),Impostazioni!$B$28),Impostazioni!$B$26)-Impostazioni!$B$22)*Impostazioni!$B$19+MAX(0,MIN(MAX(G10,0),Impostazioni!$B$28)-Impostazioni!$B$26)*Impostazioni!$B$27)*Impostazioni!$B$21,0))) | I10: =MAX(0,G10-IF(ISNUMBER(Impostazioni!$B$12),Impostazioni!$B$12,H10))*Impostazioni!$B$18 | J10: =H10+I10 | K10: =J10-J9+Impostazioni!$B$25/12 | L10: =SUMIFS(Spese!$D$5:$D$204,Spese!$A$5:$A$204,">="&DATE('Parametri 2026'!$B$6,6,1),Spese!$A$5:$A$204,"<"&DATE('Parametri 2026'!$B$6,7,1)) | M10: =B10-K10-L10 | N10: =N9+M10
A11: Luglio | B11: =SUMIFS(Fatture!$M$5:$M$304,Fatture!$C$5:$C$304,">="&DATE('Parametri 2026'!$B$6,7,1),Fatture!$C$5:$C$304,"<"&DATE('Parametri 2026'!$B$6,8,1)) | C11: =COUNTIFS(Fatture!$C$5:$C$304,">="&DATE('Parametri 2026'!$B$6,7,1),Fatture!$C$5:$C$304,"<"&DATE('Parametri 2026'!$B$6,8,1),Fatture!$N$5:$N$304,"Incassata") | D11: =D10+B11 | E11: =D11/'Parametri 2026'!$B$7 | F11: =D11/'Parametri 2026'!$B$8 | G11: =D11*Impostazioni!$B$16 | H11: =Impostazioni!$B$25+IF(OR(Impostazioni!$B$17=1,Impostazioni!$B$17=2),MIN(MAX(G11,0),Impostazioni!$B$28)*Impostazioni!$B$19,IF(Impostazioni!$B$17=5,MAX(G11,0)*Impostazioni!$B$19,IF(OR(Impostazioni!$B$17=3,Impostazioni!$B$17=4),(MAX(0,MIN(MIN(MAX(G11,0),Impostazioni!$B$28),Impostazioni!$B$26)-Impostazioni!$B$22)*Impostazioni!$B$19+MAX(0,MIN(MAX(G11,0),Impostazioni!$B$28)-Impostazioni!$B$26)*Impostazioni!$B$27)*Impostazioni!$B$21,0))) | I11: =MAX(0,G11-IF(ISNUMBER(Impostazioni!$B$12),Impostazioni!$B$12,H11))*Impostazioni!$B$18 | J11: =H11+I11 | K11: =J11-J10+Impostazioni!$B$25/12 | L11: =SUMIFS(Spese!$D$5:$D$204,Spese!$A$5:$A$204,">="&DATE('Parametri 2026'!$B$6,7,1),Spese!$A$5:$A$204,"<"&DATE('Parametri 2026'!$B$6,8,1)) | M11: =B11-K11-L11 | N11: =N10+M11
A12: Agosto | B12: =SUMIFS(Fatture!$M$5:$M$304,Fatture!$C$5:$C$304,">="&DATE('Parametri 2026'!$B$6,8,1),Fatture!$C$5:$C$304,"<"&DATE('Parametri 2026'!$B$6,9,1)) | C12: =COUNTIFS(Fatture!$C$5:$C$304,">="&DATE('Parametri 2026'!$B$6,8,1),Fatture!$C$5:$C$304,"<"&DATE('Parametri 2026'!$B$6,9,1),Fatture!$N$5:$N$304,"Incassata") | D12: =D11+B12 | E12: =D12/'Parametri 2026'!$B$7 | F12: =D12/'Parametri 2026'!$B$8 | G12: =D12*Impostazioni!$B$16 | H12: =Impostazioni!$B$25+IF(OR(Impostazioni!$B$17=1,Impostazioni!$B$17=2),MIN(MAX(G12,0),Impostazioni!$B$28)*Impostazioni!$B$19,IF(Impostazioni!$B$17=5,MAX(G12,0)*Impostazioni!$B$19,IF(OR(Impostazioni!$B$17=3,Impostazioni!$B$17=4),(MAX(0,MIN(MIN(MAX(G12,0),Impostazioni!$B$28),Impostazioni!$B$26)-Impostazioni!$B$22)*Impostazioni!$B$19+MAX(0,MIN(MAX(G12,0),Impostazioni!$B$28)-Impostazioni!$B$26)*Impostazioni!$B$27)*Impostazioni!$B$21,0))) | I12: =MAX(0,G12-IF(ISNUMBER(Impostazioni!$B$12),Impostazioni!$B$12,H12))*Impostazioni!$B$18 | J12: =H12+I12 | K12: =J12-J11+Impostazioni!$B$25/12 | L12: =SUMIFS(Spese!$D$5:$D$204,Spese!$A$5:$A$204,">="&DATE('Parametri 2026'!$B$6,8,1),Spese!$A$5:$A$204,"<"&DATE('Parametri 2026'!$B$6,9,1)) | M12: =B12-K12-L12 | N12: =N11+M12
A13: Settembre | B13: =SUMIFS(Fatture!$M$5:$M$304,Fatture!$C$5:$C$304,">="&DATE('Parametri 2026'!$B$6,9,1),Fatture!$C$5:$C$304,"<"&DATE('Parametri 2026'!$B$6,10,1)) | C13: =COUNTIFS(Fatture!$C$5:$C$304,">="&DATE('Parametri 2026'!$B$6,9,1),Fatture!$C$5:$C$304,"<"&DATE('Parametri 2026'!$B$6,10,1),Fatture!$N$5:$N$304,"Incassata") | D13: =D12+B13 | E13: =D13/'Parametri 2026'!$B$7 | F13: =D13/'Parametri 2026'!$B$8 | G13: =D13*Impostazioni!$B$16 | H13: =Impostazioni!$B$25+IF(OR(Impostazioni!$B$17=1,Impostazioni!$B$17=2),MIN(MAX(G13,0),Impostazioni!$B$28)*Impostazioni!$B$19,IF(Impostazioni!$B$17=5,MAX(G13,0)*Impostazioni!$B$19,IF(OR(Impostazioni!$B$17=3,Impostazioni!$B$17=4),(MAX(0,MIN(MIN(MAX(G13,0),Impostazioni!$B$28),Impostazioni!$B$26)-Impostazioni!$B$22)*Impostazioni!$B$19+MAX(0,MIN(MAX(G13,0),Impostazioni!$B$28)-Impostazioni!$B$26)*Impostazioni!$B$27)*Impostazioni!$B$21,0))) | I13: =MAX(0,G13-IF(ISNUMBER(Impostazioni!$B$12),Impostazioni!$B$12,H13))*Impostazioni!$B$18 | J13: =H13+I13 | K13: =J13-J12+Impostazioni!$B$25/12 | L13: =SUMIFS(Spese!$D$5:$D$204,Spese!$A$5:$A$204,">="&DATE('Parametri 2026'!$B$6,9,1),Spese!$A$5:$A$204,"<"&DATE('Parametri 2026'!$B$6,10,1)) | M13: =B13-K13-L13 | N13: =N12+M13
A14: Ottobre | B14: =SUMIFS(Fatture!$M$5:$M$304,Fatture!$C$5:$C$304,">="&DATE('Parametri 2026'!$B$6,10,1),Fatture!$C$5:$C$304,"<"&DATE('Parametri 2026'!$B$6,11,1)) | C14: =COUNTIFS(Fatture!$C$5:$C$304,">="&DATE('Parametri 2026'!$B$6,10,1),Fatture!$C$5:$C$304,"<"&DATE('Parametri 2026'!$B$6,11,1),Fatture!$N$5:$N$304,"Incassata") | D14: =D13+B14 | E14: =D14/'Parametri 2026'!$B$7 | F14: =D14/'Parametri 2026'!$B$8 | G14: =D14*Impostazioni!$B$16 | H14: =Impostazioni!$B$25+IF(OR(Impostazioni!$B$17=1,Impostazioni!$B$17=2),MIN(MAX(G14,0),Impostazioni!$B$28)*Impostazioni!$B$19,IF(Impostazioni!$B$17=5,MAX(G14,0)*Impostazioni!$B$19,IF(OR(Impostazioni!$B$17=3,Impostazioni!$B$17=4),(MAX(0,MIN(MIN(MAX(G14,0),Impostazioni!$B$28),Impostazioni!$B$26)-Impostazioni!$B$22)*Impostazioni!$B$19+MAX(0,MIN(MAX(G14,0),Impostazioni!$B$28)-Impostazioni!$B$26)*Impostazioni!$B$27)*Impostazioni!$B$21,0))) | I14: =MAX(0,G14-IF(ISNUMBER(Impostazioni!$B$12),Impostazioni!$B$12,H14))*Impostazioni!$B$18 | J14: =H14+I14 | K14: =J14-J13+Impostazioni!$B$25/12 | L14: =SUMIFS(Spese!$D$5:$D$204,Spese!$A$5:$A$204,">="&DATE('Parametri 2026'!$B$6,10,1),Spese!$A$5:$A$204,"<"&DATE('Parametri 2026'!$B$6,11,1)) | M14: =B14-K14-L14 | N14: =N13+M14
A15: Novembre | B15: =SUMIFS(Fatture!$M$5:$M$304,Fatture!$C$5:$C$304,">="&DATE('Parametri 2026'!$B$6,11,1),Fatture!$C$5:$C$304,"<"&DATE('Parametri 2026'!$B$6,12,1)) | C15: =COUNTIFS(Fatture!$C$5:$C$304,">="&DATE('Parametri 2026'!$B$6,11,1),Fatture!$C$5:$C$304,"<"&DATE('Parametri 2026'!$B$6,12,1),Fatture!$N$5:$N$304,"Incassata") | D15: =D14+B15 | E15: =D15/'Parametri 2026'!$B$7 | F15: =D15/'Parametri 2026'!$B$8 | G15: =D15*Impostazioni!$B$16 | H15: =Impostazioni!$B$25+IF(OR(Impostazioni!$B$17=1,Impostazioni!$B$17=2),MIN(MAX(G15,0),Impostazioni!$B$28)*Impostazioni!$B$19,IF(Impostazioni!$B$17=5,MAX(G15,0)*Impostazioni!$B$19,IF(OR(Impostazioni!$B$17=3,Impostazioni!$B$17=4),(MAX(0,MIN(MIN(MAX(G15,0),Impostazioni!$B$28),Impostazioni!$B$26)-Impostazioni!$B$22)*Impostazioni!$B$19+MAX(0,MIN(MAX(G15,0),Impostazioni!$B$28)-Impostazioni!$B$26)*Impostazioni!$B$27)*Impostazioni!$B$21,0))) | I15: =MAX(0,G15-IF(ISNUMBER(Impostazioni!$B$12),Impostazioni!$B$12,H15))*Impostazioni!$B$18 | J15: =H15+I15 | K15: =J15-J14+Impostazioni!$B$25/12 | L15: =SUMIFS(Spese!$D$5:$D$204,Spese!$A$5:$A$204,">="&DATE('Parametri 2026'!$B$6,11,1),Spese!$A$5:$A$204,"<"&DATE('Parametri 2026'!$B$6,12,1)) | M15: =B15-K15-L15 | N15: =N14+M15
A16: Dicembre | B16: =SUMIFS(Fatture!$M$5:$M$304,Fatture!$C$5:$C$304,">="&DATE('Parametri 2026'!$B$6,12,1),Fatture!$C$5:$C$304,"<"&DATE('Parametri 2026'!$B$6,13,1)) | C16: =COUNTIFS(Fatture!$C$5:$C$304,">="&DATE('Parametri 2026'!$B$6,12,1),Fatture!$C$5:$C$304,"<"&DATE('Parametri 2026'!$B$6,13,1),Fatture!$N$5:$N$304,"Incassata") | D16: =D15+B16 | E16: =D16/'Parametri 2026'!$B$7 | F16: =D16/'Parametri 2026'!$B$8 | G16: =D16*Impostazioni!$B$16 | H16: =Impostazioni!$B$25+IF(OR(Impostazioni!$B$17=1,Impostazioni!$B$17=2),MIN(MAX(G16,0),Impostazioni!$B$28)*Impostazioni!$B$19,IF(Impostazioni!$B$17=5,MAX(G16,0)*Impostazioni!$B$19,IF(OR(Impostazioni!$B$17=3,Impostazioni!$B$17=4),(MAX(0,MIN(MIN(MAX(G16,0),Impostazioni!$B$28),Impostazioni!$B$26)-Impostazioni!$B$22)*Impostazioni!$B$19+MAX(0,MIN(MAX(G16,0),Impostazioni!$B$28)-Impostazioni!$B$26)*Impostazioni!$B$27)*Impostazioni!$B$21,0))) | I16: =MAX(0,G16-IF(ISNUMBER(Impostazioni!$B$12),Impostazioni!$B$12,H16))*Impostazioni!$B$18 | J16: =H16+I16 | K16: =J16-J15+Impostazioni!$B$25/12 | L16: =SUMIFS(Spese!$D$5:$D$204,Spese!$A$5:$A$204,">="&DATE('Parametri 2026'!$B$6,12,1),Spese!$A$5:$A$204,"<"&DATE('Parametri 2026'!$B$6,13,1)) | M16: =B16-K16-L16 | N16: =N15+M16
A17: Totale | B17: =SUM(B5:B16) | C17: =SUM(C5:C16) | D17: =D16 | E17: =E16 | F17: =F16 | G17: =G16 | H17: =H16 | I17: =I16 | J17: =J16 | K17: =SUM(K5:K16) | L17: =SUM(L5:L16) | M17: =SUM(M5:M16) | N17: =N16
A19: Come leggere il riepilogo
A20: • Incassato: somma della colonna "Ricavo che conta" delle fatture con data di incasso nel mese.
A21: • Tasse e contributi da inizio anno: stessa formula della Dashboard applicata all'incassato fino a fine mese. A dicembre coincide con il totale dell'anno.
A22: • Da accantonare nel mese: quanto mettere da parte di quello che hai incassato nel mese. I contributi fissi di artigiani e commercianti sono divisi in 12 quote uguali.
A23: • Netto stimato: incassato meno quota da accantonare e spese del mese.

Sheet Dashboard
B1: =IF(Impostazioni!$B$5="","Dashboard 2026","Dashboard 2026 · "&Impostazioni!$B$5)
B2: =IF(Impostazioni!$B$16=0,"Scegli attività e previdenza in Impostazioni.","Coefficiente "&ROUND(Impostazioni!$B$16*100,0)&"% · "&Impostazioni!$B$7&" · imposta "&ROUND(Impostazioni!$B$18*100,0)&"%")
O3: Dati per i grafici
B4: Incassato nel 2026 | E4: Tasse e contributi stimati | H4: Netto stimato | K4: Soglia di 85.000 € | O4: Mese | P4: Incassato | Q4: Da accantonare | R4: Da inizio anno | S4: Soglia 85.000 €
B5: ='Riepilogo mensile'!$B$17 | E5: ='Riepilogo mensile'!$J$16 | H5: ='Riepilogo mensile'!$B$17-'Riepilogo mensile'!$J$16 | K5: ='Riepilogo mensile'!$B$17/'Parametri 2026'!$B$7 | O5: Gen | P5: ='Riepilogo mensile'!B5 | Q5: ='Riepilogo mensile'!K5 | R5: ='Riepilogo mensile'!D5 | S5: ='Parametri 2026'!$B$7
B6: ='Riepilogo mensile'!$C$17&" fatture incassate" | E6: =IF('Riepilogo mensile'!$B$17>0,"il "&FIXED('Riepilogo mensile'!$J$16/'Riepilogo mensile'!$B$17*100,1)&"% di quanto incassi","") | H6: ="circa "&FIXED(('Riepilogo mensile'!$B$17-'Riepilogo mensile'!$J$16)/12,0)&" € al mese" | K6: =IF('Riepilogo mensile'!$B$17>'Parametri 2026'!$B$7,"soglia superata","mancano "&FIXED('Parametri 2026'!$B$7-'Riepilogo mensile'!$B$17,0)&" €") | O6: Feb | P6: ='Riepilogo mensile'!B6 | Q6: ='Riepilogo mensile'!K6 | R6: ='Riepilogo mensile'!D6 | S6: ='Parametri 2026'!$B$7
O7: Mar | P7: ='Riepilogo mensile'!B7 | Q7: ='Riepilogo mensile'!K7 | R7: ='Riepilogo mensile'!D7 | S7: ='Parametri 2026'!$B$7
B8: =IF('Riepilogo mensile'!$B$17>'Parametri 2026'!$B$8,"Oltre 100.000 € di ricavi esci dal forfettario già quest'anno: l'IVA si applica dall'operazione che fa superare la soglia e il reddito dell'intero anno si tassa con IRPEF ordinaria e costi reali. Imposta e contributi di questo file sono solo indicativi: l'imposta sostitutiva non è dovuta.",IF('Riepilogo mensile'!$B$17>'Parametri 2026'!$B$7,"Oltre 85.000 € di ricavi resti forfettario per quest'anno, ma dal prossimo passi al regime ordinario.","Sotto 85.000 € di ricavi: nessun limite superato.")) | O8: Apr | P8: ='Riepilogo mensile'!B8 | Q8: ='Riepilogo mensile'!K8 | R8: ='Riepilogo mensile'!D8 | S8: ='Parametri 2026'!$B$7
O9: Mag | P9: ='Riepilogo mensile'!B9 | Q9: ='Riepilogo mensile'!K9 | R9: ='Riepilogo mensile'!D9 | S9: ='Parametri 2026'!$B$7
B10: Dettaglio del calcolo (stessa logica del calcolatore NettoChiaro) | I10: Soglie del regime | O10: Giu | P10: ='Riepilogo mensile'!B10 | Q10: ='Riepilogo mensile'!K10 | R10: ='Riepilogo mensile'!D10 | S10: ='Parametri 2026'!$B$7
B11: Incassato nell'anno (per data di incasso) | F11: ='Riepilogo mensile'!$B$17 | I11: Verso 85.000 € | L11: ='Riepilogo mensile'!$B$17/'Parametri 2026'!$B$7 | O11: Lug | P11: ='Riepilogo mensile'!B11 | Q11: ='Riepilogo mensile'!K11 | R11: ='Riepilogo mensile'!D11 | S11: ='Parametri 2026'!$B$7
B12: Coefficiente di redditività | F12: =Impostazioni!$B$16 | I12: =REPT("█",ROUND(MIN(1,MAX(0,'Riepilogo mensile'!$B$17/'Parametri 2026'!$B$7))*24,0))&REPT("░",24-ROUND(MIN(1,MAX(0,'Riepilogo mensile'!$B$17/'Parametri 2026'!$B$7))*24,0)) | O12: Ago | P12: ='Riepilogo mensile'!B12 | Q12: ='Riepilogo mensile'!K12 | R12: ='Riepilogo mensile'!D12 | S12: ='Parametri 2026'!$B$7
B13: Reddito imponibile lordo | F13: ='Riepilogo mensile'!$G$16 | I13: Mancano a 85.000 € | L13: =MAX(0,'Parametri 2026'!$B$7-'Riepilogo mensile'!$B$17) | O13: Set | P13: ='Riepilogo mensile'!B13 | Q13: ='Riepilogo mensile'!K13 | R13: ='Riepilogo mensile'!D13 | S13: ='Parametri 2026'!$B$7
B14: Contributi fissi (artigiani e commercianti) | F14: =Impostazioni!$B$25 | I14: Verso 100.000 € | L14: ='Riepilogo mensile'!$B$17/'Parametri 2026'!$B$8 | O14: Ott | P14: ='Riepilogo mensile'!B14 | Q14: ='Riepilogo mensile'!K14 | R14: ='Riepilogo mensile'!D14 | S14: ='Parametri 2026'!$B$7
B15: Contributi a percentuale | F15: ='Riepilogo mensile'!$H$16-Impostazioni!$B$25 | I15: =REPT("█",ROUND(MIN(1,MAX(0,'Riepilogo mensile'!$B$17/'Parametri 2026'!$B$8))*24,0))&REPT("░",24-ROUND(MIN(1,MAX(0,'Riepilogo mensile'!$B$17/'Parametri 2026'!$B$8))*24,0)) | O15: Nov | P15: ='Riepilogo mensile'!B15 | Q15: ='Riepilogo mensile'!K15 | R15: ='Riepilogo mensile'!D15 | S15: ='Parametri 2026'!$B$7
B16: Contributi previdenziali totali | F16: ='Riepilogo mensile'!$H$16 | I16: Mancano a 100.000 € | L16: =MAX(0,'Parametri 2026'!$B$8-'Riepilogo mensile'!$B$17) | O16: Dic | P16: ='Riepilogo mensile'!B16 | Q16: ='Riepilogo mensile'!K16 | R16: ='Riepilogo mensile'!D16 | S16: ='Parametri 2026'!$B$7
B17: Contributi dedotti dal reddito | F17: =IF(ISNUMBER(Impostazioni!$B$12),Impostazioni!$B$12,'Riepilogo mensile'!$H$16)
B18: Reddito su cui si paga l'imposta | F18: =MAX(0,'Riepilogo mensile'!$G$16-IF(ISNUMBER(Impostazioni!$B$12),Impostazioni!$B$12,'Riepilogo mensile'!$H$16)) | I18: Fatture 2026
B19: Aliquota dell'imposta sostitutiva | F19: =Impostazioni!$B$18 | I19: Emesse nel 2026 | L19: =COUNTIFS(Fatture!$B$5:$B$304,">="&DATE('Parametri 2026'!$B$6,1,1),Fatture!$B$5:$B$304,"<"&DATE('Parametri 2026'!$B$6+1,1,1),Fatture!$F$5:$F$304,"<>")
B20: Imposta sostitutiva stimata | F20: ='Riepilogo mensile'!$I$16 | I20: Totale emesso nel 2026 | L20: =SUMIFS(Fatture!$L$5:$L$304,Fatture!$B$5:$B$304,">="&DATE('Parametri 2026'!$B$6,1,1),Fatture!$B$5:$B$304,"<"&DATE('Parametri 2026'!$B$6+1,1,1))
B21: Totale tasse e contributi | F21: ='Riepilogo mensile'!$J$16 | I21: Incassate nel 2026 | L21: ='Riepilogo mensile'!$C$17
B22: Incidenza sull'incassato | F22: =IF('Riepilogo mensile'!$B$17>0,'Riepilogo mensile'!$J$16/'Riepilogo mensile'!$B$17,0) | I22: Da incassare (numero) | L22: =COUNTIF(Fatture!$N$5:$N$304,"Da incassare")
B23: Netto stimato (incassato − tasse e contributi) | F23: ='Riepilogo mensile'!$B$17-'Riepilogo mensile'!$J$16 | I23: Da incassare (totale) | L23: =SUMIFS(Fatture!$L$5:$L$304,Fatture!$N$5:$N$304,"Da incassare")
B24: Spese registrate (facoltative) | F24: ='Riepilogo mensile'!$L$17 | I24: Bollo sulle fatture emesse nel 2026 | L24: =SUMIFS(Fatture!$J$5:$J$304,Fatture!$B$5:$B$304,">="&DATE('Parametri 2026'!$B$6,1,1),Fatture!$B$5:$B$304,"<"&DATE('Parametri 2026'!$B$6+1,1,1))
B25: Netto dopo le spese | F25: ='Riepilogo mensile'!$B$17-'Riepilogo mensile'!$J$16-'Riepilogo mensile'!$L$17
B26: Netto medio mensile dopo le spese | F26: =('Riepilogo mensile'!$B$17-'Riepilogo mensile'!$J$16-'Riepilogo mensile'!$L$17)/12
B27: =IF(NOT(ISNUMBER(Impostazioni!$B$12)),"Contributi dedotti: stima a regime (i contributi calcolati sull'anno). Se conosci quelli versati nel 2026, inseriscili in Impostazioni.","Contributi dedotti: quelli versati nel 2026 indicati in Impostazioni.")
B30: Controlli
B31: =IF(SUMPRODUCT((LEN($U$31:$U$42)>0)*1)=0,"Nessun problema rilevato.",U31&IF(U31="","",CHAR(10))&U32&IF(U32="","",CHAR(10))&U33&IF(U33="","",CHAR(10))&U34&IF(U34="","",CHAR(10))&U35&IF(U35="","",CHAR(10))&U36&IF(U36="","",CHAR(10))&U37&IF(U37="","",CHAR(10))&U38&IF(U38="","",CHAR(10))&U39&IF(U39="","",CHAR(10))&U40&IF(U40="","",CHAR(10))&U41&IF(U41="","",CHAR(10))&U42&IF(U42="","",CHAR(10))) | U31: =IF(Impostazioni!$B$6="","Scegli l'attività in Impostazioni: senza coefficiente il reddito risulta zero.","")
U32: =IF(Impostazioni!$B$17=0,"Scegli la previdenza in Impostazioni: senza, i contributi risultano zero.","")
U33: =IF(AND(Impostazioni!$B$17=5,Impostazioni!$B$19=0),"Hai scelto una cassa professionale: inserisci la sua aliquota in Impostazioni.","")
U34: =IF(AND(Impostazioni!$B$10="Sì",Impostazioni!$B$17<>3,Impostazioni!$B$17<>4),"La riduzione del 35% vale solo per artigiani e commercianti: qui non è applicata.","")
U35: =IF(AND(Impostazioni!$B$17>2,COUNTIF(Fatture!$G$5:$G$304,"Sì")+COUNTIF(Fatture!$G$5:$G$304,"Si")>0),"Fatture con rivalsa INPS 4%: "&(COUNTIF(Fatture!$G$5:$G$304,"Sì")+COUNTIF(Fatture!$G$5:$G$304,"Si"))&". La rivalsa spetta solo agli iscritti alla Gestione Separata.","")
U36: =IF(COUNTIF(Fatture!$N$5:$N$304,"Compenso non valido")>0,"Fatture con il compenso scritto come testo: "&COUNTIF(Fatture!$N$5:$N$304,"Compenso non valido")&". Scrivi solo il numero (es. 1500,50): finché non lo correggi la riga non entra nei calcoli.","")
U37: =IF(SUMPRODUCT((Fatture!$B$5:$B$304<>"")*(1-ISNUMBER(Fatture!$B$5:$B$304)))+SUMPRODUCT((Fatture!$C$5:$C$304<>"")*(1-ISNUMBER(Fatture!$C$5:$C$304)))>0,"Date delle fatture scritte come testo: "&(SUMPRODUCT((Fatture!$B$5:$B$304<>"")*(1-ISNUMBER(Fatture!$B$5:$B$304)))+SUMPRODUCT((Fatture!$C$5:$C$304<>"")*(1-ISNUMBER(Fatture!$C$5:$C$304))))&". Scrivile come gg/mm/aaaa: un incasso con la data non valida non entra nei calcoli.","")
U38: =IF(SUMPRODUCT(ISNUMBER(Fatture!$C$5:$C$304)*ISNUMBER(Fatture!$B$5:$B$304)*(Fatture!$C$5:$C$304<Fatture!$B$5:$B$304))>0,"Fatture con la data di incasso prima di quella di emissione: "&SUMPRODUCT(ISNUMBER(Fatture!$C$5:$C$304)*ISNUMBER(Fatture!$B$5:$B$304)*(Fatture!$C$5:$C$304<Fatture!$B$5:$B$304))&". Controlla le date.","")
U39: =IF(COUNTIF(Fatture!$N$5:$N$304,"Incassata nel *")>0,"Fatture incassate in un altro anno, che non contano nel 2026: "&COUNTIF(Fatture!$N$5:$N$304,"Incassata nel *")&".","")
B40: Grafici | U40: =IF(SUMPRODUCT((Spese!$D$5:$D$204<>"")*(1-ISNUMBER(Spese!$D$5:$D$204)*ISNUMBER(Spese!$A$5:$A$204)))>0,"Spese senza una data valida o con l'importo scritto come testo: "&SUMPRODUCT((Spese!$D$5:$D$204<>"")*(1-ISNUMBER(Spese!$D$5:$D$204)*ISNUMBER(Spese!$A$5:$A$204)))&". Non entrano nel totale delle spese.","")
U41: =IF(OR(AND(Impostazioni!$B$12<>"",NOT(ISNUMBER(Impostazioni!$B$12))),AND(Impostazioni!$B$13<>"",NOT(ISNUMBER(Impostazioni!$B$13))),AND(Impostazioni!$B$8<>"",NOT(ISNUMBER(Impostazioni!$B$8)))),"In Impostazioni un importo o l'aliquota della cassa è scritto come testo: scrivi solo il numero, altrimenti il foglio lo ignora.","")
U42: =IF(AND(OR(Impostazioni!$B$17=3,Impostazioni!$B$17=4),'Riepilogo mensile'!$B$17>0,'Riepilogo mensile'!$G$16<Impostazioni!$B$22),"Il reddito è sotto il minimale INPS: i contributi fissi sono dovuti comunque"&IF(Impostazioni!$B$20="Sì"," (ridotti del 35%)."," per intero."),"")

Sheet Scadenze
A1: Scadenze 2026-2027
A2: Versamenti legati all'anno 2026. Se una scadenza cade di sabato o festivo slitta al primo giorno lavorativo: le date qui sotto sono già spostate. Le proroghe vengono decise di anno in anno: controlla prima di pagare.
A4: Data | B4: Versamento | C4: Chi lo paga | D4: Codice F24 | E4: Importo stimato (€) | F4: Note | G4: Stato | H4: Fatto
A5: 46160 | B5: Contributi INPS fissi 2026: 1ª rata | C5: Artigiani e commercianti | D5: Sezione INPS | E5: =IF(OR(Impostazioni!$B$17=3,Impostazioni!$B$17=4),ROUND(Impostazioni!$B$25/4,2),"Non dovuto") | F5: Il 16 maggio 2026 era sabato. Gli importi esatti sono nel Cassetto previdenziale INPS. | G5: =IF(H5="Sì","Fatto",IF(A5<TODAY(),"Passata",IF(A5-TODAY()<=30,"Entro 30 giorni","")))
A6: 46174 | B6: Bollo fatture elettroniche, 1° trimestre 2026 | C6: Tutti | D6: 2521 | E6: =IF($B$24>'Parametri 2026'!$B$15,$B$24,0) | F6: Il 31 maggio 2026 era domenica. Fino a 5.000 € il versamento si può rinviare alla scadenza del trimestre successivo (importo già spostato qui). | G6: =IF(H6="Sì","Fatto",IF(A6<TODAY(),"Passata",IF(A6-TODAY()<=30,"Entro 30 giorni","")))
A7: 46223 | B7: Imposta sostitutiva: saldo 2025 e 1° acconto 2026 | C7: Tutti | D7: 1792 saldo, 1790 acconto | E7: Dalla dichiarazione | F7: Termine ordinario 30 giugno, prorogato al 20 luglio dal DL 89/2026 (art. 6) per forfettari e soggetti ISA. Fino al 20 agosto con la maggiorazione dello 0,80%. Acconto: 50% + 50%. | G7: =IF(H7="Sì","Fatto",IF(A7<TODAY(),"Passata",IF(A7-TODAY()<=30,"Entro 30 giorni","")))
