Workbook

Sheet Start Here
B1: 2026 Budget Planner
B2: Plan your money month by month, log every transaction and see your whole year at a glance.
B5: Start in 6 steps
B6: 1. Settings: check the year and choose your currency symbol ($, £, € ...). It appears in the column headings.
B7: 2. Categories: rename, delete or add categories (up to 60). Give each one a type: Income, Fixed bills, Variable expenses or Savings & debt.
B8: 3. Monthly Budget: type a typical monthly amount for each category. All 12 months fill in by themselves; type over a single month for costs that do not repeat every month (annual insurance, holiday gifts).
B9: 4. Transactions: log every payment and every income with date, description, category (from the drop-down list) and amount. Use positive amounts; for a refund, type a negative amount in the same category.
B10: 5. Monthly Summary and Annual Dashboard: nothing to type, they update by themselves. Pick the month to review at the top of Monthly Summary.
B11: 6. Optional: track your Savings Goals, Sinking Funds and Debt Payoff plan.
B13: Color key
B14: Yellow cells: your inputs. Type over them freely.
B15: White cells: formulas. The sheets are protected so you do not delete them by mistake.
... B37: Sheets in this file
B38: Settings | C38: Year, currency symbol, plan name, accounts and the date used for "months left".
B39: Categories | C39: Your categories and their types.
B40: Transactions | C40: One log for the whole year: 2,000 rows with drop-down lists and automatic checks.
B41: Monthly Budget | C41: Planned amounts per category and month, and "Left to budget".
B42: Monthly Summary | C42: Actual vs planned for the month you choose and the year to date, plus actuals for every month.
B43: Annual Dashboard | C43: Income, expenses, savings rate, top spending categories and charts.
B44: Savings Goals | C44: Targets, progress and how much to save each month.
B45: Sinking Funds | C45: Money set aside for irregular costs: balance, amount still needed, monthly amount.
B46: Debt Payoff | C46: Snowball or avalanche order, debt-free date and interest saved.
B47: Debt Schedule | C47: Month-by-month balances behind Debt Payoff (calculated, nothing to type).
B49: This planner is a personal organization tool. It is not financial, tax or legal advice.
B50: Made by NettoChiaro · version 2026.1 · Questions? Send us a message on Etsy.

Sheet Settings
B1: Settings
B2: Set these once. Yellow cells are inputs.
B3: Setting | C3: Your value | D3: Notes
B4: Budget year | C4: 2026 | D4: The calendar year of this planner. Transactions from other years are flagged.
B5: Currency symbol | C5: $ | D5: Shown in the column headings, for example "Amount ($)". Pick one from the list or type your own.
B6: Plan name (optional) | C6: Alex & Sam (sample data) | D6: Shown on the dashboard, for example "Smith household".
B7: As-of date (optional) | C7: 46387 | D7: Leave empty to use today's date. Used for "months left" and payoff dates.
B9: Values used by the formulas (calculated)
B10: Month to review | C10: ='Monthly Summary'!$B$3 | D10: Chosen at the top of Monthly Summary. Auto = the latest month.
B11: As-of date used | C11: =IF(ISNUMBER(C7),C7,TODAY())
B12: Month used (number) | C12: =IFERROR(MATCH('Monthly Summary'!$B$3,Lists!$A$2:$A$13,0),IF(YEAR(C11)<C4,1,IF(YEAR(C11)>C4,12,MONTH(C11)))) | D12: Auto: the month of the as-of date; December for a past year, January for a future year.
B13: Month used (name) | C13: =INDEX(Lists!$A$2:$A$13,C12)
B14: Currency in headings | C14: =IF(TRIM(C5)="",""," ("&TRIM(C5)&")")
B15: Month used (short) | C15: =LEFT(C13,3)
B17: Accounts and payment methods (drop-down in Transactions)
B18: Checking | C18: Optional. Rename or add up to 8.
B19: Savings
B20: Credit card
B21: Debit card
B22: Cash

Sheet Categories
A1: Categories
A2: Up to 60 categories. Each one needs a type. Changes show up everywhere, including the drop-down list in Transactions.
A3: Types: Income · Fixed bills (same amount every month) · Variable expenses · Savings & debt (savings, investing and debt payments). Avoid the characters * ? ~ in names.
A5: Category | B5: Type | C5: Notes | D5: Check
A6: Paycheck 1 | B6: Income | C6: Take-home pay after tax. Rename it, for example "Alex pay". | D6: =IF(A6="",IF(B6="","","Name missing"),IF(B6="","Choose a type",IF(COUNTIF($A$6:$A$65,A6)>1,"Name used twice",IF(ISNA(MATCH(B6,Lists!$D$2:$D$5,0)),"Unknown type",""))))
A7: Paycheck 2 | B7: Income | C7: Second earner, if any. | D7: =IF(A7="",IF(B7="","","Name missing"),IF(B7="","Choose a type",IF(COUNTIF($A$6:$A$65,A7)>1,"Name used twice",IF(ISNA(MATCH(B7,Lists!$D$2:$D$5,0)),"Unknown type",""))))
A8: Side income | B8: Income | C8: Freelance work, selling things, tips. | D8: =IF(A8="",IF(B8="","","Name missing"),IF(B8="","Choose a type",IF(COUNTIF($A$6:$A$65,A8)>1,"Name used twice",IF(ISNA(MATCH(B8,Lists!$D$2:$D$5,0)),"Unknown type",""))))
A9: Other income | B9: Income | C9: Tax refunds, gifts, interest, benefits. | D9: =IF(A9="",IF(B9="","","Name missing"),IF(B9="","Choose a type",IF(COUNTIF($A$6:$A$65,A9)>1,"Name used twice",IF(ISNA(MATCH(B9,Lists!$D$2:$D$5,0)),"Unknown type",""))))
A10: Rent / Mortgage | B10: Fixed bills | D10: =IF(A10="",IF(B10="","","Name missing"),IF(B10="","Choose a type",IF(COUNTIF($A$6:$A$65,A10)>1,"Name used twice",IF(ISNA(MATCH(B10,Lists!$D$2:$D$5,0)),"Unknown type",""))))
A11: Utilities | B11: Fixed bills | C11: Electricity, gas, water, trash. | D11: =IF(A11="",IF(B11="","","Name missing"),IF(B11="","Choose a type",IF(COUNTIF($A$6:$A$65,A11)>1,"Name used twice",IF(ISNA(MATCH(B11,Lists!$D$2:$D$5,0)),"Unknown type",""))))
A12: Internet & Phone | B12: Fixed bills | D12: =IF(A12="",IF(B12="","","Name missing"),IF(B12="","Choose a type",IF(COUNTIF($A$6:$A$65,A12)>1,"Name used twice",IF(ISNA(MATCH(B12,Lists!$D$2:$D$5,0)),"Unknown type",""))))
A13: Insurance | B13: Fixed bills | C13: Car, home or renters, life, health. | D13: =IF(A13="",IF(B13="","","Name missing"),IF(B13="","Choose a type",IF(COUNTIF($A$6:$A$65,A13)>1,"Name used twice",IF(ISNA(MATCH(B13,Lists!$D$2:$D$5,0)),"Unknown type",""))))
A14: Subscriptions | B14: Fixed bills | C14: Streaming, apps, gym, memberships. | D14: =IF(A14="",IF(B14="","","Name missing"),IF(B14="","Choose a type",IF(COUNTIF($A$6:$A$65,A14)>1,"Name used twice",IF(ISNA(MATCH(B14,Lists!$D$2:$D$5,0)),"Unknown type",""))))
A15: Car payment | B15: Fixed bills | C15: Car loan or lease. | D15: =IF(A15="",IF(B15="","","Name missing"),IF(B15="","Choose a type",IF(COUNTIF($A$6:$A$65,A15)>1,"Name used twice",IF(ISNA(MATCH(B15,Lists!$D$2:$D$5,0)),"Unknown type",""))))
A16: Groceries | B16: Variable expenses | C16: Food and household supplies. | D16: =IF(A16="",IF(B16="","","Name missing"),IF(B16="","Choose a type",IF(COUNTIF($A$6:$A$65,A16)>1,"Name used twice",IF(ISNA(MATCH(B16,Lists!$D$2:$D$5,0)),"Unknown type",""))))
A17: Dining out | B17: Variable expenses | C17: Restaurants, takeout, coffee. | D17: =IF(A17="",IF(B17="","","Name missing"),IF(B17="","Choose a type",IF(COUNTIF($A$6:$A$65,A17)>1,"Name used twice",IF(ISNA(MATCH(B17,Lists!$D$2:$D$5,0)),"Unknown type",""))))
A18: Transport / Gas | B18: Variable expenses | C18: Fuel, public transport, parking, tolls, car repairs. | D18: =IF(A18="",IF(B18="","","Name missing"),IF(B18="","Choose a type",IF(COUNTIF($A$6:$A$65,A18)>1,"Name used twice",IF(ISNA(MATCH(B18,Lists!$D$2:$D$5,0)),"Unknown type",""))))
A19: Health | B19: Variable expenses | C19: Pharmacy, doctor and dentist visits, copays. | D19: =IF(A19="",IF(B19="","","Name missing"),IF(B19="","Choose a type",IF(COUNTIF($A$6:$A$65,A19)>1,"Name used twice",IF(ISNA(MATCH(B19,Lists!$D$2:$D$5,0)),"Unknown type",""))))
A20: Kids | B20: Variable expenses | C20: Childcare, school, activities, clothes. | D20: =IF(A20="",IF(B20="","","Name missing"),IF(B20="","Choose a type",IF(COUNTIF($A$6:$A$65,A20)>1,"Name used twice",IF(ISNA(MATCH(B20,Lists!$D$2:$D$5,0)),"Unknown type",""))))
A21: Personal care | B21: Variable expenses | C21: Haircuts, toiletries, cosmetics. | D21: =IF(A21="",IF(B21="","","Name missing"),IF(B21="","Choose a type",IF(COUNTIF($A$6:$A$65,A21)>1,"Name used twice",IF(ISNA(MATCH(B21,Lists!$D$2:$D$5,0)),"Unknown type",""))))
A22: Entertainment | B22: Variable expenses | C22: Movies, events, hobbies, games. | D22: =IF(A22="",IF(B22="","","Name missing"),IF(B22="","Choose a type",IF(COUNTIF($A$6:$A$65,A22)>1,"Name used twice",IF(ISNA(MATCH(B22,Lists!$D$2:$D$5,0)),"Unknown type",""))))
A23: Gifts | B23: Variable expenses | C23: Birthdays, holidays, donations. | D23: =IF(A23="",IF(B23="","","Name missing"),IF(B23="","Choose a type",IF(COUNTIF($A$6:$A$65,A23)>1,"Name used twice",IF(ISNA(MATCH(B23,Lists!$D$2:$D$5,0)),"Unknown type",""))))
A24: Travel | B24: Variable expenses | C24: Trips and vacations. | D24: =IF(A24="",IF(B24="","","Name missing"),IF(B24="","Choose a type",IF(COUNTIF($A$6:$A$65,A24)>1,"Name used twice",IF(ISNA(MATCH(B24,Lists!$D$2:$D$5,0)),"Unknown type",""))))
A25: Clothing | B25: Variable expenses | D25: =IF(A25="",IF(B25="","","Name missing"),IF(B25="","Choose a type",IF(COUNTIF($A$6:$A$65,A25)>1,"Name used twice",IF(ISNA(MATCH(B25,Lists!$D$2:$D$5,0)),"Unknown type",""))))
A26: Home & repairs | B26: Variable expenses | C26: Furniture, tools, repairs, appliances. | D26: =IF(A26="",IF(B26="","","Name missing"),IF(B26="","Choose a type",IF(COUNTIF($A$6:$A$65,A26)>1,"Name used twice",IF(ISNA(MATCH(B26,Lists!$D$2:$D$5,0)),"Unknown type",""))))
A27: Pets | B27: Variable expenses | C27: Food, vet, grooming. | D27: =IF(A27="",IF(B27="","","Name missing"),IF(B27="","Choose a type",IF(COUNTIF($A$6:$A$65,A27)>1,"Name used twice",IF(ISNA(MATCH(B27,Lists!$D$2:$D$5,0)),"Unknown type",""))))
A28: Misc | B28: Variable expenses | C28: Anything that does not fit elsewhere. | D28: =IF(A28="",IF(B28="","","Name missing"),IF(B28="","Choose a type",IF(COUNTIF($A$6:$A$65,A28)>1,"Name used twice",IF(ISNA(MATCH(B28,Lists!$D$2:$D$5,0)),"Unknown type",""))))
A29: Emergency fund | B29: Savings & debt | C29: Money moved to your emergency savings. | D29: =IF(A29="",IF(B29="","","Name missing"),IF(B29="","Choose a type",IF(COUNTIF($A$6:$A$65,A29)>1,"Name used twice",IF(ISNA(MATCH(B29,Lists!$D$2:$D$5,0)),"Unknown type",""))))
A30: Savings goals | B30: Savings & debt | C30: Money moved to the goals in Savings Goals. | D30: =IF(A30="",IF(B30="","","Name missing"),IF(B30="","Choose a type",IF(COUNTIF($A$6:$A$65,A30)>1,"Name used twice",IF(ISNA(MATCH(B30,Lists!$D$2:$D$5,0)),"Unknown type",""))))
A31: Sinking funds | B31: Savings & debt | C31: Money set aside for the funds in Sinking Funds. | D31: =IF(A31="",IF(B31="","","Name missing"),IF(B31="","Choose a type",IF(COUNTIF($A$6:$A$65,A31)>1,"Name used twice",IF(ISNA(MATCH(B31,Lists!$D$2:$D$5,0)),"Unknown type",""))))
A32: Retirement & investing | B32: Savings & debt | C32: Pension or retirement account, investments. | D32: =IF(A32="",IF(B32="","","Name missing"),IF(B32="","Choose a type",IF(COUNTIF($A$6:$A$65,A32)>1,"Name used twice",IF(ISNA(MATCH(B32,Lists!$D$2:$D$5,0)),"Unknown type",""))))
A33: Debt payments | B33: Savings & debt | C33: Credit cards, student and personal loans (see Debt Payoff). | D33: =IF(A33="",IF(B33="","","Name missing"),IF(B33="","Choose a type",IF(COUNTIF($A$6:$A$65,A33)>1,"Name used twice",IF(ISNA(MATCH(B33,Lists!$D$2:$D$5,0)),"Unknown type",""))))
D34: =IF(A34="",IF(B34="","","Name missing"),IF(B34="","Choose a type",IF(COUNTIF($A$6:$A$65,A34)>1,"Name used twice",IF(ISNA(MATCH(B34,Lists!$D$2:$D$5,0)),"Unknown type",""))))
D35: =IF(A35="",IF(B35="","","Name missing"),IF(B35="","Choose a type",IF(COUNTIF($A$6:$A$65,A35)>1,"Name used twice",IF(ISNA(MATCH(B35,Lists!$D$2:$D$5,0)),"Unknown type",""))))
D36: =IF(A36="",IF(B36="","","Name missing"),IF(B36="","Choose a type",IF(COUNTIF($A$6:$A$65,A36)>1,"Name used twice",IF(ISNA(MATCH(B36,Lists!$D$2:$D$5,0)),"Unknown type",""))))
D37: =IF(A37="",IF(B37="","","Name missing"),IF(B37="","Choose a type",IF(COUNTIF($A$6:$A$65,A37)>1,"Name used twice",IF(ISNA(MATCH(B37,Lists!$D$2:$D$5,0)),"Unknown type",""))))
D38: =IF(A38="",IF(B38="","","Name missing"),IF(B38="","Choose a type",IF(COUNTIF($A$6:$A$65,A38)>1,"Name used twice",IF(ISNA(MATCH(B38,Lists!$D$2:$D$5,0)),"Unknown type",""))))
D39: =IF(A39="",IF(B39="","","Name missing"),IF(B39="","Choose a type",IF(COUNTIF($A$6:$A$65,A39)>1,"Name used twice",IF(ISNA(MATCH(B39,Lists!$D$2:$D$5,0)),"Unknown type",""))))
D40: =IF(A40="",IF(B40="","","Name missing"),IF(B40="","Choose a type",IF(COUNTIF($A$6:$A$65,A40)>1,"Name used twice",IF(ISNA(MATCH(B40,Lists!$D$2:$D$5,0)),"Unknown type",""))))
D41: =IF(A41="",IF(B41="","","Name missing"),IF(B41="","Choose a type",IF(COUNTIF($A$6:$A$65,A41)>1,"Name used twice",IF(ISNA(MATCH(B41,Lists!$D$2:$D$5,0)),"Unknown type",""))))
...

Sheet Transactions
A1: Transactions
A2: One row per payment or income. Dates as year-month-day (2026-03-15). Positive amounts; a refund is a negative amount in the same category.
A3: ="Rows used: "&COUNT(D6:D2005)&" of 2,000 · Total income "&Settings!$C$4&": "&FIXED(SUMIFS(D6:D2005,H6:H2005,"Income",A6:A2005,">="&DATE(Settings!$C$4,1,1),A6:A2005,"<"&DATE(Settings!$C$4+1,1,1)),2)&" · Total expenses "&Settings!$C$4&": "&FIXED(SUMIFS(D6:D2005,H6:H2005,"Fixed bills",A6:A2005,">="&DATE(Settings!$C$4,1,1),A6:A2005,"<"&DATE(Settings!$C$4+1,1,1))+SUMIFS(D6:D2005,H6:H2005,"Variable expenses",A6:A2005,">="&DATE(Settings!$C$4,1,1),A6:A2005,"<"&DATE(Settings!$C$4+1,1,1)),2)
A5: Date | B5: Description | C5: Category | D5: ="Amount"&Settings!$C$14 | E5: Account | F5: Goal / fund (optional) | G5: Notes | H5: Type | I5: Check
A6: 46023 | B6: Alex paycheck | C6: Paycheck 1 | D6: 2100 | E6: Checking | H6: =IF(C6="","",IFERROR(INDEX(Categories!$B$6:$B$65,MATCH(C6,Categories!$A$6:$A$65,0))&"","")) | I6: =IF(AND(A6="",C6="",D6=""),"",IF(A6="","Date missing",IF(NOT(ISNUMBER(A6)),"Date not recognized",IF(YEAR(A6)<>Settings!$C$4,"Not in "&Settings!$C$4,IF(C6="","Category missing",IF(H6="",IF(COUNTIF(Categories!$A$6:$A$65,C6)>0,"Category has no type","Category not in list"),IF(D6="","Amount missing",IF(NOT(ISNUMBER(D6)),"Amount is not a number",IF(F6="","",IF(ISNA(MATCH(F6,Lists!$G$2:$G$25,0)),"Goal / fund not in list",IF(H6="Income","Fund tag ignored on income","")))))))))))
A7: 46023 | B7: Rent | C7: Rent / Mortgage | D7: 1850 | E7: Checking | H7: =IF(C7="","",IFERROR(INDEX(Categories!$B$6:$B$65,MATCH(C7,Categories!$A$6:$A$65,0))&"","")) | I7: =IF(AND(A7="",C7="",D7=""),"",IF(A7="","Date missing",IF(NOT(ISNUMBER(A7)),"Date not recognized",IF(YEAR(A7)<>Settings!$C$4,"Not in "&Settings!$C$4,IF(C7="","Category missing",IF(H7="",IF(COUNTIF(Categories!$A$6:$A$65,C7)>0,"Category has no type","Category not in list"),IF(D7="","Amount missing",IF(NOT(ISNUMBER(D7)),"Amount is not a number",IF(F7="","",IF(ISNA(MATCH(F7,Lists!$G$2:$G$25,0)),"Goal / fund not in list",IF(H7="Income","Fund tag ignored on income","")))))))))))
A8: 46023 | B8: Dentist copay | C8: Health | D8: 53.73 | E8: Debit card | H8: =IF(C8="","",IFERROR(INDEX(Categories!$B$6:$B$65,MATCH(C8,Categories!$A$6:$A$65,0))&"","")) | I8: =IF(AND(A8="",C8="",D8=""),"",IF(A8="","Date missing",IF(NOT(ISNUMBER(A8)),"Date not recognized",IF(YEAR(A8)<>Settings!$C$4,"Not in "&Settings!$C$4,IF(C8="","Category missing",IF(H8="",IF(COUNTIF(Categories!$A$6:$A$65,C8)>0,"Category has no type","Category not in list"),IF(D8="","Amount missing",IF(NOT(ISNUMBER(D8)),"Amount is not a number",IF(F8="","",IF(ISNA(MATCH(F8,Lists!$G$2:$G$25,0)),"Goal / fund not in list",IF(H8="Income","Fund tag ignored on income","")))))))))))
A9: 46023 | B9: After-school program | C9: Kids | D9: 320 | E9: Checking | H9: =IF(C9="","",IFERROR(INDEX(Categories!$B$6:$B$65,MATCH(C9,Categories!$A$6:$A$65,0))&"","")) | I9: =IF(AND(A9="",C9="",D9=""),"",IF(A9="","Date missing",IF(NOT(ISNUMBER(A9)),"Date not recognized",IF(YEAR(A9)<>Settings!$C$4,"Not in "&Settings!$C$4,IF(C9="","Category missing",IF(H9="",IF(COUNTIF(Categories!$A$6:$A$65,C9)>0,"Category has no type","Category not in list"),IF(D9="","Amount missing",IF(NOT(ISNUMBER(D9)),"Amount is not a number",IF(F9="","",IF(ISNA(MATCH(F9,Lists!$G$2:$G$25,0)),"Goal / fund not in list",IF(H9="Income","Fund tag ignored on income","")))))))))))
A10: 46024 | B10: Gym membership | C10: Subscriptions | D10: 45 | E10: Checking | H10: =IF(C10="","",IFERROR(INDEX(Categories!$B$6:$B$65,MATCH(C10,Categories!$A$6:$A$65,0))&"","")) | I10: =IF(AND(A10="",C10="",D10=""),"",IF(A10="","Date missing",IF(NOT(ISNUMBER(A10)),"Date not recognized",IF(YEAR(A10)<>Settings!$C$4,"Not in "&Settings!$C$4,IF(C10="","Category missing",IF(H10="",IF(COUNTIF(Categories!$A$6:$A$65,C10)>0,"Category has no type","Category not in list"),IF(D10="","Amount missing",IF(NOT(ISNUMBER(D10)),"Amount is not a number",IF(F10="","",IF(ISNA(MATCH(F10,Lists!$G$2:$G$25,0)),"Goal / fund not in list",IF(H10="Income","Fund tag ignored on income","")))))))))))
A11: 46024 | B11: Transfer to emergency fund | C11: Emergency fund | D11: 300 | E11: Savings | F11: Emergency fund | H11: =IF(C11="","",IFERROR(INDEX(Categories!$B$6:$B$65,MATCH(C11,Categories!$A$6:$A$65,0))&"","")) | I11: =IF(AND(A11="",C11="",D11=""),"",IF(A11="","Date missing",IF(NOT(ISNUMBER(A11)),"Date not recognized",IF(YEAR(A11)<>Settings!$C$4,"Not in "&Settings!$C$4,IF(C11="","Category missing",IF(H11="",IF(COUNTIF(Categories!$A$6:$A$65,C11)>0,"Category has no type","Category not in list"),IF(D11="","Amount missing",IF(NOT(ISNUMBER(D11)),"Amount is not a number",IF(F11="","",IF(ISNA(MATCH(F11,Lists!$G$2:$G$25,0)),"Goal / fund not in list",IF(H11="Income","Fund tag ignored on income","")))))))))))
A12: 46024 | B12: Transfer: house fund | C12: Savings goals | D12: 300 | E12: Savings | F12: House down payment | H12: =IF(C12="","",IFERROR(INDEX(Categories!$B$6:$B$65,MATCH(C12,Categories!$A$6:$A$65,0))&"","")) | I12: =IF(AND(A12="",C12="",D12=""),"",IF(A12="","Date missing",IF(NOT(ISNUMBER(A12)),"Date not recognized",IF(YEAR(A12)<>Settings!$C$4,"Not in "&Settings!$C$4,IF(C12="","Category missing",IF(H12="",IF(COUNTIF(Categories!$A$6:$A$65,C12)>0,"Category has no type","Category not in list"),IF(D12="","Amount missing",IF(NOT(ISNUMBER(D12)),"Amount is not a number",IF(F12="","",IF(ISNA(MATCH(F12,Lists!$G$2:$G$25,0)),"Goal / fund not in list",IF(H12="Income","Fund tag ignored on income","")))))))))))
A13: 46024 | B13: Transfer: laptop | C13: Savings goals | D13: 100 | E13: Savings | F13: New laptop | H13: =IF(C13="","",IFERROR(INDEX(Categories!$B$6:$B$65,MATCH(C13,Categories!$A$6:$A$65,0))&"","")) | I13: =IF(AND(A13="",C13="",D13=""),"",IF(A13="","Date missing",IF(NOT(ISNUMBER(A13)),"Date not recognized",IF(YEAR(A13)<>Settings!$C$4,"Not in "&Settings!$C$4,IF(C13="","Category missing",IF(H13="",IF(COUNTIF(Categories!$A$6:$A$65,C13)>0,"Category has no type","Category not in list"),IF(D13="","Amount missing",IF(NOT(ISNUMBER(D13)),"Amount is not a number",IF(F13="","",IF(ISNA(MATCH(F13,Lists!$G$2:$G$25,0)),"Goal / fund not in list",IF(H13="Income","Fund tag ignored on income","")))))))))))
A14: 46024 | B14: Set aside: car maintenance | C14: Sinking funds | D14: 60 | E14: Savings | F14: Car maintenance | H14: =IF(C14="","",IFERROR(INDEX(Categories!$B$6:$B$65,MATCH(C14,Categories!$A$6:$A$65,0))&"","")) | I14: =IF(AND(A14="",C14="",D14=""),"",IF(A14="","Date missing",IF(NOT(ISNUMBER(A14)),"Date not recognized",IF(YEAR(A14)<>Settings!$C$4,"Not in "&Settings!$C$4,IF(C14="","Category missing",IF(H14="",IF(COUNTIF(Categories!$A$6:$A$65,C14)>0,"Category has no type","Category not in list"),IF(D14="","Amount missing",IF(NOT(ISNUMBER(D14)),"Amount is not a number",IF(F14="","",IF(ISNA(MATCH(F14,Lists!$G$2:$G$25,0)),"Goal / fund not in list",IF(H14="Income","Fund tag ignored on income","")))))))))))
A15: 46024 | B15: Set aside: holiday gifts | C15: Sinking funds | D15: 50 | E15: Savings | F15: Holiday gifts | H15: =IF(C15="","",IFERROR(INDEX(Categories!$B$6:$B$65,MATCH(C15,Categories!$A$6:$A$65,0))&"","")) | I15: =IF(AND(A15="",C15="",D15=""),"",IF(A15="","Date missing",IF(NOT(ISNUMBER(A15)),"Date not recognized",IF(YEAR(A15)<>Settings!$C$4,"Not in "&Settings!$C$4,IF(C15="","Category missing",IF(H15="",IF(COUNTIF(Categories!$A$6:$A$65,C15)>0,"Category has no type","Category not in list"),IF(D15="","Amount missing",IF(NOT(ISNUMBER(D15)),"Amount is not a number",IF(F15="","",IF(ISNA(MATCH(F15,Lists!$G$2:$G$25,0)),"Goal / fund not in list",IF(H15="Income","Fund tag ignored on income","")))))))))))
A16: 46024 | B16: Set aside: summer vacation | C16: Sinking funds | D16: 150 | E16: Savings | F16: Summer vacation | H16: =IF(C16="","",IFERROR(INDEX(Categories!$B$6:$B$65,MATCH(C16,Categories!$A$6:$A$65,0))&"","")) | I16: =IF(AND(A16="",C16="",D16=""),"",IF(A16="","Date missing",IF(NOT(ISNUMBER(A16)),"Date not recognized",IF(YEAR(A16)<>Settings!$C$4,"Not in "&Settings!$C$4,IF(C16="","Category missing",IF(H16="",IF(COUNTIF(Categories!$A$6:$A$65,C16)>0,"Category has no type","Category not in list"),IF(D16="","Amount missing",IF(NOT(ISNUMBER(D16)),"Amount is not a number",IF(F16="","",IF(ISNA(MATCH(F16,Lists!$G$2:$G$25,0)),"Goal / fund not in list",IF(H16="Income","Fund tag ignored on income","")))))))))))
A17: 46024 | B17: Set aside: home repairs | C17: Sinking funds | D17: 40 | E17: Savings | F17: Home repairs | H17: =IF(C17="","",IFERROR(INDEX(Categories!$B$6:$B$65,MATCH(C17,Categories!$A$6:$A$65,0))&"","")) | I17: =IF(AND(A17="",C17="",D17=""),"",IF(A17="","Date missing",IF(NOT(ISNUMBER(A17)),"Date not recognized",IF(YEAR(A17)<>Settings!$C$4,"Not in "&Settings!$C$4,IF(C17="","Category missing",IF(H17="",IF(COUNTIF(Categories!$A$6:$A$65,C17)>0,"Category has no type","Category not in list"),IF(D17="","Amount missing",IF(NOT(ISNUMBER(D17)),"Amount is not a number",IF(F17="","",IF(ISNA(MATCH(F17,Lists!$G$2:$G$25,0)),"Goal / fund not in list",IF(H17="Income","Fund tag ignored on income","")))))))))))
A18: 46025 | B18: Video streaming | C18: Subscriptions | D18: 15.49 | E18: Credit card | H18: =IF(C18="","",IFERROR(INDEX(Categories!$B$6:$B$65,MATCH(C18,Categories!$A$6:$A$65,0))&"","")) | I18: =IF(AND(A18="",C18="",D18=""),"",IF(A18="","Date missing",IF(NOT(ISNUMBER(A18)),"Date not recognized",IF(YEAR(A18)<>Settings!$C$4,"Not in "&Settings!$C$4,IF(C18="","Category missing",IF(H18="",IF(COUNTIF(Categories!$A$6:$A$65,C18)>0,"Category has no type","Category not in list"),IF(D18="","Amount missing",IF(NOT(ISNUMBER(D18)),"Amount is not a number",IF(F18="","",IF(ISNA(MATCH(F18,Lists!$G$2:$G$25,0)),"Goal / fund not in list",IF(H18="Income","Fund tag ignored on income","")))))))))))
A19: 46025 | B19: Supermarket | C19: Groceries | D19: 191.42 | E19: Debit card | H19: =IF(C19="","",IFERROR(INDEX(Categories!$B$6:$B$65,MATCH(C19,Categories!$A$6:$A$65,0))&"","")) | I19: =IF(AND(A19="",C19="",D19=""),"",IF(A19="","Date missing",IF(NOT(ISNUMBER(A19)),"Date not recognized",IF(YEAR(A19)<>Settings!$C$4,"Not in "&Settings!$C$4,IF(C19="","Category missing",IF(H19="",IF(COUNTIF(Categories!$A$6:$A$65,C19)>0,"Category has no type","Category not in list"),IF(D19="","Amount missing",IF(NOT(ISNUMBER(D19)),"Amount is not a number",IF(F19="","",IF(ISNA(MATCH(F19,Lists!$G$2:$G$25,0)),"Goal / fund not in list",IF(H19="Income","Fund tag ignored on income","")))))))))))
A20: 46025 | B20: Retirement contribution | C20: Retirement & investing | D20: 600 | E20: Checking | H20: =IF(C20="","",IFERROR(INDEX(Categories!$B$6:$B$65,MATCH(C20,Categories!$A$6:$A$65,0))&"","")) | I20: =IF(AND(A20="",C20="",D20=""),"",IF(A20="","Date missing",IF(NOT(ISNUMBER(A20)),"Date not recognized",IF(YEAR(A20)<>Settings!$C$4,"Not in "&Settings!$C$4,IF(C20="","Category missing",IF(H20="",IF(COUNTIF(Categories!$A$6:$A$65,C20)>0,"Category has no type","Category not in list"),IF(D20="","Amount missing",IF(NOT(ISNUMBER(D20)),"Amount is not a number",IF(F20="","",IF(ISNA(MATCH(F20,Lists!$G$2:$G$25,0)),"Goal / fund not in list",IF(H20="Income","Fund tag ignored on income","")))))))))))
A21: 46026 | B21: Gas station | C21: Transport / Gas | D21: 44.13 | E21: Credit card | H21: =IF(C21="","",IFERROR(INDEX(Categories!$B$6:$B$65,MATCH(C21,Categories!$A$6:$A$65,0))&"","")) | I21: =IF(AND(A21="",C21="",D21=""),"",IF(A21="","Date missing",IF(NOT(ISNUMBER(A21)),"Date not recognized",IF(YEAR(A21)<>Settings!$C$4,"Not in "&Settings!$C$4,IF(C21="","Category missing",IF(H21="",IF(COUNTIF(Categories!$A$6:$A$65,C21)>0,"Category has no type","Category not in list"),IF(D21="","Amount missing",IF(NOT(ISNUMBER(D21)),"Amount is not a number",IF(F21="","",IF(ISNA(MATCH(F21,Lists!$G$2:$G$25,0)),"Goal / fund not in list",IF(H21="Income","Fund tag ignored on income","")))))))))))
A22: 46027 | B22: Car insurance | C22: Insurance | D22: 128 | E22: Checking | H22: =IF(C22="","",IFERROR(INDEX(Categories!$B$6:$B$65,MATCH(C22,Categories!$A$6:$A$65,0))&"","")) | I22: =IF(AND(A22="",C22="",D22=""),"",IF(A22="","Date missing",IF(NOT(ISNUMBER(A22)),"Date not recognized",IF(YEAR(A22)<>Settings!$C$4,"Not in "&Settings!$C$4,IF(C22="","Category missing",IF(H22="",IF(COUNTIF(Categories!$A$6:$A$65,C22)>0,"Category has no type","Category not in list"),IF(D22="","Amount missing",IF(NOT(ISNUMBER(D22)),"Amount is not a number",IF(F22="","",IF(ISNA(MATCH(F22,Lists!$G$2:$G$25,0)),"Goal / fund not in list",IF(H22="Income","Fund tag ignored on income","")))))))))))
A23: 46027 | B23: Renters insurance | C23: Insurance | D23: 18 | E23: Checking | H23: =IF(C23="","",IFERROR(INDEX(Categories!$B$6:$B$65,MATCH(C23,Categories!$A$6:$A$65,0))&"","")) | I23: =IF(AND(A23="",C23="",D23=""),"",IF(A23="","Date missing",IF(NOT(ISNUMBER(A23)),"Date not recognized",IF(YEAR(A23)<>Settings!$C$4,"Not in "&Settings!$C$4,IF(C23="","Category missing",IF(H23="",IF(COUNTIF(Categories!$A$6:$A$65,C23)>0,"Category has no type","Category not in list"),IF(D23="","Amount missing",IF(NOT(ISNUMBER(D23)),"Amount is not a number",IF(F23="","",IF(ISNA(MATCH(F23,Lists!$G$2:$G$25,0)),"Goal / fund not in list",IF(H23="Income","Fund tag ignored on income","")))))))))))
A24: 46029 | B24: Music streaming | C24: Subscriptions | D24: 10.99 | E24: Credit card | H24: =IF(C24="","",IFERROR(INDEX(Categories!$B$6:$B$65,MATCH(C24,Categories!$A$6:$A$65,0))&"","")) | I24: =IF(AND(A24="",C24="",D24=""),"",IF(A24="","Date missing",IF(NOT(ISNUMBER(A24)),"Date not recognized",IF(YEAR(A24)<>Settings!$C$4,"Not in "&Settings!$C$4,IF(C24="","Category missing",IF(H24="",IF(COUNTIF(Categories!$A$6:$A$65,C24)>0,"Category has no type","Category not in list"),IF(D24="","Amount missing",IF(NOT(ISNUMBER(D24)),"Amount is not a number",IF(F24="","",IF(ISNA(MATCH(F24,Lists!$G$2:$G$25,0)),"Goal / fund not in list",IF(H24="Income","Fund tag ignored on income","")))))))))))
A25: 46029 | B25: Takeout | C25: Dining out | D25: 23.84 | E25: Credit card | H25: =IF(C25="","",IFERROR(INDEX(Categories!$B$6:$B$65,MATCH(C25,Categories!$A$6:$A$65,0))&"","")) | I25: =IF(AND(A25="",C25="",D25=""),"",IF(A25="","Date missing",IF(NOT(ISNUMBER(A25)),"Date not recognized",IF(YEAR(A25)<>Settings!$C$4,"Not in "&Settings!$C$4,IF(C25="","Category missing",IF(H25="",IF(COUNTIF(Categories!$A$6:$A$65,C25)>0,"Category has no type","Category not in list"),IF(D25="","Amount missing",IF(NOT(ISNUMBER(D25)),"Amount is not a number",IF(F25="","",IF(ISNA(MATCH(F25,Lists!$G$2:$G$25,0)),"Goal / fund not in list",IF(H25="Income","Fund tag ignored on income","")))))))))))
A26: 46031 | B26: Pet food | C26: Pets | D26: 46.29 | E26: Debit card | H26: =IF(C26="","",IFERROR(INDEX(Categories!$B$6:$B$65,MATCH(C26,Categories!$A$6:$A$65,0))&"","")) | I26: =IF(AND(A26="",C26="",D26=""),"",IF(A26="","Date missing",IF(NOT(ISNUMBER(A26)),"Date not recognized",IF(YEAR(A26)<>Settings!$C$4,"Not in "&Settings!$C$4,IF(C26="","Category missing",IF(H26="",IF(COUNTIF(Categories!$A$6:$A$65,C26)>0,"Category has no type","Category not in list"),IF(D26="","Amount missing",IF(NOT(ISNUMBER(D26)),"Amount is not a number",IF(F26="","",IF(ISNA(MATCH(F26,Lists!$G$2:$G$25,0)),"Goal / fund not in list",IF(H26="Income","Fund tag ignored on income","")))))))))))
A27: 46032 | B27: Car loan payment | C27: Car payment | D27: 389 | E27: Checking | H27: =IF(C27="","",IFERROR(INDEX(Categories!$B$6:$B$65,MATCH(C27,Categories!$A$6:$A$65,0))&"","")) | I27: =IF(AND(A27="",C27="",D27=""),"",IF(A27="","Date missing",IF(NOT(ISNUMBER(A27)),"Date not recognized",IF(YEAR(A27)<>Settings!$C$4,"Not in "&Settings!$C$4,IF(C27="","Category missing",IF(H27="",IF(COUNTIF(Categories!$A$6:$A$65,C27)>0,"Category has no type","Category not in list"),IF(D27="","Amount missing",IF(NOT(ISNUMBER(D27)),"Amount is not a number",IF(F27="","",IF(ISNA(MATCH(F27,Lists!$G$2:$G$25,0)),"Goal / fund not in list",IF(H27="Income","Fund tag ignored on income","")))))))))))
A28: 46032 | B28: Warehouse store | C28: Groceries | D28: 183.97 | E28: Debit card | H28: =IF(C28="","",IFERROR(INDEX(Categories!$B$6:$B$65,MATCH(C28,Categories!$A$6:$A$65,0))&"","")) | I28: =IF(AND(A28="",C28="",D28=""),"",IF(A28="","Date missing",IF(NOT(ISNUMBER(A28)),"Date not recognized",IF(YEAR(A28)<>Settings!$C$4,"Not in "&Settings!$C$4,IF(C28="","Category missing",IF(H28="",IF(COUNTIF(Categories!$A$6:$A$65,C28)>0,"Category has no type","Category not in list"),IF(D28="","Amount missing",IF(NOT(ISNUMBER(D28)),"Amount is not a number",IF(F28="","",IF(ISNA(MATCH(F28,Lists!$G$2:$G$25,0)),"Goal / fund not in list",IF(H28="Income","Fund tag ignored on income","")))))))))))
A29: 46034 | B29: Internet | C29: Internet & Phone | D29: 65 | E29: Checking | H29: =IF(C29="","",IFERROR(INDEX(Categories!$B$6:$B$65,MATCH(C29,Categories!$A$6:$A$65,0))&"","")) | I29: =IF(AND(A29="",C29="",D29=""),"",IF(A29="","Date missing",IF(NOT(ISNUMBER(A29)),"Date not recognized",IF(YEAR(A29)<>Settings!$C$4,"Not in "&Settings!$C$4,IF(C29="","Category missing",IF(H29="",IF(COUNTIF(Categories!$A$6:$A$65,C29)>0,"Category has no type","Category not in list"),IF(D29="","Amount missing",IF(NOT(ISNUMBER(D29)),"Amount is not a number",IF(F29="","",IF(ISNA(MATCH(F29,Lists!$G$2:$G$25,0)),"Goal / fund not in list",IF(H29="Income","Fund tag ignored on income","")))))))))))
... A62: 46055 | B62: Gym membership | C62: Subscriptions | D62: 45 | E62: Checking | H62: =IF(C62="","",IFERROR(INDEX(Categories!$B$6:$B$65,MATCH(C62,Categories!$A$6:$A$65,0))&"","")) | I62: =IF(AND(A62="",C62="",D62=""),"",IF(A62="","Date missing",IF(NOT(ISNUMBER(A62)),"Date not recognized",IF(YEAR(A62)<>Settings!$C$4,"Not in "&Settings!$C$4,IF(C62="","Category missing",IF(H62="",IF(COUNTIF(Categories!$A$6:$A$65,C62)>0,"Category has no type","Category not in list"),IF(D62="","Amount missing",IF(NOT(ISNUMBER(D62)),"Amount is not a number",IF(F62="","",IF(ISNA(MATCH(F62,Lists!$G$2:$G$25,0)),"Goal / fund not in list",IF(H62="Income","Fund tag ignored on income","")))))))))))
A63: 46055 | B63: Transfer to emergency fund | C63: Emergency fund | D63: 300 | E63: Savings | F63: Emergency fund | H63: =IF(C63="","",IFERROR(INDEX(Categories!$B$6:$B$65,MATCH(C63,Categories!$A$6:$A$65,0))&"","")) | I63: =IF(AND(A63="",C63="",D63=""),"",IF(A63="","Date missing",IF(NOT(ISNUMBER(A63)),"Date not recognized",IF(YEAR(A63)<>Settings!$C$4,"Not in "&Settings!$C$4,IF(C63="","Category missing",IF(H63="",IF(COUNTIF(Categories!$A$6:$A$65,C63)>0,"Category has no type","Category not in list"),IF(D63="","Amount missing",IF(NOT(ISNUMBER(D63)),"Amount is not a number",IF(F63="","",IF(ISNA(MATCH(F63,Lists!$G$2:$G$25,0)),"Goal / fund not in list",IF(H63="Income","Fund tag ignored on income","")))))))))))
A64: 46055 | B64: Transfer: house fund | C64: Savings goals | D64: 300 | E64: Savings | F64: House down payment | H64: =IF(C64="","",IFERROR(INDEX(Categories!$B$6:$B$65,MATCH(C64,Categories!$A$6:$A$65,0))&"","")) | I64: =IF(AND(A64="",C64="",D64=""),"",IF(A64="","Date missing",IF(NOT(ISNUMBER(A64)),"Date not recognized",IF(YEAR(A64)<>Settings!$C$4,"Not in "&Settings!$C$4,IF(C64="","Category missing",IF(H64="",IF(COUNTIF(Categories!$A$6:$A$65,C64)>0,"Category has no type","Category not in list"),IF(D64="","Amount missing",IF(NOT(ISNUMBER(D64)),"Amount is not a number",IF(F64="","",IF(ISNA(MATCH(F64,Lists!$G$2:$G$25,0)),"Goal / fund not in list",IF(H64="Income","Fund tag ignored on income","")))))))))))
A65: 46055 | B65: Transfer: laptop | C65: Savings goals | D65: 100 | E65: Savings | F65: New laptop | H65: =IF(C65="","",IFERROR(INDEX(Categories!$B$6:$B$65,MATCH(C65,Categories!$A$6:$A$65,0))&"","")) | I65: =IF(AND(A65="",C65="",D65=""),"",IF(A65="","Date missing",IF(NOT(ISNUMBER(A65)),"Date not recognized",IF(YEAR(A65)<>Settings!$C$4,"Not in "&Settings!$C$4,IF(C65="","Category missing",IF(H65="",IF(COUNTIF(Categories!$A$6:$A$65,C65)>0,"Category has no type","Category not in list"),IF(D65="","Amount missing",IF(NOT(ISNUMBER(D65)),"Amount is not a number",IF(F65="","",IF(ISNA(MATCH(F65,Lists!$G$2:$G$25,0)),"Goal / fund not in list",IF(H65="Income","Fund tag ignored on income","")))))))))))
A66: 46055 | B66: Set aside: car maintenance | C66: Sinking funds | D66: 60 | E66: Savings | F66: Car maintenance | H66: =IF(C66="","",IFERROR(INDEX(Categories!$B$6:$B$65,MATCH(C66,Categories!$A$6:$A$65,0))&"","")) | I66: =IF(AND(A66="",C66="",D66=""),"",IF(A66="","Date missing",IF(NOT(ISNUMBER(A66)),"Date not recognized",IF(YEAR(A66)<>Settings!$C$4,"Not in "&Settings!$C$4,IF(C66="","Category missing",IF(H66="",IF(COUNTIF(Categories!$A$6:$A$65,C66)>0,"Category has no type","Category not in list"),IF(D66="","Amount missing",IF(NOT(ISNUMBER(D66)),"Amount is not a number",IF(F66="","",IF(ISNA(MATCH(F66,Lists!$G$2:$G$25,0)),"Goal / fund not in list",IF(H66="Income","Fund tag ignored on income","")))))))))))
A67: 46055 | B67: Set aside: holiday gifts | C67: Sinking funds | D67: 50 | E67: Savings | F67: Holiday gifts | H67: =IF(C67="","",IFERROR(INDEX(Categories!$B$6:$B$65,MATCH(C67,Categories!$A$6:$A$65,0))&"","")) | I67: =IF(AND(A67="",C67="",D67=""),"",IF(A67="","Date missing",IF(NOT(ISNUMBER(A67)),"Date not recognized",IF(YEAR(A67)<>Settings!$C$4,"Not in "&Settings!$C$4,IF(C67="","Category missing",IF(H67="",IF(COUNTIF(Categories!$A$6:$A$65,C67)>0,"Category has no type","Category not in list"),IF(D67="","Amount missing",IF(NOT(ISNUMBER(D67)),"Amount is not a number",IF(F67="","",IF(ISNA(MATCH(F67,Lists!$G$2:$G$25,0)),"Goal / fund not in list",IF(H67="Income","Fund tag ignored on income","")))))))))))
A68: 46055 | B68: Set aside: summer vacation | C68: Sinking funds | D68: 150 | E68: Savings | F68: Summer vacation | H68: =IF(C68="","",IFERROR(INDEX(Categories!$B$6:$B$65,MATCH(C68,Categories!$A$6:$A$65,0))&"","")) | I68: =IF(AND(A68="",C68="",D68=""),"",IF(A68="","Date missing",IF(NOT(ISNUMBER(A68)),"Date not recognized",IF(YEAR(A68)<>Settings!$C$4,"Not in "&Settings!$C$4,IF(C68="","Category missing",IF(H68="",IF(COUNTIF(Categories!$A$6:$A$65,C68)>0,"Category has no type","Category not in list"),IF(D68="","Amount missing",IF(NOT(ISNUMBER(D68)),"Amount is not a number",IF(F68="","",IF(ISNA(MATCH(F68,Lists!$G$2:$G$25,0)),"Goal / fund not in list",IF(H68="Income","Fund tag ignored on income","")))))))))))
A69: 46055 | B69: Set aside: home repairs | C69: Sinking funds | D69: 40 | E69: Savings | F69: Home repairs | H69: =IF(C69="","",IFERROR(INDEX(Categories!$B$6:$B$65,MATCH(C69,Categories!$A$6:$A$65,0))&"","")) | I69: =IF(AND(A69="",C69="",D69=""),"",IF(A69="","Date missing",IF(NOT(ISNUMBER(A69)),"Date not recognized",IF(YEAR(A69)<>Settings!$C$4,"Not in "&Settings!$C$4,IF(C69="","Category missing",IF(H69="",IF(COUNTIF(Categories!$A$6:$A$65,C69)>0,"Category has no type","Category not in list"),IF(D69="","Amount missing",IF(NOT(ISNUMBER(D69)),"Amount is not a number",IF(F69="","",IF(ISNA(MATCH(F69,Lists!$G$2:$G$25,0)),"Goal / fund not in list",IF(H69="Income","Fund tag ignored on income","")))))))))))
A70: 46056 | B70: Video streaming | C70: Subscriptions | D70: 15.49 | E70: Credit card | H70: =IF(C70="","",IFERROR(INDEX(Categories!$B$6:$B$65,MATCH(C70,Categories!$A$6:$A$65,0))&"","")) | I70: =IF(AND(A70="",C70="",D70=""),"",IF(A70="","Date missing",IF(NOT(ISNUMBER(A70)),"Date not recognized",IF(YEAR(A70)<>Settings!$C$4,"Not in "&Settings!$C$4,IF(C70="","Category missing",IF(H70="",IF(COUNTIF(Categories!$A$6:$A$65,C70)>0,"Category has no type","Category not in list"),IF(D70="","Amount missing",IF(NOT(ISNUMBER(D70)),"Amount is not a number",IF(F70="","",IF(ISNA(MATCH(F70,Lists!$G$2:$G$25,0)),"Goal / fund not in list",IF(H70="Income","Fund tag ignored on income","")))))))))))
A71: 46056 | B71: Farmers market | C71: Groceries | D71: 167.42 | E71: Debit card | H71: =IF(C71="","",IFERROR(INDEX(Categories!$B$6:$B$65,MATCH(C71,Categories!$A$6:$A$65,0))&"","")) | I71: =IF(AND(A71="",C71="",D71=""),"",IF(A71="","Date missing",IF(NOT(ISNUMBER(A71)),"Date not recognized",IF(YEAR(A71)<>Settings!$C$4,"Not in "&Settings!$C$4,IF(C71="","Category missing",IF(H71="",IF(COUNTIF(Categories!$A$6:$A$65,C71)>0,"Category has no type","Category not in list"),IF(D71="","Amount missing",IF(NOT(ISNUMBER(D71)),"Amount is not a number",IF(F71="","",IF(ISNA(MATCH(F71,Lists!$G$2:$G$25,0)),"Goal / fund not in list",IF(H71="Income","Fund tag ignored on income","")))))))))))
A72: 46056 | B72: Movie tickets | C72: Entertainment | D72: 32.76 | E72: Credit card | H72: =IF(C72="","",IFERROR(INDEX(Categories!$B$6:$B$65,MATCH(C72,Categories!$A$6:$A$65,0))&"","")) | I72: =IF(AND(A72="",C72="",D72=""),"",IF(A72="","Date missing",IF(NOT(ISNUMBER(A72)),"Date not recognized",IF(YEAR(A72)<>Settings!$C$4,"Not in "&Settings!$C$4,IF(C72="","Category missing",IF(H72="",IF(COUNTIF(Categories!$A$6:$A$65,C72)>0,"Category has no type","Category not in list"),IF(D72="","Amount missing",IF(NOT(ISNUMBER(D72)),"Amount is not a number",IF(F72="","",IF(ISNA(MATCH(F72,Lists!$G$2:$G$25,0)),"Goal / fund not in list",IF(H72="Income","Fund tag ignored on income","")))))))))))
A73: 46056 | B73: Retirement contribution | C73: Retirement & investing | D73: 600 | E73: Checking | H73: =IF(C73="","",IFERROR(INDEX(Categories!$B$6:$B$65,MATCH(C73,Categories!$A$6:$A$65,0))&"","")) | I73: =IF(AND(A73="",C73="",D73=""),"",IF(A73="","Date missing",IF(NOT(ISNUMBER(A73)),"Date not recognized",IF(YEAR(A73)<>Settings!$C$4,"Not in "&Settings!$C$4,IF(C73="","Category missing",IF(H73="",IF(COUNTIF(Categories!$A$6:$A$65,C73)>0,"Category has no type","Category not in list"),IF(D73="","Amount missing",IF(NOT(ISNUMBER(D73)),"Amount is not a number",IF(F73="","",IF(ISNA(MATCH(F73,Lists!$G$2:$G$25,0)),"Goal / fund not in list",IF(H73="Income","Fund tag ignored on income","")))))))))))
...

Sheet Monthly Budget
A1: Monthly Budget
A2: Type a typical monthly amount in column C: the 12 months fill in by themselves. For a month that is different (annual bills, holidays), type over that month.
A3: To go back to the typical amount, copy a month that you did not change. The summary rows at the top are calculated.
D4: ="Planned by month"&Settings!$C$14
A5: Category | B5: Type | C5: ="Typical month"&Settings!$C$14 | D5: Jan | E5: Feb | F5: Mar | G5: Apr | H5: May | I5: Jun | J5: Jul | K5: Aug | L5: Sep | M5: Oct | N5: Nov | O5: Dec | P5: ="Year total"&Settings!$C$14
A6: Income | B6: Income | C6: =SUMIFS(C$14:C$73,$B$14:$B$73,"Income") | D6: =SUMIFS(D$14:D$73,$B$14:$B$73,"Income") | E6: =SUMIFS(E$14:E$73,$B$14:$B$73,"Income") | F6: =SUMIFS(F$14:F$73,$B$14:$B$73,"Income") | G6: =SUMIFS(G$14:G$73,$B$14:$B$73,"Income") | H6: =SUMIFS(H$14:H$73,$B$14:$B$73,"Income") | I6: =SUMIFS(I$14:I$73,$B$14:$B$73,"Income") | J6: =SUMIFS(J$14:J$73,$B$14:$B$73,"Income") | ... P6: =SUMIFS(P$14:P$73,$B$14:$B$73,"Income")
A7: Fixed bills | B7: Fixed bills | C7: =SUMIFS(C$14:C$73,$B$14:$B$73,"Fixed bills") | D7: =SUMIFS(D$14:D$73,$B$14:$B$73,"Fixed bills") | E7: =SUMIFS(E$14:E$73,$B$14:$B$73,"Fixed bills") | F7: =SUMIFS(F$14:F$73,$B$14:$B$73,"Fixed bills") | G7: =SUMIFS(G$14:G$73,$B$14:$B$73,"Fixed bills") | H7: =SUMIFS(H$14:H$73,$B$14:$B$73,"Fixed bills") | I7: =SUMIFS(I$14:I$73,$B$14:$B$73,"Fixed bills") | J7: =SUMIFS(J$14:J$73,$B$14:$B$73,"Fixed bills") | ... P7: =SUMIFS(P$14:P$73,$B$14:$B$73,"Fixed bills")
A8: Variable expenses | B8: Variable expenses | C8: =SUMIFS(C$14:C$73,$B$14:$B$73,"Variable expenses") | D8: =SUMIFS(D$14:D$73,$B$14:$B$73,"Variable expenses") | E8: =SUMIFS(E$14:E$73,$B$14:$B$73,"Variable expenses") | F8: =SUMIFS(F$14:F$73,$B$14:$B$73,"Variable expenses") | G8: =SUMIFS(G$14:G$73,$B$14:$B$73,"Variable expenses") | H8: =SUMIFS(H$14:H$73,$B$14:$B$73,"Variable expenses") | I8: =SUMIFS(I$14:I$73,$B$14:$B$73,"Variable expenses") | J8: =SUMIFS(J$14:J$73,$B$14:$B$73,"Variable expenses") | ... P8: =SUMIFS(P$14:P$73,$B$14:$B$73,"Variable expenses")
A9: Total expenses | B9: All expenses | C9: =C7+C8 | D9: =D7+D8 | E9: =E7+E8 | F9: =F7+F8 | G9: =G7+G8 | H9: =H7+H8 | I9: =I7+I8 | J9: =J7+J8 | ... P9: =P7+P8
A10: Savings & debt payments | B10: Savings & debt | C10: =SUMIFS(C$14:C$73,$B$14:$B$73,"Savings & debt") | D10: =SUMIFS(D$14:D$73,$B$14:$B$73,"Savings & debt") | E10: =SUMIFS(E$14:E$73,$B$14:$B$73,"Savings & debt") | F10: =SUMIFS(F$14:F$73,$B$14:$B$73,"Savings & debt") | G10: =SUMIFS(G$14:G$73,$B$14:$B$73,"Savings & debt") | H10: =SUMIFS(H$14:H$73,$B$14:$B$73,"Savings & debt") | I10: =SUMIFS(I$14:I$73,$B$14:$B$73,"Savings & debt") | J10: =SUMIFS(J$14:J$73,$B$14:$B$73,"Savings & debt") | ... P10: =SUMIFS(P$14:P$73,$B$14:$B$73,"Savings & debt")
A11: Paid from goals & funds | B11: Funds | J11: 1500 | L11: 500 | O11: 600 | P11: =SUM(D11:O11)
A12: Left to budget | B12: Result | C12: =C6-C9-C10+N(C11) | D12: =D6-D9-D10+N(D11) | E12: =E6-E9-E10+N(E11) | F12: =F6-F9-F10+N(F11) | G12: =G6-G9-G10+N(G11) | H12: =H6-H9-H10+N(H11) | I12: =I6-I9-I10+N(I11) | J12: =J6-J9-J10+N(J11) | ... P12: =P6-P9-P10+N(P11)
A13: Categories
A14: =IF(Categories!$A6="","",Categories!$A6) | B14: =IF(A14="","",Categories!$B6&"") | C14: 4200 | D14: =$C14 | E14: =$C14 | F14: =$C14 | G14: =$C14 | H14: =$C14 | I14: =$C14 | J14: =$C14 | K14: =$C14 | ... O14: =$C14 | P14: =SUM(D14:O14)
A15: =IF(Categories!$A7="","",Categories!$A7) | B15: =IF(A15="","",Categories!$B7&"") | C15: 2950 | D15: =$C15 | E15: =$C15 | F15: =$C15 | G15: =$C15 | H15: =$C15 | I15: =$C15 | J15: =$C15 | K15: =$C15 | ... O15: =$C15 | P15: =SUM(D15:O15)
A16: =IF(Categories!$A8="","",Categories!$A8) | B16: =IF(A16="","",Categories!$B8&"") | C16: 250 | D16: =$C16 | E16: =$C16 | F16: =$C16 | G16: =$C16 | H16: =$C16 | I16: =$C16 | J16: =$C16 | K16: =$C16 | ... O16: =$C16 | P16: =SUM(D16:O16)
A17: =IF(Categories!$A9="","",Categories!$A9) | B17: =IF(A17="","",Categories!$B9&"") | C17: 0 | D17: =$C17 | E17: =$C17 | F17: =$C17 | G17: 1200 | H17: =$C17 | I17: =$C17 | J17: =$C17 | K17: =$C17 | L17: =$C17 | M17: =$C17 | N17: =$C17 | O17: 300 | P17: =SUM(D17:O17)
A18: =IF(Categories!$A10="","",Categories!$A10) | B18: =IF(A18="","",Categories!$B10&"") | C18: 1850 | D18: =$C18 | E18: =$C18 | F18: =$C18 | G18: =$C18 | H18: =$C18 | I18: =$C18 | J18: =$C18 | K18: =$C18 | ... O18: =$C18 | P18: =SUM(D18:O18)
A19: =IF(Categories!$A11="","",Categories!$A11) | B19: =IF(A19="","",Categories!$B11&"") | C19: 200 | D19: 260 | E19: 250 | F19: =$C19 | G19: =$C19 | H19: =$C19 | I19: =$C19 | J19: 240 | K19: 245 | L19: =$C19 | M19: =$C19 | N19: =$C19 | O19: 260 | P19: =SUM(D19:O19)
A20: =IF(Categories!$A12="","",Categories!$A12) | B20: =IF(A20="","",Categories!$B12&"") | C20: 135 | D20: =$C20 | E20: =$C20 | F20: =$C20 | G20: =$C20 | H20: =$C20 | I20: =$C20 | J20: =$C20 | K20: =$C20 | ... O20: =$C20 | P20: =SUM(D20:O20)
A21: =IF(Categories!$A13="","",Categories!$A13) | B21: =IF(A21="","",Categories!$B13&"") | C21: 146 | D21: =$C21 | E21: =$C21 | F21: =$C21 | G21: =$C21 | H21: =$C21 | I21: =$C21 | J21: =$C21 | K21: =$C21 | ... O21: =$C21 | P21: =SUM(D21:O21)
A22: =IF(Categories!$A14="","",Categories!$A14) | B22: =IF(A22="","",Categories!$B14&"") | C22: 72 | D22: =$C22 | E22: =$C22 | F22: 102 | G22: =$C22 | H22: =$C22 | I22: =$C22 | J22: =$C22 | K22: =$C22 | L22: =$C22 | M22: =$C22 | N22: =$C22 | O22: =$C22 | P22: =SUM(D22:O22)
A23: =IF(Categories!$A15="","",Categories!$A15) | B23: =IF(A23="","",Categories!$B15&"") | C23: 389 | D23: =$C23 | E23: =$C23 | F23: =$C23 | G23: =$C23 | H23: =$C23 | I23: =$C23 | J23: =$C23 | K23: =$C23 | ... O23: =$C23 | P23: =SUM(D23:O23)
A24: =IF(Categories!$A16="","",Categories!$A16) | B24: =IF(A24="","",Categories!$B16&"") | C24: 720 | D24: =$C24 | E24: =$C24 | F24: =$C24 | G24: =$C24 | H24: =$C24 | I24: =$C24 | J24: =$C24 | K24: =$C24 | ... M24: =$C24 | N24: 760 | O24: 820 | P24: =SUM(D24:O24)
A25: =IF(Categories!$A17="","",Categories!$A17) | B25: =IF(A25="","",Categories!$B17&"") | C25: 240 | D25: =$C25 | E25: =$C25 | F25: =$C25 | G25: =$C25 | H25: =$C25 | I25: =$C25 | J25: =$C25 | K25: =$C25 | ... O25: =$C25 | P25: =SUM(D25:O25)
A26: =IF(Categories!$A18="","",Categories!$A18) | B26: =IF(A26="","",Categories!$B18&"") | C26: 200 | D26: =$C26 | E26: =$C26 | F26: =$C26 | G26: =$C26 | H26: =$C26 | I26: =$C26 | J26: =$C26 | K26: =$C26 | L26: 750 | M26: =$C26 | N26: =$C26 | O26: =$C26 | P26: =SUM(D26:O26)
A27: =IF(Categories!$A19="","",Categories!$A19) | B27: =IF(A27="","",Categories!$B19&"") | C27: 60 | D27: =$C27 | E27: =$C27 | F27: =$C27 | G27: =$C27 | H27: =$C27 | I27: =$C27 | J27: =$C27 | K27: =$C27 | ... O27: =$C27 | P27: =SUM(D27:O27)
A28: =IF(Categories!$A20="","",Categories!$A20) | B28: =IF(A28="","",Categories!$B20&"") | C28: 390 | D28: =$C28 | E28: =$C28 | F28: =$C28 | G28: =$C28 | H28: =$C28 | I28: =$C28 | J28: 500 | K28: 640 | L28: =$C28 | M28: =$C28 | N28: =$C28 | O28: =$C28 | P28: =SUM(D28:O28)
A29: =IF(Categories!$A21="","",Categories!$A21) | B29: =IF(A29="","",Categories!$B21&"") | C29: 45 | D29: =$C29 | E29: =$C29 | F29: =$C29 | G29: =$C29 | H29: =$C29 | I29: =$C29 | J29: =$C29 | K29: =$C29 | ... O29: =$C29 | P29: =SUM(D29:O29)
A30: =IF(Categories!$A22="","",Categories!$A22) | B30: =IF(A30="","",Categories!$B22&"") | C30: 80 | D30: =$C30 | E30: =$C30 | F30: =$C30 | G30: =$C30 | H30: =$C30 | I30: =$C30 | J30: =$C30 | K30: =$C30 | ... O30: =$C30 | P30: =SUM(D30:O30)
A31: =IF(Categories!$A23="","",Categories!$A23) | B31: =IF(A31="","",Categories!$B23&"") | C31: 40 | D31: =$C31 | E31: =$C31 | F31: =$C31 | G31: =$C31 | H31: =$C31 | I31: =$C31 | J31: =$C31 | K31: =$C31 | ... N31: =$C31 | O31: 650 | P31: =SUM(D31:O31)
A32: =IF(Categories!$A24="","",Categories!$A24) | B32: =IF(A32="","",Categories!$B24&"") | C32: 0 | D32: =$C32 | E32: =$C32 | F32: =$C32 | G32: =$C32 | H32: 200 | I32: =$C32 | J32: 1600 | K32: =$C32 | L32: =$C32 | M32: =$C32 | N32: =$C32 | O32: =$C32 | P32: =SUM(D32:O32)
A33: =IF(Categories!$A25="","",Categories!$A25) | B33: =IF(A33="","",Categories!$B25&"") | C33: 60 | D33: =$C33 | E33: =$C33 | F33: =$C33 | G33: =$C33 | H33: =$C33 | I33: =$C33 | J33: =$C33 | K33: =$C33 | ... O33: =$C33 | P33: =SUM(D33:O33)
A34: =IF(Categories!$A26="","",Categories!$A26) | B34: =IF(A34="","",Categories!$B26&"") | C34: 60 | D34: =$C34 | E34: =$C34 | F34: =$C34 | G34: =$C34 | H34: =$C34 | I34: =$C34 | J34: =$C34 | K34: =$C34 | ... O34: =$C34 | P34: =SUM(D34:O34)
A35: =IF(Categories!$A27="","",Categories!$A27) | B35: =IF(A35="","",Categories!$B27&"") | C35: 50 | D35: =$C35 | E35: =$C35 | F35: 210 | G35: =$C35 | H35: =$C35 | I35: =$C35 | J35: =$C35 | K35: =$C35 | L35: =$C35 | M35: =$C35 | N35: =$C35 | O35: =$C35 | P35: =SUM(D35:O35)
A36: =IF(Categories!$A28="","",Categories!$A28) | B36: =IF(A36="","",Categories!$B28&"") | C36: 40 | D36: =$C36 | E36: =$C36 | F36: =$C36 | G36: =$C36 | H36: =$C36 | I36: =$C36 | J36: =$C36 | K36: =$C36 | ... O36: =$C36 | P36: =SUM(D36:O36)
A37: =IF(Categories!$A29="","",Categories!$A29) | B37: =IF(A37="","",Categories!$B29&"") | C37: 300 | D37: =$C37 | E37: =$C37 | F37: =$C37 | G37: =$C37 | H37: =$C37 | I37: =$C37 | J37: =$C37 | K37: =$C37 | ... O37: =$C37 | P37: =SUM(D37:O37)
A38: =IF(Categories!$A30="","",Categories!$A30) | B38: =IF(A38="","",Categories!$B30&"") | C38: 400 | D38: =$C38 | E38: =$C38 | F38: =$C38 | G38: =$C38 | H38: =$C38 | I38: =$C38 | J38: =$C38 | K38: =$C38 | ... O38: =$C38 | P38: =SUM(D38:O38)
A39: =IF(Categories!$A31="","",Categories!$A31) | B39: =IF(A39="","",Categories!$B31&"") | C39: 300 | D39: =$C39 | E39: =$C39 | F39: =$C39 | G39: =$C39 | H39: =$C39 | I39: =$C39 | J39: =$C39 | K39: =$C39 | ... O39: =$C39 | P39: =SUM(D39:O39)
A40: =IF(Categories!$A32="","",Categories!$A32) | B40: =IF(A40="","",Categories!$B32&"") | C40: 600 | D40: =$C40 | E40: =$C40 | F40: =$C40 | G40: =$C40 | H40: =$C40 | I40: =$C40 | J40: =$C40 | K40: =$C40 | ... O40: =$C40 | P40: =SUM(D40:O40)
...

Sheet Monthly Summary
A1: Monthly Summary
A2: Actual amounts from Transactions compared with Monthly Budget. Difference = actual − planned: green is better than planned, red is worse.
A3: Month to review ▸ | B3: Auto | C3: ="Showing "&Settings!$C$13&" "&Settings!$C$4&". Auto = the latest month (today, or the as-of date in Settings)."
C4: =Settings!$C$13&" "&Settings!$C$4&Settings!$C$14 | H4: ="Year to date ("&IF(Settings!$C$12=1,"Jan","Jan–"&Settings!$C$15)&")"&Settings!$C$14 | L4: ="Actual by month"&Settings!$C$14 | X4: ="Full year"&Settings!$C$14
A5: Category | B5: Type | C5: Planned | D5: Actual | E5: Difference | F5: % of plan | H5: Planned | I5: Actual | J5: Difference | L5: Jan | M5: Feb | N5: Mar | O5: Apr | P5: May | Q5: Jun | R5: Jul | S5: Aug | T5: Sep | U5: Oct | V5: Nov | W5: Dec | X5: Actual | Y5: Planned | Z5: Difference | AA5: Rank key
A6: Income | B6: Income | C6: =SUMIFS(C$14:C$73,$B$14:$B$73,"Income") | D6: =SUMIFS(D$14:D$73,$B$14:$B$73,"Income") | E6: =D6-C6 | F6: =IF(C6=0,"",D6/C6) | H6: =SUMIFS(H$14:H$73,$B$14:$B$73,"Income") | I6: =SUMIFS(I$14:I$73,$B$14:$B$73,"Income") | J6: =I6-H6 | L6: =SUMIFS(L$14:L$73,$B$14:$B$73,"Income") | M6: =SUMIFS(M$14:M$73,$B$14:$B$73,"Income") | N6: =SUMIFS(N$14:N$73,$B$14:$B$73,"Income") | O6: =SUMIFS(O$14:O$73,$B$14:$B$73,"Income") | P6: =SUMIFS(P$14:P$73,$B$14:$B$73,"Income") | Q6: =SUMIFS(Q$14:Q$73,$B$14:$B$73,"Income") | R6: =SUMIFS(R$14:R$73,$B$14:$B$73,"Income") | S6: =SUMIFS(S$14:S$73,$B$14:$B$73,"Income") | ... Y6: =SUMIFS(Y$14:Y$73,$B$14:$B$73,"Income") | Z6: =X6-Y6
A7: Fixed bills | B7: Fixed bills | C7: =SUMIFS(C$14:C$73,$B$14:$B$73,"Fixed bills") | D7: =SUMIFS(D$14:D$73,$B$14:$B$73,"Fixed bills") | E7: =D7-C7 | F7: =IF(C7=0,"",D7/C7) | H7: =SUMIFS(H$14:H$73,$B$14:$B$73,"Fixed bills") | I7: =SUMIFS(I$14:I$73,$B$14:$B$73,"Fixed bills") | J7: =I7-H7 | L7: =SUMIFS(L$14:L$73,$B$14:$B$73,"Fixed bills") | M7: =SUMIFS(M$14:M$73,$B$14:$B$73,"Fixed bills") | N7: =SUMIFS(N$14:N$73,$B$14:$B$73,"Fixed bills") | O7: =SUMIFS(O$14:O$73,$B$14:$B$73,"Fixed bills") | P7: =SUMIFS(P$14:P$73,$B$14:$B$73,"Fixed bills") | Q7: =SUMIFS(Q$14:Q$73,$B$14:$B$73,"Fixed bills") | R7: =SUMIFS(R$14:R$73,$B$14:$B$73,"Fixed bills") | S7: =SUMIFS(S$14:S$73,$B$14:$B$73,"Fixed bills") | ... Y7: =SUMIFS(Y$14:Y$73,$B$14:$B$73,"Fixed bills") | Z7: =X7-Y7
A8: Variable expenses | B8: Variable expenses | C8: =SUMIFS(C$14:C$73,$B$14:$B$73,"Variable expenses") | D8: =SUMIFS(D$14:D$73,$B$14:$B$73,"Variable expenses") | E8: =D8-C8 | F8: =IF(C8=0,"",D8/C8) | H8: =SUMIFS(H$14:H$73,$B$14:$B$73,"Variable expenses") | I8: =SUMIFS(I$14:I$73,$B$14:$B$73,"Variable expenses") | J8: =I8-H8 | L8: =SUMIFS(L$14:L$73,$B$14:$B$73,"Variable expenses") | M8: =SUMIFS(M$14:M$73,$B$14:$B$73,"Variable expenses") | N8: =SUMIFS(N$14:N$73,$B$14:$B$73,"Variable expenses") | O8: =SUMIFS(O$14:O$73,$B$14:$B$73,"Variable expenses") | P8: =SUMIFS(P$14:P$73,$B$14:$B$73,"Variable expenses") | Q8: =SUMIFS(Q$14:Q$73,$B$14:$B$73,"Variable expenses") | R8: =SUMIFS(R$14:R$73,$B$14:$B$73,"Variable expenses") | S8: =SUMIFS(S$14:S$73,$B$14:$B$73,"Variable expenses") | ... Y8: =SUMIFS(Y$14:Y$73,$B$14:$B$73,"Variable expenses") | Z8: =X8-Y8
A9: Total expenses | B9: All expenses | C9: =C7+C8 | D9: =D7+D8 | E9: =D9-C9 | F9: =IF(C9=0,"",D9/C9) | H9: =H7+H8 | I9: =I7+I8 | J9: =I9-H9 | L9: =L7+L8 | M9: =M7+M8 | N9: =N7+N8 | O9: =O7+O8 | P9: =P7+P8 | Q9: =Q7+Q8 | R9: =R7+R8 | S9: =S7+S8 | ... Y9: =Y7+Y8 | Z9: =X9-Y9
A10: Savings & debt payments | B10: Savings & debt | C10: =SUMIFS(C$14:C$73,$B$14:$B$73,"Savings & debt") | D10: =SUMIFS(D$14:D$73,$B$14:$B$73,"Savings & debt") | E10: =D10-C10 | F10: =IF(C10=0,"",D10/C10) | H10: =SUMIFS(H$14:H$73,$B$14:$B$73,"Savings & debt") | I10: =SUMIFS(I$14:I$73,$B$14:$B$73,"Savings & debt") | J10: =I10-H10 | L10: =SUMIFS(L$14:L$73,$B$14:$B$73,"Savings & debt") | M10: =SUMIFS(M$14:M$73,$B$14:$B$73,"Savings & debt") | N10: =SUMIFS(N$14:N$73,$B$14:$B$73,"Savings & debt") | O10: =SUMIFS(O$14:O$73,$B$14:$B$73,"Savings & debt") | P10: =SUMIFS(P$14:P$73,$B$14:$B$73,"Savings & debt") | Q10: =SUMIFS(Q$14:Q$73,$B$14:$B$73,"Savings & debt") | R10: =SUMIFS(R$14:R$73,$B$14:$B$73,"Savings & debt") | S10: =SUMIFS(S$14:S$73,$B$14:$B$73,"Savings & debt") | ... Y10: =SUMIFS(Y$14:Y$73,$B$14:$B$73,"Savings & debt") | Z10: =X10-Y10
A11: Paid from goals & funds | B11: Funds | C11: =INDEX('Monthly Budget'!$D$11:$O$11,1,Settings!$C$12) | D11: =INDEX($L$11:$W$11,1,Settings!$C$12) | E11: =D11-C11 | H11: =SUMIFS('Monthly Budget'!$D$11:$O$11,Lists!$I$2:$T$2,"<="&Settings!$C$12) | I11: =SUMIFS($L$11:$W$11,Lists!$I$2:$T$2,"<="&Settings!$C$12) | J11: =I11-H11 | L11: =SUMIFS(Transactions!$D$6:$D$2005,Transactions!$F$6:$F$2005,"<>",Transactions!$H$6:$H$2005,"Fixed bills",Transactions!$A$6:$A$2005,">="&DATE(Settings!$C$4,1,1),Transactions!$A$6:$A$2005,"<"&DATE(Settings!$C$4,2,1))+SUMIFS(Transactions!$D$6:$D$2005,Transactions!$F$6:$F$2005,"<>",Transactions!$H$6:$H$2005,"Variable expenses",Transactions!$A$6:$A$2005,">="&DATE(Settings!$C$4,1,1),Transactions!$A$6:$A$2005,"<"&DATE(Settings!$C$4,2,1)) | M11: =SUMIFS(Transactions!$D$6:$D$2005,Transactions!$F$6:$F$2005,"<>",Transactions!$H$6:$H$2005,"Fixed bills",Transactions!$A$6:$A$2005,">="&DATE(Settings!$C$4,2,1),Transactions!$A$6:$A$2005,"<"&DATE(Settings!$C$4,3,1))+SUMIFS(Transactions!$D$6:$D$2005,Transactions!$F$6:$F$2005,"<>",Transactions!$H$6:$H$2005,"Variable expenses",Transactions!$A$6:$A$2005,">="&DATE(Settings!$C$4,2,1),Transactions!$A$6:$A$2005,"<"&DATE(Settings!$C$4,3,1)) | N11: =SUMIFS(Transactions!$D$6:$D$2005,Transactions!$F$6:$F$2005,"<>",Transactions!$H$6:$H$2005,"Fixed bills",Transactions!$A$6:$A$2005,">="&DATE(Settings!$C$4,3,1),Transactions!$A$6:$A$2005,"<"&DATE(Settings!$C$4,4,1))+SUMIFS(Transactions!$D$6:$D$2005,Transactions!$F$6:$F$2005,"<>",Transactions!$H$6:$H$2005,"Variable expenses",Transactions!$A$6:$A$2005,">="&DATE(Settings!$C$4,3,1),Transactions!$A$6:$A$2005,"<"&DATE(Settings!$C$4,4,1)) | O11: =SUMIFS(Transactions!$D$6:$D$2005,Transactions!$F$6:$F$2005,"<>",Transactions!$H$6:$H$2005,"Fixed bills",Transactions!$A$6:$A$2005,">="&DATE(Settings!$C$4,4,1),Transactions!$A$6:$A$2005,"<"&DATE(Settings!$C$4,5,1))+SUMIFS(Transactions!$D$6:$D$2005,Transactions!$F$6:$F$2005,"<>",Transactions!$H$6:$H$2005,"Variable expenses",Transactions!$A$6:$A$2005,">="&DATE(Settings!$C$4,4,1),Transactions!$A$6:$A$2005,"<"&DATE(Settings!$C$4,5,1)) | P11: =SUMIFS(Transactions!$D$6:$D$2005,Transactions!$F$6:$F$2005,"<>",Transactions!$H$6:$H$2005,"Fixed bills",Transactions!$A$6:$A$2005,">="&DATE(Settings!$C$4,5,1),Transactions!$A$6:$A$2005,"<"&DATE(Settings!$C$4,6,1))+SUMIFS(Transactions!$D$6:$D$2005,Transactions!$F$6:$F$2005,"<>",Transactions!$H$6:$H$2005,"Variable expenses",Transactions!$A$6:$A$2005,">="&DATE(Settings!$C$4,5,1),Transactions!$A$6:$A$2005,"<"&DATE(Settings!$C$4,6,1)) | Q11: =SUMIFS(Transactions!$D$6:$D$2005,Transactions!$F$6:$F$2005,"<>",Transactions!$H$6:$H$2005,"Fixed bills",Transactions!$A$6:$A$2005,">="&DATE(Settings!$C$4,6,1),Transactions!$A$6:$A$2005,"<"&DATE(Settings!$C$4,7,1))+SUMIFS(Transactions!$D$6:$D$2005,Transactions!$F$6:$F$2005,"<>",Transactions!$H$6:$H$2005,"Variable expenses",Transactions!$A$6:$A$2005,">="&DATE(Settings!$C$4,6,1),Transactions!$A$6:$A$2005,"<"&DATE(Settings!$C$4,7,1)) | R11: =SUMIFS(Transactions!$D$6:$D$2005,Transactions!$F$6:$F$2005,"<>",Transactions!$H$6:$H$2005,"Fixed bills",Transactions!$A$6:$A$2005,">="&DATE(Settings!$C$4,7,1),Transactions!$A$6:$A$2005,"<"&DATE(Settings!$C$4,8,1))+SUMIFS(Transactions!$D$6:$D$2005,Transactions!$F$6:$F$2005,"<>",Transactions!$H$6:$H$2005,"Variable expenses",Transactions!$A$6:$A$2005,">="&DATE(Settings!$C$4,7,1),Transactions!$A$6:$A$2005,"<"&DATE(Settings!$C$4,8,1)) | S11: =SUMIFS(Transactions!$D$6:$D$2005,Transactions!$F$6:$F$2005,"<>",Transactions!$H$6:$H$2005,"Fixed bills",Transactions!$A$6:$A$2005,">="&DATE(Settings!$C$4,8,1),Transactions!$A$6:$A$2005,"<"&DATE(Settings!$C$4,9,1))+SUMIFS(Transactions!$D$6:$D$2005,Transactions!$F$6:$F$2005,"<>",Transactions!$H$6:$H$2005,"Variable expenses",Transactions!$A$6:$A$2005,">="&DATE(Settings!$C$4,8,1),Transactions!$A$6:$A$2005,"<"&DATE(Settings!$C$4,9,1)) | T11: =SUMIFS(Transactions!$D$6:$D$2005,Transactions!$F$6:$F$2005,"<>",Transactions!$H$6:$H$2005,"Fixed bills",Transactions!$A$6:$A$2005,">="&DATE(Settings!$C$4,9,1),Transactions!$A$6:$A$2005,"<"&DATE(Settings!$C$4,10,1))+SUMIFS(Transactions!$D$6:$D$2005,Transactions!$F$6:$F$2005,"<>",Transactions!$H$6:$H$2005,"Variable expenses",Transactions!$A$6:$A$2005,">="&DATE(Settings!$C$4,9,1),Transactions!$A$6:$A$2005,"<"&DATE(Settings!$C$4,10,1)) | U11: =SUMIFS(Transactions!$D$6:$D$2005,Transactions!$F$6:$F$2005,"<>",Transactions!$H$6:$H$2005,"Fixed bills",Transactions!$A$6:$A$2005,">="&DATE(Settings!$C$4,10,1),Transactions!$A$6:$A$2005,"<"&DATE(Settings!$C$4,11,1))+SUMIFS(Transactions!$D$6:$D$2005,Transactions!$F$6:$F$2005,"<>",Transactions!$H$6:$H$2005,"Variable expenses",Transactions!$A$6:$A$2005,">="&DATE(Settings!$C$4,10,1),Transactions!$A$6:$A$2005,"<"&DATE(Settings!$C$4,11,1)) | V11: =SUMIFS(Transactions!$D$6:$D$2005,Transactions!$F$6:$F$2005,"<>",Transactions!$H$6:$H$2005,"Fixed bills",Transactions!$A$6:$A$2005,">="&DATE(Settings!$C$4,11,1),Transactions!$A$6:$A$2005,"<"&DATE(Settings!$C$4,12,1))+SUMIFS(Transactions!$D$6:$D$2005,Transactions!$F$6:$F$2005,"<>",Transactions!$H$6:$H$2005,"Variable expenses",Transactions!$A$6:$A$2005,">="&DATE(Settings!$C$4,11,1),Transactions!$A$6:$A$2005,"<"&DATE(Settings!$C$4,12,1)) | W11: =SUMIFS(Transactions!$D$6:$D$2005,Transactions!$F$6:$F$2005,"<>",Transactions!$H$6:$H$2005,"Fixed bills",Transactions!$A$6:$A$2005,">="&DATE(Settings!$C$4,12,1),Transactions!$A$6:$A$2005,"<"&DATE(Settings!$C$4,13,1))+SUMIFS(Transactions!$D$6:$D$2005,Transactions!$F$6:$F$2005,"<>",Transactions!$H$6:$H$2005,"Variable expenses",Transactions!$A$6:$A$2005,">="&DATE(Settings!$C$4,12,1),Transactions!$A$6:$A$2005,"<"&DATE(Settings!$C$4,13,1)) | X11: =SUM(L11:W11) | Y11: ='Monthly Budget'!$P$11 | Z11: =X11-Y11
A12: Left over | B12: Result | C12: =C6-C9-C10+C11 | D12: =D6-D9-D10+D11 | E12: =D12-C12 | H12: =H6-H9-H10+H11 | I12: =I6-I9-I10+I11 | J12: =I12-H12 | L12: =L6-L9-L10+L11 | M12: =M6-M9-M10+M11 | N12: =N6-N9-N10+N11 | O12: =O6-O9-O10+O11 | P12: =P6-P9-P10+P11 | Q12: =Q6-Q9-Q10+Q11 | R12: =R6-R9-R10+R11 | S12: =S6-S9-S10+S11 | ... Y12: =Y6-Y9-Y10+Y11 | Z12: =X12-Y12
A13: Categories
